Workbook

Sheet Monthly
A1: Date | B1: Year | C1: Month | D1: Y.M. | E1: Calamar | F1: StaHelena | G1: STDA_Cal | H1: STDA_Hel | I1: Ratios
A2: 42339 | B2: 2015 | C2: diciembre | D2: 2015.9167 | E2: 4444 | F2: 266.3 | G2: =STANDARDIZE(E2,Climatology!B$13,Climatology!C$13) -> -1.9010084 | H2: =STANDARDIZE(F2,Climatology!D$13,Climatology!E$13) -> -1.6093318 | I2: =F2/E2*100 -> 5.9923492
A3: 42309 | B3: 2015 | C3: noviembre | D3: 2015.8333 | E3: 5803 | F3: 327.5 | G3: =STANDARDIZE(E3,Climatology!B$12,Climatology!C$12) -> -1.5800333 | H3: =STANDARDIZE(F3,Climatology!D$12,Climatology!E$12) -> -1.3332503 | I3: =F3/E3*100 -> 5.6436326
A4: 42278 | B4: 2015 | C4: octubre | D4: 2015.75 | E4: 4343 | F4: 236.6 | G4: =STANDARDIZE(E4,Climatology!B$11,Climatology!C$11) -> -2.1254077 | H4: =STANDARDIZE(F4,Climatology!D$11,Climatology!E$11) -> -1.5920587 | I4: =F4/E4*100 -> 5.4478471
A5: 42248 | B5: 2015 | C5: septiembre | D5: 2015.6667 | E5: 4394 | F5: 242.4 | G5: =STANDARDIZE(E5,Climatology!B$10,Climatology!C$10) -> -1.5363843 | H5: =STANDARDIZE(F5,Climatology!D$10,Climatology!E$10) -> -1.1243722 | I5: =F5/E5*100 -> 5.5166136
A6: 42217 | B6: 2015 | C6: agosto | D6: 2015.5833 | E6: 4127 | F6: 233.5 | G6: =STANDARDIZE(E6,Climatology!B$9,Climatology!C$9) -> -1.615821 | H6: =STANDARDIZE(F6,Climatology!D$9,Climatology!E$9) -> -1.1279157 | I6: =F6/E6*100 -> 5.6578629
A7: 42186 | B7: 2015 | C7: julio | D7: 2015.5 | E7: 4341 | F7: 240.5 | G7: =STANDARDIZE(E7,Climatology!B$8,Climatology!C$8) -> -1.757977 | H7: =STANDARDIZE(F7,Climatology!D$8,Climatology!E$8) -> -1.2532204 | I7: =F7/E7*100 -> 5.5401981
A8: 42156 | B8: 2015 | C8: junio | D8: 2015.4167 | E8: 5904 | F8: 328.8 | G8: =STANDARDIZE(E8,Climatology!B$7,Climatology!C$7) -> -1.3341594 | H8: =STANDARDIZE(F8,Climatology!D$7,Climatology!E$7) -> -0.58746305 | I8: =F8/E8*100 -> 5.5691057
A9: 42125 | B9: 2015 | C9: mayo | D9: 2015.3333 | E9: 5097 | F9: 283.8 | G9: =STANDARDIZE(E9,Climatology!B$6,Climatology!C$6) -> -1.213701 | H9: =STANDARDIZE(F9,Climatology!D$6,Climatology!E$6) -> -0.40178907 | I9: =F9/E9*100 -> 5.5679812
A10: 42095 | B10: 2015 | C10: abril | D10: 2015.25 | E10: 4877 | F10: 255.8 | G10: =STANDARDIZE(E10,Climatology!B$5,Climatology!C$5) -> -0.043018985 | H10: =STANDARDIZE(F10,Climatology!D$5,Climatology!E$5) -> 0.1887642 | I10: =F10/E10*100 -> 5.2450277
A11: 42064 | B11: 2015 | C11: marzo | D11: 2015.1667 | E11: 3399 | F11: 185.7 | G11: =STANDARDIZE(E11,Climatology!B$4,Climatology!C$4) -> -0.45820824 | H11: =STANDARDIZE(F11,Climatology!D$4,Climatology!E$4) -> -0.16896869 | I11: =F11/E11*100 -> 5.4633716
A12: 42036 | B12: 2015 | C12: febrero | D12: 2015.0833 | E12: 3990 | F12: 220.7 | G12: =STANDARDIZE(E12,Climatology!B$3,Climatology!C$3) -> -0.26999695 | H12: =STANDARDIZE(F12,Climatology!D$3,Climatology!E$3) -> -0.18095642 | I12: =F12/E12*100 -> 5.5313283
A13: 42005 | B13: 2015 | C13: enero | D13: 2015 | E13: 4582 | F13: 295.3 | G13: =STANDARDIZE(E13,Climatology!B$2,Climatology!C$2) -> -0.97527319 | H13: =STANDARDIZE(F13,Climatology!D$2,Climatology!E$2) -> -0.5390918 | I13: =F13/E13*100 -> 6.4447839
A14: 41974 | B14: 2014 | C14: diciembre | D14: 2014.9167 | E14: 8477 | F14: 523.3 | G14: =STANDARDIZE(E14,Climatology!B$13,Climatology!C$13) -> -0.46089545 | H14: =STANDARDIZE(F14,Climatology!D$13,Climatology!E$13) -> 0.26593564 | I14: =F14/E14*100 -> 6.1731745
A15: 41944 | B15: 2014 | C15: noviembre | D15: 2014.8333 | E15: 8321 | F15: 496.8 | G15: =STANDARDIZE(E15,Climatology!B$12,Climatology!C$12) -> -0.5907216 | H15: =STANDARDIZE(F15,Climatology!D$12,Climatology!E$12) -> 0.14590616 | I15: =F15/E15*100 -> 5.9704362
A16: 41913 | B16: 2014 | C16: octubre | D16: 2014.75 | E16: 7039 | F16: 411.8 | G16: =STANDARDIZE(E16,Climatology!B$11,Climatology!C$11) -> -0.73636459 | H16: =STANDARDIZE(F16,Climatology!D$11,Climatology!E$11) -> -0.14708905 | I16: =F16/E16*100 -> 5.8502628
A17: 41883 | B17: 2014 | C17: septiembre | D17: 2014.6667 | E17: 5495 | F17: 313.2 | G17: =STANDARDIZE(E17,Climatology!B$10,Climatology!C$10) -> -0.99233701 | H17: =STANDARDIZE(F17,Climatology!D$10,Climatology!E$10) -> -0.57919272 | I17: =F17/E17*100 -> 5.699727
A18: 41852 | B18: 2014 | C18: agosto | D18: 2014.5833 | E18: 4197 | F18: 230.4 | G18: =STANDARDIZE(E18,Climatology!B$9,Climatology!C$9) -> -1.5805276 | H18: =STANDARDIZE(F18,Climatology!D$9,Climatology!E$9) -> -1.1517768 | I18: =F18/E18*100 -> 5.4896355
A19: 41821 | B19: 2014 | C19: julio | D19: 2014.5 | E19: 4744 | F19: 280.5 | G19: =STANDARDIZE(E19,Climatology!B$8,Climatology!C$8) -> -1.5593859 | H19: =STANDARDIZE(F19,Climatology!D$8,Climatology!E$8) -> -0.9331831 | I19: =F19/E19*100 -> 5.9127319
A20: 41791 | B20: 2014 | C20: junio | D20: 2014.4167 | E20: 6647 | F20: 369.3 | G20: =STANDARDIZE(E20,Climatology!B$7,Climatology!C$7) -> -0.89338397 | H20: =STANDARDIZE(F20,Climatology!D$7,Climatology!E$7) -> -0.22466565 | I20: =F20/E20*100 -> 5.5558899
A21: 41760 | B21: 2014 | C21: mayo | D21: 2014.3333 | E21: 6475 | F21: 339.4 | G21: =STANDARDIZE(E21,Climatology!B$6,Climatology!C$6) -> -0.26218843 | H21: =STANDARDIZE(F21,Climatology!D$6,Climatology!E$6) -> 0.10042469 | I21: =F21/E21*100 -> 5.2416988
A22: 41730 | B22: 2014 | C22: abril | D22: 2014.25 | E22: 4075 | F22: 197.2 | G22: =STANDARDIZE(E22,Climatology!B$5,Climatology!C$5) -> -0.61713428 | H22: =STANDARDIZE(F22,Climatology!D$5,Climatology!E$5) -> -0.36129765 | I22: =F22/E22*100 -> 4.8392638
A23: 41699 | B23: 2014 | C23: marzo | D23: 2014.1667 | E23: 4551 | F23: 216.6 | G23: =STANDARDIZE(E23,Climatology!B$4,Climatology!C$4) -> 0.27426086 | H23: =STANDARDIZE(F23,Climatology!D$4,Climatology!E$4) -> 0.15648036 | I23: =F23/E23*100 -> 4.7593935
A24: 41671 | B24: 2014 | C24: febrero | D24: 2014.0833 | E24: 3771 | F24: 198.5 | G24: =STANDARDIZE(E24,Climatology!B$3,Climatology!C$3) -> -0.39767964 | H24: =STANDARDIZE(F24,Climatology!D$3,Climatology!E$3) -> -0.35959582 | I24: =F24/E24*100 -> 5.2638557
A25: 41640 | B25: 2014 | C25: enero | D25: 2014 | E25: 5797 | F25: 338.7 | G25: =STANDARDIZE(E25,Climatology!B$2,Climatology!C$2) -> -0.44537563 | H25: =STANDARDIZE(F25,Climatology!D$2,Climatology!E$2) -> -0.24755285 | I25: =F25/E25*100 -> 5.8426772
A26: 41609 | B26: 2013 | C26: diciembre | D26: 2013.9167 | E26: 8407 | F26: 411.1 | G26: =STANDARDIZE(E26,Climatology!B$13,Climatology!C$13) -> -0.48589121 | H26: =STANDARDIZE(F26,Climatology!D$13,Climatology!E$13) -> -0.55276087 | I26: =F26/E26*100 -> 4.8899726
A27: 41579 | B27: 2013 | C27: noviembre | D27: 2013.8333 | E27: 8535 | F27: 427.3 | G27: =STANDARDIZE(E27,Climatology!B$12,Climatology!C$12) -> -0.50664189 | H27: =STANDARDIZE(F27,Climatology!D$12,Climatology!E$12) -> -0.4613081 | I27: =F27/E27*100 -> 5.0064441
A28: 41548 | B28: 2013 | C28: octubre | D28: 2013.75 | E28: 7850 | F28: 404.5 | G28: =STANDARDIZE(E28,Climatology!B$11,Climatology!C$11) -> -0.31851817 | H28: =STANDARDIZE(F28,Climatology!D$11,Climatology!E$11) -> -0.20729612 | I28: =F28/E28*100 -> 5.1528662
A29: 41518 | B29: 2013 | C29: septiembre | D29: 2013.6667 | E29: 7369 | F29: 358 | G29: =STANDARDIZE(E29,Climatology!B$10,Climatology!C$10) -> -0.066320074 | H29: =STANDARDIZE(F29,Climatology!D$10,Climatology!E$10) -> -0.23422038 | I29: =F29/E29*100 -> 4.8581897
A30: 41487 | B30: 2013 | C30: agosto | D30: 2013.5833 | E30: 5564 | F30: 272.5 | G30: =STANDARDIZE(E30,Climatology!B$9,Climatology!C$9) -> -0.89129715 | H30: =STANDARDIZE(F30,Climatology!D$9,Climatology!E$9) -> -0.82772756 | I30: =F30/E30*100 -> 4.8975557
A31: 41456 | B31: 2013 | C31: julio | D31: 2013.5 | E31: 6649 | F31: 317.4 | G31: =STANDARDIZE(E31,Climatology!B$8,Climatology!C$8) -> -0.62063602 | H31: =STANDARDIZE(F31,Climatology!D$8,Climatology!E$8) -> -0.63794867 | I31: =F31/E31*100 -> 4.7736502
A32: 41426 | B32: 2013 | C32: junio | D32: 2013.4167 | E32: 8229 | F32: 351.5 | G32: =STANDARDIZE(E32,Climatology!B$7,Climatology!C$7) -> 0.045117686 | H32: =STANDARDIZE(F32,Climatology!D$7,Climatology!E$7) -> -0.38411735 | I32: =F32/E32*100 -> 4.2714789
A33: 41395 | B33: 2013 | C33: mayo | D33: 2013.3333 | E33: 6259 | F33: 274 | G33: =STANDARDIZE(E33,Climatology!B$6,Climatology!C$6) -> -0.41133698 | H33: =STANDARDIZE(F33,Climatology!D$6,Climatology!E$6) -> -0.49030876 | I33: =F33/E33*100 -> 4.3776961
A34: 41365 | B34: 2013 | C34: abril | D34: 2013.25 | E34: 4229 | F34: 182 | G34: =STANDARDIZE(E34,Climatology!B$5,Climatology!C$5) -> -0.50689269 | H34: =STANDARDIZE(F34,Climatology!D$5,Climatology!E$5) -> -0.50397581 | I34: =F34/E34*100 -> 4.3036179
A35: 41334 | B35: 2013 | C35: marzo | D35: 2013.1667 | E35: 3792 | F35: 178 | G35: =STANDARDIZE(E35,Climatology!B$4,Climatology!C$4) -> -0.20832946 | H35: =STANDARDIZE(F35,Climatology!D$4,Climatology!E$4) -> -0.25006764 | I35: =F35/E35*100 -> 4.6940928
A36: 41306 | B36: 2013 | C36: febrero | D36: 2013.0833 | E36: 3205 | F36: 163.4 | G36: =STANDARDIZE(E36,Climatology!B$3,Climatology!C$3) -> -0.72767237 | H36: =STANDARDIZE(F36,Climatology!D$3,Climatology!E$3) -> -0.64203921 | I36: =F36/E36*100 -> 5.0982839
A37: 41275 | B37: 2013 | C37: enero | D37: 2013 | E37: 3669 | F37: 188.9 | G37: =STANDARDIZE(E37,Climatology!B$2,Climatology!C$2) -> -1.3734596 | H37: =STANDARDIZE(F37,Climatology!D$2,Climatology!E$2) -> -1.2538325 | I37: =F37/E37*100 -> 5.1485418
A38: 41244 | B38: 2012 | C38: diciembre | D38: 2012.9167 | E38: 6855 | F38: 341.8 | G38: =STANDARDIZE(E38,Climatology!B$13,Climatology!C$13) -> -1.040083 | H38: =STANDARDIZE(F38,Climatology!D$13,Climatology!E$13) -> -1.0584264 | I38: =F38/E38*100 -> 4.9861415
A39: 41214 | B39: 2012 | C39: noviembre | D39: 2012.8333 | E39: 7858 | F39: 377.8 | G39: =STANDARDIZE(E39,Climatology!B$12,Climatology!C$12) -> -0.77263238 | H39: =STANDARDIZE(F39,Climatology!D$12,Climatology!E$12) -> -0.89378444 | I39: =F39/E39*100 -> 4.8078391
A40: 41183 | B40: 2012 | C40: octubre | D40: 2012.75 | E40: 6414 | F40: 318.2 | G40: =STANDARDIZE(E40,Climatology!B$11,Climatology!C$11) -> -1.0583794 | H40: =STANDARDIZE(F40,Climatology!D$11,Climatology!E$11) -> -0.91905912 | I40: =F40/E40*100 -> 4.9610228
...

Sheet Annual
A1: Year | B1: Calamar | C1: STDA_Cal | D1: StaHelena | E1: STDA_Hel
A2: 2015 | B2: 4608.4167 | C2: -1.9642069 | D2: 259.74167 | E2: -1.0404962 | F2: 217 | G2: 376 | H2: =(G2-F2)/F2*100 -> 73.271889
A3: 2014 | B3: 5799.0833 | C3: -1.0864725 | D3: 326.30833 | E3: -0.36817683
A4: 2013 | B4: 6146.4167 | C4: -0.83042563 | D4: 294.05 | E4: -0.69398409
A5: 2012 | B5: 7361.5 | C5: 0.065308289 | D5: 356.475 | E5: -0.063495288
A6: 2011 | B6: 10223.917 | C6: 2.1754217 | D6: 515.89167 | E6: 1.5466036
A7: 2010 | B7: 9012.1667 | C7: 1.2821451 | D7: 465.34167 | E7: 1.0360516
A8: 2009 | B8: 6946.25 | C8: -0.24080529 | D8: 419.25833 | E8: 0.57061265
A9: 2008 | B9: 9878.4167 | C9: 1.9207264 | D9: 560.5 | E9: 1.9971451
A10: 2007 | B10: 8904.25 | C10: 1.2025912 | D10: 525.62727 | E10: 1.6449326
A11: 2006 | B11: 8022.4167 | C11: 0.55252218 | D11: 482.40833 | E11: 1.2084239
A12: 2005 | B12: 7210.1667 | C12: -0.046251467 | D12: 401.8 | E12: 0.39428452
A13: 2004 | B13: 6657.8333 | C13: -0.45342 | D13: 370.78333 | E13: 0.08101803
A14: 2003 | B14: 6293.6667 | C14: -0.72187602 | D14: 377.73636 | E14: 0.15124322
... A36: 1981 | B36: 9255.3333 | C36: 1.4614025 | D36: 256.24583 | E36: -1.0758039
A37: 1980 | B37: 6208.4167 | C37: -0.78472053 | D37: =AVERAGEIF(Monthly!B$2:B$901,A37,Monthly!F$2:F$901) -> 170.45691
A38: 1979 | B38: 7326.75 | C38: 0.039691318 | D38: =AVERAGEIF(Monthly!B$2:B$901,A38,Monthly!F$2:F$901) -> 207.25007
A39: 1978 | B39: 6900.75 | C39: -0.27434694 | D39: =AVERAGEIF(Monthly!B$2:B$901,A39,Monthly!F$2:F$901) -> 193.23468
A40: 1977 | B40: 5718 | C40: -1.1462454 | D40: =AVERAGEIF(Monthly!B$2:B$901,A40,Monthly!F$2:F$901) -> 154.3222
A41: 1976 | B41: 7073.8333 | C41: -0.14675354 | D41: =AVERAGEIF(Monthly!B$2:B$901,A41,Monthly!F$2:F$901) -> 198.92912
A42: 1975 | B42: 8841 | C42: 1.1559646 | D42: =AVERAGEIF(Monthly!B$2:B$901,A42,Monthly!F$2:F$901) -> 257.0689
A43: 1974 | B43: 8906.5833 | C43: 1.2043113 | D43: =AVERAGEIF(Monthly!B$2:B$901,A43,Monthly!F$2:F$901) -> 259.22659
A44: 1973 | B44: 6785.4167 | C44: -0.35936825 | D44: =AVERAGEIF(Monthly!B$2:B$901,A44,Monthly!F$2:F$901) -> 189.44021
A45: 1972 | B45: 7173.75 | C45: -0.073097069 | D45: =AVERAGEIF(Monthly!B$2:B$901,A45,Monthly!F$2:F$901) -> 202.21637
A46: 1971 | B46: 10321.083 | C46: 2.247051 | D46: =AVERAGEIF(Monthly!B$2:B$901,A46,Monthly!F$2:F$901) -> 305.76364
A47: 1970 | B47: 8388.8333 | C47: 0.82263685 | D47: =AVERAGEIF(Monthly!B$2:B$901,A47,Monthly!F$2:F$901) -> 242.19262
A48: 1969 | B48: 7425.6667 | C48: 0.11261061 | D48: =AVERAGEIF(Monthly!B$2:B$901,A48,Monthly!F$2:F$901) -> 210.50443
... A67: 1950 | B67: 8975.5 | C67: 1.2551152 | D67: =AVERAGEIF(Monthly!B$2:B$901,A67,Monthly!F$2:F$901) -> 261.49395

Sheet Climatology
A1: Month | B1: Calamar | C1: SD | D1: StaHelena | E1: SD | F1: StaHelena-before | G1: StaHelena-after
A2: Enero | B2: =AVERAGEIFS(Monthly!E$2:E$901,Monthly!C$2:C$901,A2) -> 6818.2 | C2: {=_xlfn.STDEV.S(IF(Monthly!C$2:C$901=A2,Monthly!E$2:E$901))} -> 2292.896 | D2: =AVERAGEIF(Monthly!C$2:C$421,A2,Monthly!F$2:F$421) -> 375.552 | E2: {=_xlfn.STDEV.S(IF(Monthly!C$2:C$421=A2,Monthly!F$2:F$421))} -> 148.86518 | F2: =AVERAGEIF(Monthly!C386:C421,A2,Monthly!F$386:F$421) -> 195.64 | G2: =AVERAGEIF(Monthly!C$2:C$387,A2,Monthly!F$2:F$387) -> 392.41875
A3: Febrero | B3: =AVERAGEIFS(Monthly!E$2:E$901,Monthly!C$2:C$901,A3) -> 4453.0959 | C3: {=_xlfn.STDEV.S(IF(Monthly!C$2:C$901=A3,Monthly!E$2:E$901))} -> 1715.1893 | D3: =AVERAGEIF(Monthly!C$2:C$421,A3,Monthly!F$2:F$421) -> 243.18794 | E3: {=_xlfn.STDEV.S(IF(Monthly!C$2:C$421=A3,Monthly!F$2:F$421))} -> 124.27269 | F3: =AVERAGEIF(Monthly!C387:C422,A3,Monthly!F$386:F$421) -> 85.766667 | G3: =AVERAGEIF(Monthly!C$2:C$387,A3,Monthly!F$2:F$387) -> 256.47742
A4: Marzo | B4: =AVERAGEIFS(Monthly!E$2:E$901,Monthly!C$2:C$901,A4) -> 4119.6528 | C4: {=_xlfn.STDEV.S(IF(Monthly!C$2:C$901=A4,Monthly!E$2:E$901))} -> 1572.7626 | D4: =AVERAGEIF(Monthly!C$2:C$421,A4,Monthly!F$2:F$421) -> 201.74286 | E4: {=_xlfn.STDEV.S(IF(Monthly!C$2:C$421=A4,Monthly!F$2:F$421))} -> 94.945738 | F4: =AVERAGEIF(Monthly!C388:C423,A4,Monthly!F$386:F$421) -> 181.05667 | G4: =AVERAGEIF(Monthly!C$2:C$387,A4,Monthly!F$2:F$387) -> 212.61562
A5: Abril | B5: =AVERAGEIFS(Monthly!E$2:E$901,Monthly!C$2:C$901,A5) -> 4937.0946 | C5: {=_xlfn.STDEV.S(IF(Monthly!C$2:C$901=A5,Monthly!E$2:E$901))} -> 1396.932 | D5: =AVERAGEIF(Monthly!C$2:C$421,A5,Monthly!F$2:F$421) -> 235.69029 | E5: {=_xlfn.STDEV.S(IF(Monthly!C$2:C$421=A5,Monthly!F$2:F$421))} -> 106.53347 | F5: =AVERAGEIF(Monthly!C389:C424,A5,Monthly!F$386:F$421) -> 292.13333 | G5: =AVERAGEIF(Monthly!C$2:C$387,A5,Monthly!F$2:F$387) -> 248.23226
A6: Mayo | B6: =AVERAGEIFS(Monthly!E$2:E$901,Monthly!C$2:C$901,A6) -> 6854.7067 | C6: {=_xlfn.STDEV.S(IF(Monthly!C$2:C$901=A6,Monthly!E$2:E$901))} -> 1448.2206 | D6: =AVERAGEIF(Monthly!C$2:C$421,A6,Monthly!F$2:F$421) -> 328.282 | E6: {=_xlfn.STDEV.S(IF(Monthly!C$2:C$421=A6,Monthly!F$2:F$421))} -> 110.70983 | F6: =AVERAGEIF(Monthly!C390:C425,A6,Monthly!F$386:F$421) -> 234.76667 | G6: =AVERAGEIF(Monthly!C$2:C$387,A6,Monthly!F$2:F$387) -> 342.08437
A7: Junio | B7: =AVERAGEIFS(Monthly!E$2:E$901,Monthly!C$2:C$901,A7) -> 8152.9467 | C7: {=_xlfn.STDEV.S(IF(Monthly!C$2:C$901=A7,Monthly!E$2:E$901))} -> 1685.6656 | D7: =AVERAGEIF(Monthly!C$2:C$421,A7,Monthly!F$2:F$421) -> 394.38 | E7: {=_xlfn.STDEV.S(IF(Monthly!C$2:C$421=A7,Monthly!F$2:F$421))} -> 111.63255 | F7: =AVERAGEIF(Monthly!C391:C426,A7,Monthly!F$386:F$421) -> 311.06667 | G7: =AVERAGEIF(Monthly!C$2:C$387,A7,Monthly!F$2:F$387) -> 406.09688
A8: Julio | B8: =AVERAGEIFS(Monthly!E$2:E$901,Monthly!C$2:C$901,A8) -> 7908.4533 | C8: {=_xlfn.STDEV.S(IF(Monthly!C$2:C$901=A8,Monthly!E$2:E$901))} -> 2029.2946 | D8: =AVERAGEIF(Monthly!C$2:C$421,A8,Monthly!F$2:F$421) -> 397.13429 | E8: {=_xlfn.STDEV.S(IF(Monthly!C$2:C$421=A8,Monthly!F$2:F$421))} -> 124.98542 | F8: =AVERAGEIF(Monthly!C392:C427,A8,Monthly!F$386:F$421) -> 195.64 | G8: =AVERAGEIF(Monthly!C$2:C$387,A8,Monthly!F$2:F$387) -> 406.97813
A9: Agosto | B9: =AVERAGEIFS(Monthly!E$2:E$901,Monthly!C$2:C$901,A9) -> 7331.7733 | C9: {=_xlfn.STDEV.S(IF(Monthly!C$2:C$901=A9,Monthly!E$2:E$901))} -> 1983.3715 | D9: =AVERAGEIF(Monthly!C$2:C$421,A9,Monthly!F$2:F$421) -> 380.03714 | E9: {=_xlfn.STDEV.S(IF(Monthly!C$2:C$421=A9,Monthly!F$2:F$421))} -> 129.91852 | F9: =AVERAGEIF(Monthly!C393:C428,A9,Monthly!F$386:F$421) -> 85.766667 | G9: =AVERAGEIF(Monthly!C$2:C$387,A9,Monthly!F$2:F$387) -> 391.39687
A10: Septiembre | B10: =AVERAGEIFS(Monthly!E$2:E$901,Monthly!C$2:C$901,A10) -> 7503.2133 | C10: {=_xlfn.STDEV.S(IF(Monthly!C$2:C$901=A10,Monthly!E$2:E$901))} -> 2023.7211 | D10: =AVERAGEIF(Monthly!C$2:C$421,A10,Monthly!F$2:F$421) -> 388.41714 | E10: {=_xlfn.STDEV.S(IF(Monthly!C$2:C$421=A10,Monthly!F$2:F$421))} -> 129.86548 | F10: =AVERAGEIF(Monthly!C394:C429,A10,Monthly!F$386:F$421) -> 181.05667 | G10: =AVERAGEIF(Monthly!C$2:C$387,A10,Monthly!F$2:F$387) -> 402.82187
A11: Octubre | B11: =AVERAGEIFS(Monthly!E$2:E$901,Monthly!C$2:C$901,A11) -> 8468.2133 | C11: {=_xlfn.STDEV.S(IF(Monthly!C$2:C$901=A11,Monthly!E$2:E$901))} -> 1940.9045 | D11: =AVERAGEIF(Monthly!C$2:C$421,A11,Monthly!F$2:F$421) -> 429.63429 | E11: {=_xlfn.STDEV.S(IF(Monthly!C$2:C$421=A11,Monthly!F$2:F$421))} -> 121.24822 | F11: =AVERAGEIF(Monthly!C395:C430,A11,Monthly!F$386:F$421) -> 292.13333 | G11: =AVERAGEIF(Monthly!C$2:C$387,A11,Monthly!F$2:F$387) -> 445.00937
A12: Noviembre | B12: =AVERAGEIFS(Monthly!E$2:E$901,Monthly!C$2:C$901,A12) -> 9824.5068 | C12: {=_xlfn.STDEV.S(IF(Monthly!C$2:C$901=A12,Monthly!E$2:E$901))} -> 2545.2038 | D12: =AVERAGEIF(Monthly!C$2:C$421,A12,Monthly!F$2:F$421) -> 480.1 | E12: {=_xlfn.STDEV.S(IF(Monthly!C$2:C$421=A12,Monthly!F$2:F$421))} -> 114.45713 | F12: =AVERAGEIF(Monthly!C396:C431,A12,Monthly!F$386:F$421) -> 234.76667 | G12: =AVERAGEIF(Monthly!C$2:C$387,A12,Monthly!F$2:F$387) -> 490.40606
A13: Diciembre | B13: =AVERAGEIFS(Monthly!E$2:E$901,Monthly!C$2:C$901,A13) -> 9767.726 | C13: {=_xlfn.STDEV.S(IF(Monthly!C$2:C$901=A13,Monthly!E$2:E$901))} -> 2800.4747 | D13: =AVERAGEIF(Monthly!C$2:C$421,A13,Monthly!F$2:F$421) -> 486.85429 | E13: {=_xlfn.STDEV.S(IF(Monthly!C$2:C$421=A13,Monthly!F$2:F$421))} -> 137.04712 | F13: =AVERAGEIF(Monthly!C397:C432,A13,Monthly!F$386:F$421) -> 311.06667 | G13: =AVERAGEIF(Monthly!C$2:C$387,A13,Monthly!F$2:F$387) -> 497.98788

Sheet Pruebas de tendencia de Mann-K2
A1: Observaciones | B1: 592
A2: 1 | B2: 477
A3: 2 | B3: 395.6
A4: 3 | B4: 361.7
A5: 4 | B5: 421
A6: 5 | B6: 513.3
A7: 6 | B7: 573.2
A8: 7 | B8: 558.3
A9: 8 | B9: 525.9
A10: 9 | B10: 571.9
A11: 10 | B11: 591.5
A12: 11 | B12: 559.9
A13: 12 | B13: 350.9
... A132: 131 | B132: 835.1

Sheet Pruebas de tendencia de Mann-K3
A1: Observaciones | B1: 592
A2: 36557 | B2: 477
A3: 36586 | B3: 395.6
A4: 36617 | B4: 361.7
A5: 36647 | B5: 421
A6: 36678 | B6: 513.3
A7: 36708 | B7: 573.2
A8: 36739 | B8: 558.3
A9: 36770 | B9: 525.9
A10: 36800 | B10: 571.9
A11: 36831 | B11: 591.5
A12: 36861 | B12: 559.9
A13: 36892 | B13: 350.9
... A39: 37681 | B39: 173
A40: 37712
A41: 37742 | B41: 324.4
A42: 37773 | B42: 392.4
A43: 37803 | B43: 449.4
A44: 37834 | B44: 443.4
A45: 37865 | B45: 400.8
A46: 37895 | B46: 467.7
A47: 37926 | B47: 518
A48: 37956 | B48: 566.4
A49: 37987 | B49: 474.6
A50: 38018 | B50: 220.1
A51: 38047 | B51: 125.6
A52: 38078 | B52: 159.3
... A85: 39083 | B85: 540.3
A86: 39114
A87: 39142 | B87: 190.1
A88: 39173 | B88: 346.9
A89: 39203 | B89: 478.1
A90: 39234 | B90: 581.8
A91: 39264 | B91: 601.1
A92: 39295 | B92: 569.9
A93: 39326 | B93: 595.6
A94: 39356 | B94: 604.4
A95: 39387 | B95: 635.8
A96: 39417 | B96: 637.9
A97: 39448 | B97: 556.6
...

Sheet Pruebas de tendencia de Mann-K4
A1: Observaciones | B1: Serie1
A2: 36526 | B2: 592
A3: 36557 | B3: 477
A4: 36586 | B4: 395.6
A5: 36617 | B5: 361.7
A6: 36647 | B6: 421
A7: 36678 | B7: 513.3
A8: 36708 | B8: 573.2
A9: 36739 | B9: 558.3
A10: 36770 | B10: 525.9
A11: 36800 | B11: 571.9
A12: 36831 | B12: 591.5
A13: 36861 | B13: 559.9
... A40: 37681 | B40: 173
A41: 37712
A42: 37742 | B42: 324.4
A43: 37773 | B43: 392.4
A44: 37803 | B44: 449.4
A45: 37834 | B45: 443.4
A46: 37865 | B46: 400.8
A47: 37895 | B47: 467.7
A48: 37926 | B48: 518
A49: 37956 | B49: 566.4
A50: 37987 | B50: 474.6
A51: 38018 | B51: 220.1
A52: 38047 | B52: 125.6
A53: 38078 | B53: 159.3
... A86: 39083 | B86: 540.3
A87: 39114
A88: 39142 | B88: 190.1
A89: 39173 | B89: 346.9
A90: 39203 | B90: 478.1
A91: 39234 | B91: 581.8
A92: 39264 | B92: 601.1
A93: 39295 | B93: 569.9
A94: 39326 | B94: 595.6
A95: 39356 | B95: 604.4
A96: 39387 | B96: 635.8
A97: 39417 | B97: 637.9
A98: 39448 | B98: 556.6
...

Sheet Pruebas de tendencia de Mann-K5
A1: Observaciones | B1: Serie1
A2: 1 | B2: 592
A3: 2 | B3: 477
A4: 3 | B4: 395.6
A5: 4 | B5: 361.7
A6: 5 | B6: 421
A7: 6 | B7: 513.3
A8: 7 | B8: 573.2
A9: 8 | B9: 558.3
A10: 9 | B10: 525.9
A11: 10 | B11: 571.9
A12: 11 | B12: 591.5
A13: 12 | B13: 559.9
... A40: 39 | B40: 173
A41: 40
A42: 41 | B42: 324.4
A43: 42 | B43: 392.4
A44: 43 | B44: 449.4
A45: 44 | B45: 443.4
A46: 45 | B46: 400.8
A47: 46 | B47: 467.7
A48: 47 | B48: 518
A49: 48 | B49: 566.4
A50: 49 | B50: 474.6
A51: 50 | B51: 220.1
A52: 51 | B52: 125.6
A53: 52 | B53: 159.3
... A86: 85 | B86: 540.3
A87: 86
A88: 87 | B88: 190.1
A89: 88 | B89: 346.9
A90: 89 | B90: 478.1
A91: 90 | B91: 581.8
A92: 91 | B92: 601.1
A93: 92 | B93: 569.9
A94: 93 | B94: 595.6
A95: 94 | B95: 604.4
A96: 95 | B96: 635.8
A97: 96 | B97: 637.9
A98: 97 | B98: 556.6
...

Sheet Pruebas de tendencia de Mann-K6
A1: Observaciones | B1: Serie1
A2: 2000 | B2: 511.775
A3: 2001 | B3: 284.85
A4: 2002 | B4: 361.55833
A5: 2003 | B5: 377.73636
A6: 2004 | B6: 370.78333
A7: 2005 | B7: 401.8
A8: 2006 | B8: 482.40833
A9: 2007 | B9: 525.62727
A10: 2008 | B10: 560.5
A11: 2009 | B11: 419.25833
A12: 2010 | B12: 465.34167

Sheet Pruebas de tendencia de Mann-K7
A1: Observaciones | B1: Serie1
A2: 1 | B2: 511.775
A3: 2 | B3: 284.85
A4: 3 | B4: 361.55833
A5: 4 | B5: 377.73636
A6: 5 | B6: 370.78333
A7: 6 | B7: 401.8
A8: 7 | B8: 482.40833
A9: 8 | B9: 525.62727
A10: 9 | B10: 560.5
A11: 10 | B11: 419.25833
A12: 11 | B12: 465.34167

Sheet Pruebas de tendencia de Mann-K8
A1: Observaciones | B1: Serie1
A2: 2000 | B2: 511.775
A3: 2001 | B3: 284.85
A4: 2002 | B4: 361.55833
A5: 2003 | B5: 377.73636
A6: 2004 | B6: 370.78333
A7: 2005 | B7: 401.8
A8: 2006 | B8: 482.40833
A9: 2007 | B9: 525.62727
A10: 2008 | B10: 560.5
A11: 2009 | B11: 419.25833
A12: 2010 | B12: 465.34167

Sheet Pruebas de tendencia de Mann-K9
A1: Observaciones | B1: Serie1
A2: 2000 | B2: 511.775
A3: 2001 | B3: 284.85
A4: 2002 | B4: 361.55833
A5: 2003 | B5: 377.73636
A6: 2004 | B6: 370.78333
A7: 2005 | B7: 401.8
A8: 2006 | B8: 482.40833
A9: 2007 | B9: 525.62727
A10: 2008 | B10: 560.5
A11: 2009 | B11: 419.25833
A12: 2010 | B12: 465.34167

Sheet Pruebas de tendencia de Mann-K1
A1: Observaciones | B1: Serie1
A2: 30713 | B2: 197.4
A3: 30742 | B3: 232.1
A4: 30773 | B4: 176.2
A5: 30803 | B5: 285.9
A6: 30834 | B6: 388.3
A7: 30864 | B7: 475.7
A8: 30895 | B8: 527.7
A9: 30926 | B9: 497.4
A10: 30956 | B10: 564.5
A11: 30987 | B11: 648.3
A12: 31017 | B12: 722.7
A13: 31048 | B13: 523.6
... A372: 41974 | B372: 741
