Workbook

Sheet VAR1
A1: Distancia (cm) | B1: Densidad optica | C1: Promedio densidad optica (2X2) | D1: Grosor de laja (cm) | E1: ln DO | F1: Ecuación Regresión Cuña | G1: Densidad | H1: Banda | I1: Pair | J1: Fecha | L1: Year | M1: Density | N1: Extension | O1: Calcification | Q1: Year | R1: Month | S1: Y.M. | T1: Density | U1: Extension | V1: Calcification
A2: 0 | B2: 0.0769 | C2: =AVERAGE(B2:B4) -> 2.3846333 | D2: 0.753 | E2: =LN(B2) -> -2.5652494 | F2: y = 0.0026e1.3248x | G2: =(0.0026*(EXP(1.3248*E2)))/D2 -> 0.0001154127 | L2: 2015 | M2: 0.66367558 | N2: 1.5082 | O2: 1.0009555 | Q2: 2015 | R2: 12 | S2: 2015.9167 | T2: 0.86752855 | U2: 0.1523 | V2: 0.1321246
A3: 0.0152 | B3: 1.8462 | C3: =AVERAGE(B2:B5) -> 4.576925 | D3: 0.75254545 | E3: =LN(C3) -> 1.5210274 | G3: =(0.0026*(EXP(1.3248*E3)))/D3 -> 0.025916048 | L3: 2014 | M3: 0.64346974 | N3: 1.6148 | O3: 1.0390749 | Q3: 2015 | R3: 11 | S3: 2015.8333 | T3: 0.91638075 | U3: 0.1371 | V3: 0.1256358
A4: 0.0305 | B4: 5.2308 | C4: =AVERAGE(B2:B6) -> 7.0077 | D4: 0.75209091 | E4: =LN(C4) -> 1.9470095 | G4: =(0.0026*(EXP(1.3248*E4)))/D4 -> 0.045595442 | L4: 2013 | M4: 0.61306653 | N4: 1.7519 | O4: 1.0740313 | Q4: 2015 | R4: 10 | S4: 2015.75 | T4: 0.91901858 | U4: 0.1067 | V4: 0.098059282
A5: 0.0457 | B5: 11.1538 | C5: =AVERAGE(B3:B7) -> 11.26156 | D5: 0.75163636 | E5: =LN(C5) -> 2.4213952 | G5: =(0.0026*(EXP(1.3248*E5)))/D5 -> 0.085530957 | L5: 2012 | M5: 0.62324338 | N5: 1.8129 | O5: 1.1298779 | Q5: 2015 | R5: 9 | S5: 2015.6667 | T5: 0.77072903 | U5: 0.1066 | V5: 0.082159714
A6: 0.0609 | B6: 16.7308 | C6: =AVERAGE(B4:B8) -> 15.98462 | D6: 0.75118182 | E6: =LN(C6) -> 2.771627 | G6: =(0.0026*(EXP(1.3248*E6)))/D6 -> 0.13611096 | L6: 2011 | M6: 0.49989233 | N6: 1.4321 | O6: 0.71589581 | Q6: 2015 | R6: 8 | S6: 2015.5833 | T6: 0.68201024 | U6: 0.1066 | V6: 0.072702291
A7: 0.0762 | B7: 21.3462 | C7: =AVERAGE(B5:B9) -> 20.84616 | D7: 0.75072727 | E7: =LN(C7) -> 3.0371698 | G7: =(0.0026*(EXP(1.3248*E7)))/D7 -> 0.19361406 | L7: 2010 | M7: 0.63715169 | N7: 1.4472 | O7: 0.92208592 | Q7: 2015 | R7: 7 | S7: 2015.5 | T7: 0.59832239 | U7: 0.1067 | V7: 0.063840999
A8: 0.0914 | B8: 25.4615 | C8: =AVERAGE(B6:B10) -> 25.0077 | D8: 0.75027273 | E8: =LN(C8) -> 3.2191838 | F8: BASADO EN RAYOS-X VETERINARIA | G8: =(0.0026*(EXP(1.3248*E8)))/D8 -> 0.24655981 | L8: 2009 | M8: 0.5635353 | N8: 1.1426 | O8: 0.64389544 | Q8: 2015 | R8: 6 | S8: 2015.4167 | T8: 0.56464061 | U8: 0.1066 | V8: 0.060190689
A9: 0.1066 | B9: 29.5385 | C9: =AVERAGE(B7:B11) -> 28.73846 | D9: 0.74981818 | E9: =LN(C9) -> 3.3582363 | G9: =(0.0026*(EXP(1.3248*E9)))/D9 -> 0.29661275 | L9: 2008 | M9: 0.67246571 | N9: 1.2492 | O9: 0.84004416 | Q9: 2015 | R9: 5 | S9: 2015.3333 | T9: 0.57385431 | U9: 0.1067 | V9: 0.061230255
A10: 0.1219 | B10: 31.9615 | C10: =AVERAGE(B8:B12) -> 31.77692 | D10: 0.74936364 | E10: =LN(C10) -> 3.4587402 | G10: =(0.0026*(EXP(1.3248*E10)))/D10 -> 0.33906147 | L10: 2007 | M10: 0.64241555 | N10: 1.4168 | O10: 0.91017435 | Q10: 2015 | R10: 4 | S10: 2015.25 | T10: 0.559072 | U10: 0.1066 | V10: 0.059597075
A11: 0.1371 | B11: 35.3846 | C11: =AVERAGE(B9:B13) -> 34.19232 | D11: 0.74890909 | E11: =LN(C11) -> 3.5320011 | G11: =(0.0026*(EXP(1.3248*E11)))/D11 -> 0.37384607 | L11: 2006 | M11: 0.72705608 | N11: 0.8531 | O11: 0.62025154 | Q11: 2015 | R11: 3 | S11: 2015.1667 | T11: 0.49275578 | U11: 0.1066 | V11: 0.052527766
A12: 0.1523 | B12: 36.5385 | C12: =AVERAGE(B10:B14) -> 35.91538 | D12: 0.74845455 | E12: =LN(C12) -> 3.5811656 | G12: =(0.0026*(EXP(1.3248*E12)))/D12 -> 0.39924867 | L12: 2005 | M12: 0.63195382 | N12: 1.9805 | O12: 1.2515845 | Q12: 2015 | R12: 2 | S12: 2015.0833 | T12: 0.48718179 | U12: 0.1829 | V12: 0.08910555
A13: 0.1676 | B13: 37.5385 | C13: =AVERAGE(B11:B15) -> 37.19232 | D13: 0.748 | E13: =LN(C13) -> 3.6161023 | G13: =(0.0026*(EXP(1.3248*E13)))/D13 -> 0.41841596 | L13: 2004 | M13: 0.62146618 | N13: 1.234 | O13: 0.76688927 | Q13: 2015 | R13: 1 | S13: 2015 | T13: 0.56768071 | U13: 0.1828 | V13: 0.10377203
A14: 0.1828 | B14: 38.1538 | C14: =AVERAGE(B12:B16) -> 37.86156 | D14: 0.74754545 | E14: =LN(C14) -> 3.6339363 | G14: =(0.0026*(EXP(1.3248*E14)))/D14 -> 0.4286799 | L14: 2003 | M14: 0.63409067 | N14: 1.2949 | O14: 0.82108401 | Q14: 2014 | R14: 12 | S14: 2014.9167 | T14: 0.70164265 | U14: 0.198 | V14: 0.13892525
A15: 0.198 | B15: 38.3462 | C15: =AVERAGE(B13:B17) -> 38.4231 | D15: 0.74709091 | E15: =LN(C15) -> 3.6486588 | G15: =(0.0026*(EXP(1.3248*E15)))/D15 -> 0.43738905 | L15: 2002 | M15: 0.68440373 | N15: 1.2492 | O15: 0.85495714 | Q15: 2014 | R15: 11 | S15: 2014.8333 | T15: 0.83715795 | U15: 0.1828 | V15: 0.15303247
A16: 0.2133 | B16: 38.7308 | C16: =AVERAGE(B14:B18) -> 38.9231 | D16: 0.74663636 | E16: =LN(C16) -> 3.6615879 | G16: =(0.0026*(EXP(1.3248*E16)))/D16 -> 0.44521625 | L16: 2001 | M16: 0.68401499 | N16: 1.9195 | O16: 1.3129668 | Q16: 2014 | R16: 10 | S16: 2014.75 | T16: 0.90984754 | U16: 0.1219 | V16: 0.11091041
A17: 0.2285 | B17: 39.3462 | C17: =AVERAGE(B15:B19) -> 39.6231 | D17: 0.74618182 | E17: =LN(C17) -> 3.6794123 | G17: =(0.0026*(EXP(1.3248*E17)))/D17 -> 0.45613226 | L17: 2000 | M17: 0.63685605 | N17: 1.5844 | O17: 1.0090347 | Q17: 2014 | R17: 9 | S17: 2014.6667 | T17: 0.79873134 | U17: 0.1066 | V17: 0.085144761
A18: 0.2437 | B18: 40.0385 | C18: =AVERAGE(B16:B20) -> 40.35386 | D18: 0.74572727 | E18: =LN(C18) -> 3.6976871 | G18: =(0.0026*(EXP(1.3248*E18)))/D18 -> 0.46759502 | L18: 1999 | M18: 0.70072623 | N18: 1.7062 | O18: 1.1955791 | Q18: 2014 | R18: 8 | S18: 2014.5833 | T18: 0.71505648 | U18: 0.1219 | V18: 0.087165385
A19: 0.259 | B19: 41.6538 | C19: =AVERAGE(B17:B21) -> 40.99232 | D19: 0.74527273 | E19: =LN(C19) -> 3.7133847 | G19: =(0.0026*(EXP(1.3248*E19)))/D19 -> 0.47771226 | L19: 1998 | M19: 0.66170289 | N19: 1.43168 | O19: 0.94734679 | Q19: 2014 | R19: 7 | S19: 2014.5 | T19: 0.71862485 | U19: 0.1067 | V19: 0.076677272
A20: 0.2742 | B20: 42 | C20: =AVERAGE(B18:B22) -> 41.32308 | D20: 0.74481818 | E20: =LN(C20) -> 3.7214212 | G20: =(0.0026*(EXP(1.3248*E20)))/D20 -> 0.48312014 | L20: 1997 | M20: 0.65477524 | N20: 1.00518 | O20: 0.65816698 | Q20: 2014 | R20: 6 | S20: 2014.4167 | T20: 0.67705937 | U20: 0.1218 | V20: 0.082465831
... A35: 0.5027 | B35: 42.0385 | C35: =AVERAGE(B33:B37) -> 42.08462 | D35: 0.738 | E35: =LN(C35) -> 3.7396824 | G35: =(0.0026*(EXP(1.3248*E35)))/D35 -> 0.49952322 | L35: 1982 | M35: 0.81390883 | N35: 0.83765 | O35: 0.68177073 | Q35: 2013 | R35: 3 | S35: 2013.1667 | T35: 0.49232435 | U35: 0.1066 | V35: 0.052481776
A36: 0.518 | B36: 42.3077 | C36: =AVERAGE(B34:B38) -> 42.62308 | D36: 0.73754545 | E36: =LN(C36) -> 3.7523959 | G36: =(0.0026*(EXP(1.3248*E36)))/D36 -> 0.50832097 | Q36: 2013 | R36: 2 | S36: 2013.0833 | T36: 0.55152581 | U36: 0.2438 | V36: 0.13446199
A37: 0.5332 | B37: 43.0769 | C37: =AVERAGE(B35:B39) -> 43.5077 | D37: 0.73709091 | E37: =LN(C37) -> 3.7729379 | G37: =(0.0026*(EXP(1.3248*E37)))/D37 -> 0.52266654 | Q37: 2013 | R37: 1 | S37: 2013 | T37: 0.54447283 | U37: 0.2589 | V37: 0.14096402
A38: 0.5484 | B38: 44.3077 | C38: =AVERAGE(B36:B40) -> 44.53076 | D38: 0.73663636 | E38: =LN(C38) -> 3.7961802 | G38: =(0.0026*(EXP(1.3248*E38)))/D38 -> 0.53934307 | Q38: 2012 | R38: 12 | S38: 2012.9167 | T38: 0.61132453 | U38: 0.259 | V38: 0.15833305
A39: 0.5637 | B39: 45.8077 | C39: =AVERAGE(B37:B41) -> 45.70768 | D39: 0.73618182 | E39: =LN(C39) -> 3.8222663 | G39: =(0.0026*(EXP(1.3248*E39)))/D39 -> 0.55865273 | Q39: 2012 | R39: 11 | S39: 2012.8333 | T39: 0.70386958 | U39: 0.259 | V39: 0.18230222
A40: 0.5789 | B40: 47.1538 | C40: =AVERAGE(B38:B42) -> 46.80768 | D40: 0.73572727 | E40: =LN(C40) -> 3.8460473 | G40: =(0.0026*(EXP(1.3248*E40)))/D40 -> 0.57688947 | Q40: 2012 | R40: 10 | S40: 2012.75 | T40: 0.7169494 | U40: 0.1371 | V40: 0.098293762
A41: 0.5941 | B41: 48.1923 | C41: =AVERAGE(B39:B43) -> 47.6769 | D41: 0.73527273 | E41: =LN(C41) -> 3.864447 | G41: =(0.0026*(EXP(1.3248*E41)))/D41 -> 0.59148991 | Q41: 2012 | R41: 9 | S41: 2012.6667 | T41: 0.71189729 | U41: 0.1371 | V41: 0.097601119
A42: 0.6094 | B42: 48.5769 | C42: =AVERAGE(B40:B44) -> 48.22306 | D42: 0.73481818 | E42: =LN(C42) -> 3.8758373 | G42: =(0.0026*(EXP(1.3248*E42)))/D42 -> 0.60085457 | Q42: 2012 | R42: 8 | S42: 2012.5833 | T42: 0.72433934 | U42: 0.1219 | V42: 0.088296965
A43: 0.6246 | B43: 48.6538 | C43: =AVERAGE(B41:B45) -> 48.47692 | D43: 0.73436364 | E43: =LN(C43) -> 3.8810878 | G43: =(0.0026*(EXP(1.3248*E43)))/D43 -> 0.60542309 | Q43: 2012 | R43: 7 | S43: 2012.5 | T43: 0.68879372 | U43: 0.1371 | V43: 0.094433619
A44: 0.6398 | B44: 48.5385 | C44: =AVERAGE(B42:B46) -> 48.6077 | D44: 0.73390909 | E44: =LN(C44) -> 3.883782 | G44: =(0.0026*(EXP(1.3248*E44)))/D44 -> 0.60796413 | Q44: 2012 | R44: 6 | S44: 2012.4167 | T44: 0.55590263 | U44: 0.1371 | V44: 0.076214251
A45: 0.6551 | B45: 48.4231 | C45: =AVERAGE(B43:B47) -> 48.8077 | D45: 0.73345455 | E45: =LN(C45) -> 3.8878881 | G45: =(0.0026*(EXP(1.3248*E45)))/D45 -> 0.61165918 | Q45: 2012 | R45: 5 | S45: 2012.3333 | T45: 0.50041521 | U45: 0.1371 | V45: 0.068606926
A46: 0.6703 | B46: 48.8462 | C46: =AVERAGE(B44:B48) -> 49.1154 | D46: 0.733 | E46: =LN(C46) -> 3.8941726 | G46: =(0.0026*(EXP(1.3248*E46)))/D46 -> 0.61715544 | Q46: 2012 | R46: 4 | S46: 2012.25 | T46: 0.55806786 | U46: 0.1219 | V46: 0.068028472
A47: 0.6855 | B47: 49.5769 | C47: =AVERAGE(B45:B49) -> 49.52308 | D47: 0.73254545 | E47: =LN(C47) -> 3.9024388 | G47: =(0.0026*(EXP(1.3248*E47)))/D47 -> 0.62433825 | Q47: 2012 | R47: 3 | S47: 2012.1667 | T47: 0.51404475 | U47: 0.1371 | V47: 0.070475535
... A49: 0.716 | B49: 50.5769 | C49: =AVERAGE(B47:B51) -> 50.15384 | D49: 0.73163636 | E49: =LN(C49) -> 3.9150951 | G49: =(0.0026*(EXP(1.3248*E49)))/D49 -> 0.63568367 | Q49: 2012 | R49: 1 | S49: 2012 | T49: 0.59570859 | U49: 0.1218 | V49: 0.072557307
A50: 0.7312 | B50: 50.6154 | C50: =AVERAGE(B48:B52) -> 50.14616 | D50: 0.73118182 | E50: =LN(C50) -> 3.9149419 | G50: =(0.0026*(EXP(1.3248*E50)))/D50 -> 0.63594982 | H50: Alta | I50: 1 | J50: 42674 | Q50: 2011 | R50: 12 | S50: 2011.9167 | T50: 0.52924583 | U50: 0.1219 | V50: 0.064515066
A51: 0.7465 | B51: 49.8077 | C51: =AVERAGE(B49:B53) -> 49.93846 | D51: 0.73072727 | E51: =LN(C51) -> 3.9107914 | G51: =(0.0026*(EXP(1.3248*E51)))/D51 -> 0.63285601 | J51: 42666 | Q51: 2011 | R51: 11 | S51: 2011.8333 | T51: 0.51957164 | U51: 0.1219 | V51: 0.063335783
A52: 0.7617 | B52: 49.5385 | C52: =AVERAGE(B50:B54) -> 49.5077 | D52: 0.73027273 | E52: =LN(C52) -> 3.9021282 | G52: =(0.0026*(EXP(1.3248*E52)))/D52 -> 0.62602363 | J52: 42659 | Q52: 2011 | R52: 10 | S52: 2011.75 | T52: 0.53569952 | U52: 0.1066 | V52: 0.057105569
A53: 0.777 | B53: 49.1538 | C53: =AVERAGE(B51:B55) -> 48.86154 | D53: 0.72981818 | E53: =LN(C53) -> 3.8889906 | G53: =(0.0026*(EXP(1.3248*E53)))/D53 -> 0.6156053 | J53: 42652 | Q53: 2011 | R53: 9 | S53: 2011.6667 | T53: 0.50319079 | U53: 0.1067 | V53: 0.053690457
A54: 0.7922 | B54: 48.4231 | C54: =AVERAGE(B52:B56) -> 48.24616 | D54: 0.72936364 | E54: =LN(C54) -> 3.8763162 | G54: =(0.0026*(EXP(1.3248*E54)))/D54 -> 0.60573225 | J54: 42645 | Q54: 2011 | R54: 8 | S54: 2011.5833 | T54: 0.49506354 | U54: 0.1218 | V54: 0.060298739
A55: 0.8074 | B55: 47.3846 | C55: =AVERAGE(B53:B57) -> 47.6077 | D55: 0.72890909 | E55: =LN(C55) -> 3.8629945 | G55: =(0.0026*(EXP(1.3248*E55)))/D55 -> 0.59550682 | J55: 42638 | Q55: 2011 | R55: 7 | S55: 2011.5 | T55: 0.5247095 | U55: 0.1067 | V55: 0.055986504
...

Sheet VAR2-Cor
A1: HU | B1: Distancia (cm) | C1: Grosor corte (cm) | D1: Ecuación | E1: Densidad | F1: Banda | G1: Pair | H1: Fecha | J1: Year | K1: Density | L1: Extension | M1: Calcification | O1: Year | P1: Month | Q1: Y.M. | R1: Density | S1: Extension | T1: Calcification
A2: -1001.222 | B2: 0 | C2: 0.246 | E2: =(0.0705*EXP(0.0015*A2))/C$2 -> 0.063828733 | J2: 2015 | K2: 0.55656811 | L2: 0.8614 | M2: 0.47942777 | O2: 2015 | P2: 12 | Q2: 2015.9167 | R2: 0.57325735 | S2: 0.1846 | T2: 0.10582331
A3: -999.667 | B3: 0.0615 | E3: =(0.0705*EXP(0.0015*A3))/C$2 -> 0.063977788 | J3: 2014 | K3: 0.55925094 | L3: 1.5383 | M3: 0.86029572 | O3: 2015 | P3: 11 | Q3: 2015.8333 | R3: 0.58027205 | S3: 0.1846 | T3: 0.10711822
A4: -998 | B4: 0.1231 | D4: y = 2E-07e2.0844x | E4: =(0.0705*EXP(0.0015*A4))/C$2 -> 0.064137964 | J4: 2013 | K4: 0.53158003 | L4: 1.5383 | M4: 0.81772956 | O4: 2015 | P4: 10 | Q4: 2015.75 | R4: 0.58220225 | S4: 0.03075 | T4: 0.017902719
A5: -745.222 | B5: 0.1846 | E5: =(0.0705*EXP(0.0015*A5))/C$2 -> 0.093709864 | J5: 2012 | K5: 0.47941428 | L5: 0.5538 | M5: 0.26549963 | O5: 2015 | P5: 9 | Q5: 2015.6667 | R5: 0.57391305 | S5: 0.03075
A6: -470.222 | B6: 0.2461 | D6: y = 0.0705e0.0015x | E6: =(0.0705*EXP(0.0015*A6))/C$2 -> 0.14155714 | J6: 2011 | K6: 0.53532273 | L6: 1.2306 | M6: 0.65876815 | O6: 2015 | P6: 8 | Q6: 2015.5833 | R6: 0.56562386 | S6: 0.03075 | T6: 0.017392934
A7: -195 | B7: 0.3077 | E7: =(0.0705*EXP(0.0015*A7))/C$2 -> 0.21390595 | J7: 2010 | K7: 0.71623738 | L7: 0.9845 | M7: 0.70513571 | O7: 2015 | P7: 7 | Q7: 2015.5 | R7: 0.55626401 | S7: 0.03075
A8: 79.778 | B8: 0.3692 | D8: y = 0.0905e0.0013x | E8: =(0.0905*EXP(0.0013*A8))/C$2 -> 0.40808888 | J8: 2009 | K8: 0.57982415 | L8: 0.923 | M8: 0.53517769 | O8: 2015 | P8: 6 | Q8: 2015.4167 | R8: 0.54690417 | S8: 0.0308 | T8: 0.016844648
A9: 175.333 | B9: 0.4307 | E9: =(0.0905*EXP(0.0013*A9))/C$2 -> 0.46206543 | J9: 2008 | K9: 0.61774638 | L9: 1.046 | M9: 0.64616271 | O9: 2015 | P9: 5 | Q9: 2015.3333 | R9: 0.53781594 | S9: 0.0308
A10: 253 | B10: 0.4922 | E10: =(0.0905*EXP(0.0013*A10))/C$2 -> 0.51115537 | J10: 2007 | K10: 0.57284197 | L10: 1.1691 | M10: 0.66970955 | O10: 2015 | P10: 4 | Q10: 2015.25 | R10: 0.52872772 | S10: 0.03075 | T10: 0.016258377
A11: 330.889 | B11: 0.5538 | E11: =(0.0905*EXP(0.0013*A11))/C$2 -> 0.56562386 | J11: 2006 | K11: 0.67419963 | L11: 1.046 | M11: 0.70521281 | O11: 2015 | P11: 3 | Q11: 2015.1667 | R11: 0.52204348 | S11: 0.03075
A12: 408.556 | B12: 0.6153 | E12: =(0.0905*EXP(0.0013*A12))/C$2 -> 0.62571587 | J12: 2005 | K12: 0.69269255 | L12: 1.5998 | M12: 1.1081695 | O12: 2015 | P12: 2 | Q12: 2015.0833 | R12: 0.51535924 | S12: 0.1231 | T12: 0.063440722
A13: 426.111 | B13: 0.6768 | E13: =(0.0905*EXP(0.0013*A13))/C$2 -> 0.64015984 | J13: 2004 | K13: 0.57239286 | L13: 1.4768 | M13: 0.84530977 | O13: 2015 | P13: 1 | Q13: 2015 | R13: 0.53859439 | S13: 0.123 | T13: 0.066247111
A14: 437.222 | B14: 0.7384 | E14: =(0.0905*EXP(0.0013*A14))/C$2 -> 0.6494736 | J14: 2003 | K14: 0.46680923 | L14: 1.1691 | M14: 0.54574667 | O14: 2014 | P14: 12 | Q14: 2014.9167 | R14: 0.56891961 | S14: 0.1231 | T14: 0.070034004
A15: 448.333 | B15: 0.7999 | E15: =(0.0905*EXP(0.0013*A15))/C$2 -> 0.65892287 | J15: 2002 | K15: 0.44937844 | L15: 1.5383 | M15: 0.69127886 | O15: 2014 | P15: 11 | Q15: 2014.8333 | R15: 0.61539725 | S15: 0.1231 | T15: 0.075755401
A16: 459.444 | B16: 0.8614 | E16: =(0.0905*EXP(0.0013*A16))/C$2 -> 0.66850962 | F16: Alta | G16: 1 | H16: 42674 | J16: 2001 | K16: 0.57104261 | L16: 0.9845 | M16: 0.56219145 | O16: 2014 | P16: 10 | Q16: 2014.75 | R16: 0.65027706 | S16: 0.123 | T16: 0.079984078
A17: 420.889 | B17: 0.923 | E17: =(0.0905*EXP(0.0013*A17))/C$2 -> 0.63582877 | H17: 42653 | J17: 2000 | K17: 0.54047929 | L17: 0.9845 | M17: 0.53210186 | O17: 2014 | P17: 9 | Q17: 2014.6667 | R17: 0.63113995 | S17: 0.1231 | T17: 0.077693327
A18: 376.778 | B18: 0.9845 | E18: =(0.0905*EXP(0.0013*A18))/C$2 -> 0.60039333 | H18: 42633 | J18: 1999 | K18: 0.56462626 | L18: 0.7383 | M18: 0.41686357 | O18: 2014 | P18: 8 | Q18: 2014.5833 | R18: 0.6150518 | S18: 0.0615 | T18: 0.037825686
A19: 332.667 | B19: 1.046 | E19: =(0.0905*EXP(0.0013*A19))/C$2 -> 0.56693275 | H19: 42612 | J19: 1998 | K19: 0.52185128 | L19: 1.3537 | M19: 0.70643007 | O19: 2014 | P19: 7 | Q19: 2014.5 | R19: 0.58785039 | S19: 0.1231 | T19: 0.072364382
A20: 288.778 | B20: 1.1076 | E20: =(0.0905*EXP(0.0013*A20))/C$2 -> 0.53549149 | H20: 42592 | J20: 1997 | K20: 0.55743605 | L20: 0.8614 | M20: 0.48017541 | O20: 2014 | P20: 6 | Q20: 2014.4167 | R20: 0.5518141 | S20: 0.123 | T20: 0.067873134
A21: 273.111 | B21: 1.1691 | E21: =(0.0905*EXP(0.0013*A21))/C$2 -> 0.52469539 | H21: 42571 | J21: 1996 | K21: 0.5763584 | L21: 1.1076 | M21: 0.63837456 | O21: 2014 | P21: 5 | Q21: 2014.3333 | R21: 0.52826946 | S21: 0.0616 | T21: 0.032541399
A22: 261.222 | B22: 1.2306 | E22: =(0.0905*EXP(0.0013*A22))/C$2 -> 0.51664821 | H22: 42551 | J22: 1995 | K22: 0.83849307 | L22: 0.7384 | M22: 0.61914328 | O22: 2014 | P22: 4 | Q22: 2014.25 | R22: 0.50745058 | S22: 0.123 | T22: 0.062416421
A23: 249.111 | B23: 1.2922 | E23: =(0.0905*EXP(0.0013*A23))/C$2 -> 0.50857764 | H23: 42530 | J23: 1994 | K23: 0.96521834 | L23: 0.7384 | M23: 0.71271722 | O23: 2014 | P23: 3 | Q23: 2014.1667 | R23: 0.487432 | S23: 0.0616 | T23: 0.030025811
A24: 237 | B24: 1.3537 | E24: =(0.0905*EXP(0.0013*A24))/C$2 -> 0.50063315 | H24: 42510 | J24: 1993 | K24: 0.71701679 | L24: 0.7383 | M24: 0.5293735 | O24: 2014 | P24: 2 | Q24: 2014.0833 | R24: 0.48651818 | S24: 0.2461 | T24: 0.11973212
A25: 233.778 | B25: 1.4152 | E25: =(0.0905*EXP(0.0013*A25))/C$2 -> 0.49854058 | H25: 42489 | J25: 1992 | K25: 0.58411483 | L25: 0.7384 | M25: 0.43131039 | O25: 2014 | P25: 1 | Q25: 2014 | R25: 0.54468741 | S25: 0.2461 | T25: 0.13404757
A26: 231.778 | B26: 1.4767 | E26: =(0.0905*EXP(0.0013*A26))/C$2 -> 0.49724606 | H26: 42469 | J26: 1991 | K26: 0.5445475 | L26: 0.4923 | M26: 0.26808073 | O26: 2013 | P26: 12 | Q26: 2013.9167 | R26: 0.5554863 | S26: 0.2461 | T26: 0.13670518
A27: 229.667 | B27: 1.5383 | E27: =(0.0905*EXP(0.0013*A27))/C$2 -> 0.49588334 | H27: 42448 | J27: 1990 | K27: 0.51534609 | L27: 1.2306 | M27: 0.6341849 | O27: 2013 | P27: 11 | Q27: 2013.8333 | R27: 0.56515097 | S27: 0.1846 | T27: 0.10432687
A28: 227.444 | B28: 1.5998 | E28: =(0.0905*EXP(0.0013*A28))/C$2 -> 0.49445235 | F28: Baja | G28: 1 | H28: 42428 | J28: 1989 | K28: 0.47062134 | L28: 1.1075 | M28: 0.52121313 | O28: 2013 | P28: 10 | Q28: 2013.75 | R28: 0.59616751 | S28: 0.1231 | T28: 0.07338822
A29: 248.667 | B29: 1.6613 | E29: =(0.0905*EXP(0.0013*A29))/C$2 -> 0.50828418 | H29: 42418 | J29: 1988 | K29: 0.46288632 | L29: 0.6769 | M29: 0.31332775 | O29: 2013 | P29: 9 | Q29: 2013.6667 | R29: 0.55381112 | S29: 0.1231 | T29: 0.068174149
A30: 272.667 | B30: 1.7229 | E30: =(0.0905*EXP(0.0013*A30))/C$2 -> 0.52439263 | H30: 42408 | J30: 1987 | K30: 0.54598168 | L30: 1.599 | M30: 0.8730247 | O30: 2013 | P30: 8 | Q30: 2013.5833 | R30: 0.52223923 | S30: 0.123 | T30: 0.064235426
A31: 296.889 | B31: 1.7844 | E31: =(0.0905*EXP(0.0013*A31))/C$2 -> 0.54116774 | H31: 42398 | J31: 1986 | K31: 0.45427719 | L31: 0.6765 | M31: 0.30731852 | O31: 2013 | P31: 7 | Q31: 2013.5 | R31: 0.53593325 | S31: 0.1231 | T31: 0.065973384
A32: 321 | B32: 1.8459 | E32: =(0.0905*EXP(0.0013*A32))/C$2 -> 0.55839891 | H32: 42388 | J32: 1985 | K32: 0.45484561 | L32: 0.615 | M32: 0.27973005 | O32: 2013 | P32: 6 | Q32: 2013.4167 | R32: 0.54284172 | S32: 0.123 | T32: 0.066769531
A33: 329.222 | B33: 1.9075 | E33: =(0.0905*EXP(0.0013*A33))/C$2 -> 0.56439942 | H33: 42378 | J33: 1984 | K33: 0.48790943 | L33: 0.738 | M33: 0.36007716 | O33: 2013 | P33: 5 | Q33: 2013.3333 | R33: 0.51302691 | S33: 0.1231 | T33: 0.063153612
A34: 335.111 | B34: 1.969 | E34: =(0.0905*EXP(0.0013*A34))/C$2 -> 0.56873688 | H34: 42368 | J34: 1983 | K34: 0.51582154 | L34: 0.6765 | M34: 0.34895327 | O34: 2013 | P34: 4 | Q34: 2013.25 | R34: 0.48572756 | S34: 0.1231 | T34: 0.059793063
A35: 341.222 | B35: 2.0305 | E35: =(0.0905*EXP(0.0013*A35))/C$2 -> 0.57327309 | H35: 42358 | J35: 1982 | K35: 0.55014832 | L35: 0.861 | M35: 0.4736777 | O35: 2013 | P35: 3 | Q35: 2013.1667 | R35: 0.47216287 | S35: 0.123 | T35: 0.058076034
A36: 347.222 | B36: 2.0921 | E36: =(0.0905*EXP(0.0013*A36))/C$2 -> 0.5777621 | H36: 42348 | J36: 1981 | K36: 0.56111844 | L36: 1.23 | M36: 0.69017568 | O36: 2013 | P36: 2 | Q36: 2013.0833 | R36: 0.46286743 | S36: 0.0616 | T36: 0.028512634
A37: 349.111 | B37: 2.1536 | E37: =(0.0905*EXP(0.0013*A37))/C$2 -> 0.57918265 | H37: 42338 | J37: 1980 | K37: 0.60441476 | L37: 1.23 | M37: 0.74343015 | O37: 2013 | P37: 1 | Q37: 2013 | R37: 0.46541491 | S37: 0.0615 | T37: 0.028623017
A38: 350.667 | B38: 2.2151 | E38: =(0.0905*EXP(0.0013*A38))/C$2 -> 0.58035541 | H38: 42328 | J38: 1979 | K38: 0.70827506 | L38: 1.476 | M38: 1.045414 | O38: 2012 | P38: 12 | Q38: 2012.9167 | R38: 0.47055201 | S38: 0.0615 | T38: 0.028938949
A39: 351.889 | B39: 2.2767 | E39: =(0.0905*EXP(0.0013*A39))/C$2 -> 0.5812781 | H39: 42318 | J39: 1978 | K39: 0.9608996 | L39: 1.107 | M39: 1.0637159 | O39: 2012 | P39: 11 | Q39: 2012.8333 | R39: 0.47567778 | S39: 0.0616 | T39: 0.029301751
A40: 353.111 | B40: 2.3382 | E40: =(0.0905*EXP(0.0013*A40))/C$2 -> 0.58220225 | F40: Alta | G40: 2 | H40: 42308 | J40: 1977 | K40: 0.85217035 | L40: 0.984 | M40: 0.83853563 | O40: 2012 | P40: 10 | Q40: 2012.75 | R40: 0.48072001 | S40: 0.03075 | T40: 0.01478214
...

Sheet VAR2-Sag
A1: HU | B1: Distancia (cm) | C1: Grosor corte (cm) | D1: Ecuación | E1: Densidad | F1: Banda | G1: Pair | H1: Fecha | J1: Year | K1: Density | L1: Extension | M1: Calcification | O1: Year | P1: Month | Q1: Y.M. | R1: Density | S1: Extension | T1: Calcification
A2: -779.111 | B2: 0 | C2: 0.246 | E2: =(0.0705*EXP(0.0015*A2))/C$2 -> 0.089065313 | J2: 2015 | K2: 0.68483194 | L2: 0.8614 | M2: 0.58991424 | O2: 2015 | P2: 12 | Q2: 2015.9167 | R2: 0.63481949 | S2: 0.0615 | T2: 0.039041399
A3: -545.222 | B3: 0.0615 | E3: =(0.0705*EXP(0.0015*A3))/C$2 -> 0.12649508 | J3: 2014 | K3: 0.72520129 | L3: 1.7844 | M3: 1.2940492 | O3: 2015 | P3: 11 | Q3: 2015.8333 | R3: 0.67882421 | S3: 0.0616 | T3: 0.041815571
A4: -311.333 | B4: 0.1231 | E4: =(0.0705*EXP(0.0015*A4))/C$2 -> 0.17965475 | J4: 2013 | K4: 0.61657194 | L4: 1.0461 | M4: 0.64499591 | O4: 2015 | P4: 10 | Q4: 2015.75 | R4: 0.72619451 | S4: 0.0615 | T4: 0.044660962
A5: -77.556 | B5: 0.1846 | D5: y = 2E-07e2.0844x | E5: =(0.0705*EXP(0.0015*A5))/C$2 -> 0.25511195 | J5: 2012 | K5: 0.56795661 | L5: 1.5998 | M5: 0.90861699 | O5: 2015 | P5: 9 | Q5: 2015.6667 | R5: 0.72263662 | S5: 0.0615 | T5: 0.044442152
A6: 46.222 | B6: 0.2461 | D6: y = 0.0705e0.0015x | E6: =(0.0705*EXP(0.0015*A6))/C$2 -> 0.30716021 | J6: 2011 | K6: 0.7071986 | L6: 0.6768 | M6: 0.47863202 | O6: 2015 | P6: 8 | Q6: 2015.5833 | R6: 0.71175994 | S6: 0.0616 | T6: 0.043844412
A7: 159.333 | B7: 0.3077 | E7: =(0.0705*EXP(0.0015*A7))/C$2 -> 0.36395708 | J7: 2010 | K7: 0.7804929 | L7: 0.7999 | M7: 0.62431627 | O7: 2015 | P7: 7 | Q7: 2015.5 | R7: 0.70084377 | S7: 0.0615 | T7: 0.043101892
A8: 272.222 | B8: 0.3692 | D8: y = 0.0905e0.0013x | E8: =(0.0905*EXP(0.0013*A8))/C$2 -> 0.52408935 | J8: 2009 | K8: 0.71647718 | L8: 0.923 | M8: 0.66130844 | O8: 2015 | P8: 6 | Q8: 2015.4167 | R8: 0.69029421 | S8: 0.0615 | T8: 0.042453094
A9: 385.333 | B9: 0.4307 | E9: =(0.0905*EXP(0.0013*A9))/C$2 -> 0.60710788 | J9: 2008 | K9: 0.72778713 | L9: 1.5383 | M9: 1.1195549 | O9: 2015 | P9: 5 | Q9: 2015.3333 | R9: 0.68246176 | S9: 0.0616 | T9: 0.042039644
A10: 477.667 | B10: 0.4922 | E10: =(0.0905*EXP(0.0013*A10))/C$2 -> 0.68453563 | J10: 2007 | K10: 0.76188545 | L10: 1.046 | M10: 0.79693218 | O10: 2015 | P10: 4 | Q10: 2015.25 | R10: 0.67510862 | S10: 0.0615 | T10: 0.04151918
A11: 568 | B11: 0.5538 | E11: =(0.0905*EXP(0.0013*A11))/C$2 -> 0.76983299 | J11: 2006 | K11: 0.70168022 | L11: 1.4152 | M11: 0.99301785 | O11: 2015 | P11: 3 | Q11: 2015.1667 | R11: 0.66793108 | S11: 0.0615 | T11: 0.041077761
A12: 658.111 | B12: 0.6153 | E12: =(0.0905*EXP(0.0013*A12))/C$2 -> 0.8655091 | J12: 2005 | K12: 0.73738 | L12: 0.7384 | M12: 0.54448139 | O12: 2015 | P12: 2 | Q12: 2015.0833 | R12: 0.66462151 | S12: 0.1231 | T12: 0.081814908
A13: 748.333 | B13: 0.6768 | E13: =(0.0905*EXP(0.0013*A13))/C$2 -> 0.97321643 | J13: 2004 | K13: 0.65270174 | L13: 0.4923 | M13: 0.32132506 | O13: 2015 | P13: 1 | Q13: 2015 | R13: 0.683765 | S13: 0.123 | T13: 0.084103096
A14: 688.333 | B14: 0.7384 | E14: =(0.0905*EXP(0.0013*A14))/C$2 -> 0.90019058 | J14: 2003 | K14: 0.61685101 | L14: 1.3536 | M14: 0.83496953 | O14: 2014 | P14: 12 | Q14: 2014.9167 | R14: 0.7175569 | S14: 0.1231 | T14: 0.088331254
A15: 611.778 | B15: 0.7999 | E15: =(0.0905*EXP(0.0013*A15))/C$2 -> 0.81491596 | J15: 2002 | K15: 0.51789733 | L15: 1.2922 | M15: 0.66922693 | O15: 2014 | P15: 11 | Q15: 2014.8333 | R15: 0.80018585 | S15: 0.1231 | T15: 0.098502878
A16: 535.222 | B16: 0.8614 | E16: =(0.0905*EXP(0.0013*A16))/C$2 -> 0.73771841 | J16: 2001 | K16: 0.66615993 | L16: 0.8614 | M16: 0.57383016 | O16: 2014 | P16: 10 | Q16: 2014.75 | R16: 0.86453176 | S16: 0.1846 | T16: 0.15959256
A17: 458.556 | B17: 0.923 | E17: =(0.0905*EXP(0.0013*A17))/C$2 -> 0.66773834 | J17: 2000 | K17: 0.86216969 | L17: 1.5998 | M17: 1.3792991 | O17: 2014 | P17: 9 | Q17: 2014.6667 | R17: 0.83120833 | S17: 0.1846 | T17: 0.15344106
A18: 432.667 | B18: 0.9845 | E18: =(0.0905*EXP(0.0013*A18))/C$2 -> 0.64563911 | J18: 1999 | K18: 0.63715476 | L18: 1.2307 | M18: 0.78414636 | O18: 2014 | P18: 8 | Q18: 2014.5833 | R18: 0.78839503 | S18: 0.123 | T18: 0.096972589
A19: 412.778 | B19: 1.046 | E19: =(0.0905*EXP(0.0013*A19))/C$2 -> 0.62915962 | J19: 1998 | K19: 0.53923241 | L19: 1.4767 | M19: 0.79628451 | O19: 2014 | P19: 7 | Q19: 2014.5 | R19: 0.7511015 | S19: 0.1846 | T19: 0.13865334
A20: 392.778 | B20: 1.1076 | E20: =(0.0905*EXP(0.0013*A20))/C$2 -> 0.6130123 | J20: 1997 | K20: 0.58066726 | L20: 1.2306 | M20: 0.71456913 | O20: 2014 | P20: 6 | Q20: 2014.4167 | R20: 0.72070569 | S20: 0.1846 | T20: 0.13304227
... A28: 323.111 | B28: 1.5998 | E28: =(0.0905*EXP(0.0013*A28))/C$2 -> 0.55993343 | J28: 1989 | K28: 0.68310391 | L28: 0.4922 | M28: 0.33622375 | O28: 2013 | P28: 10 | Q28: 2013.75 | R28: 0.61875428 | S28: 0.1231 | T28: 0.076168652
A29: 322.556 | B29: 1.6613 | E29: =(0.0905*EXP(0.0013*A29))/C$2 -> 0.55952958 | F29: Baja | G29: 1 | H29: 42428 | J29: 1988 | K29: 0.58654659 | L29: 1.2306 | M29: 0.72180423 | O29: 2013 | P29: 9 | Q29: 2013.6667 | R29: 0.60904064 | S29: 0.0615 | T29: 0.037455999
A30: 367.556 | B30: 1.7229 | E30: =(0.0905*EXP(0.0013*A30))/C$2 -> 0.59323843 | H30: 42398 | J30: 1987 | K30: 0.57184016 | L30: 0.7999 | M30: 0.45741494 | O30: 2013 | P30: 8 | Q30: 2013.5833 | R30: 0.59845597 | S30: 0.1231 | T30: 0.07366993
A31: 419.667 | B31: 1.7844 | E31: =(0.0905*EXP(0.0013*A31))/C$2 -> 0.63481949 | H31: 42368 | J31: 1986 | K31: 1.0707289 | L31: 0.7384 | M31: 0.79062621 | O31: 2013 | P31: 7 | Q31: 2013.5 | R31: 0.60623166 | S31: 0.0615 | T31: 0.037283247
A32: 471.222 | B32: 1.8459 | E32: =(0.0905*EXP(0.0013*A32))/C$2 -> 0.67882421 | H32: 42338 | J32: 1985 | K32: 1.1055051 | L32: 1.1691 | M32: 1.2924461 | O32: 2013 | P32: 6 | Q32: 2013.4167 | R32: 0.63099043 | S32: 0.1231 | T32: 0.077674922
A33: 523.111 | B33: 1.9075 | E33: =(0.0905*EXP(0.0013*A33))/C$2 -> 0.72619451 | F33: Alta | G33: 2 | H33: 42308 | J33: 1984 | K33: 0.84668658 | L33: 0.9845 | M33: 0.83356294 | O33: 2013 | P33: 5 | Q33: 2013.3333 | R33: 0.65664313 | S33: 0.0615 | T33: 0.040383553
A34: 519.333 | B34: 1.969 | E34: =(0.0905*EXP(0.0013*A34))/C$2 -> 0.72263662 | H34: 42277 | J34: 1983 | K34: 1.0358757 | L34: 1.2306 | M34: 1.2747486 | O34: 2013 | P34: 4 | Q34: 2013.25 | R34: 0.63795429 | S34: 0.1231 | T34: 0.078532173
A35: 507.667 | B35: 2.0305 | E35: =(0.0905*EXP(0.0013*A35))/C$2 -> 0.71175994 | H35: 42246 | J35: 1982 | K35: 0.94772207 | L35: 0.9845 | M35: 0.93303238 | O35: 2013 | P35: 3 | Q35: 2013.1667 | R35: 0.61274618 | S35: 0.0615 | T35: 0.03768389
A36: 495.778 | B36: 2.0921 | E36: =(0.0905*EXP(0.0013*A36))/C$2 -> 0.70084377 | H36: 42216 | J36: 1981 | K36: 1.2480592 | L36: 1.7229 | M36: 2.1502812 | O36: 2013 | P36: 2 | Q36: 2013.0833 | R36: 0.59650343 | S36: 0.0615 | T36: 0.036684961
A37: 484.111 | B37: 2.1536 | E37: =(0.0905*EXP(0.0013*A37))/C$2 -> 0.69029421 | H37: 42185 | J37: 1980 | K37: 1.1085151 | L37: 0.9845 | M37: 1.0913331 | O37: 2013 | P37: 1 | Q37: 2013 | R37: 0.60465751 | S37: 0.0616 | T37: 0.037246902
A38: 475.333 | B38: 2.2151 | E38: =(0.0905*EXP(0.0013*A38))/C$2 -> 0.68246176 | H38: 42154 | J38: 1979 | K38: 0.92895007 | L38: 0.9845 | M38: 0.91455134 | O38: 2012 | P38: 12 | Q38: 2012.9167 | R38: 0.619152 | S38: 0.0615 | T38: 0.038077848
A39: 467 | B39: 2.2767 | E39: =(0.0905*EXP(0.0013*A39))/C$2 -> 0.67510862 | H39: 42124 | J39: 1978 | K39: 1.0179565 | L39: 1.2306 | M39: 1.2526972 | O39: 2012 | P39: 11 | Q39: 2012.8333 | R39: 0.63426928 | S39: 0.0615 | T39: 0.039007561
A40: 458.778 | B40: 2.3382 | E40: =(0.0905*EXP(0.0013*A40))/C$2 -> 0.66793108 | H40: 42093 | J40: 1977 | K40: 0.96786863 | L40: 0.8611 | M40: 0.83343168 | O40: 2012 | P40: 10 | Q40: 2012.75 | R40: 0.62108366 | S40: 0.1846 | T40: 0.11465204
A41: 450.556 | B41: 2.3997 | E41: =(0.0905*EXP(0.0013*A41))/C$2 -> 0.66082985 | F41: Baja | G41: 2 | H41: 42063 | J41: 1976 | K41: 0.89586622 | L41: 1.0455 | M41: 0.93662814 | O41: 2012 | P41: 9 | Q41: 2012.6667 | R41: 0.54049374 | S41: 0.1231 | T41: 0.066534779
A42: 459.333 | B42: 2.4612 | E42: =(0.0905*EXP(0.0013*A42))/C$2 -> 0.66841317 | H42: 42048 | J42: 1975 | K42: 1.0288853 | L42: 1.1685 | M42: 1.2022525 | O42: 2012 | P42: 8 | Q42: 2012.5833 | R42: 0.52442574 | S42: 0.1846 | T42: 0.096808991
A43: 470.889 | B43: 2.5228 | E43: =(0.0905*EXP(0.0013*A43))/C$2 -> 0.67853041 | H43: 42033 | J43: 1974 | K43: 1.3502971 | L43: 1.4145 | M43: 1.9099953 | O43: 2012 | P43: 7 | Q43: 2012.5 | R43: 0.5254139 | S43: 0.1231 | T43: 0.064678451
A44: 482.667 | B44: 2.5843 | E44: =(0.0905*EXP(0.0013*A44))/C$2 -> 0.6889996 | H44: 42018 | J44: 1973 | K44: 1.3861295 | L44: 1.0455 | M44: 1.4491984 | O44: 2012 | P44: 6 | Q44: 2012.4167 | R44: 0.48657289 | S44: 0.1845 | T44: 0.089772699
A45: 494.444 | B45: 2.6458 | E45: =(0.0905*EXP(0.0013*A45))/C$2 -> 0.69962942 | H45: 42003 | J45: 1972 | K45: 0.91825614 | L45: 0.984 | M45: 0.90356404 | O45: 2012 | P45: 5 | Q45: 2012.3333 | R45: 0.5126037 | S45: 0.1231 | T45: 0.063101515
A46: 532.889 | B46: 2.7074 | E46: =(0.0905*EXP(0.0013*A46))/C$2 -> 0.73548437 | H46: 41988 | J46: 1971 | K46: 0.9551422 | L46: 1.1685 | M46: 1.1160837 | O46: 2012 | P46: 4 | Q46: 2012.25 | R46: 0.60061068 | S46: 0.1846 | T46: 0.11087273
A47: 575.889 | B47: 2.7689 | E47: =(0.0905*EXP(0.0013*A47))/C$2 -> 0.77776879 | H47: 41973 | J47: 1970 | K47: 0.97622747 | L47: 0.984 | M47: 0.96060783 | O47: 2012 | P47: 3 | Q47: 2012.1667 | R47: 0.59705189 | S47: 0.1231 | T47: 0.073497088
...

Sheet VAR3-Cor
A1: HU | B1: Distancia (cm) | C1: Grosor corte (cm) | D1: Ecuación | E1: Densidad | F1: Banda | G1: Pair | H1: Fecha | J1: Year | K1: Density | L1: Extension | M1: Calcification | O1: Year | P1: Month | Q1: M.Y. | R1: Density | S1: Extension | T1: Calcification
A2: -998 | B2: 0 | C2: 0.246 | E2: =(0.0905*EXP(0.0013*A2))/C$2 -> 0.1005217 | J2: 2015 | K2: 1.2219735 | L2: 0.6768 | M2: 0.82703169 | O2: 2015 | P2: 12 | Q2: 2015.9167 | R2: 0.92136572 | S2: 0.1231 | T2: 0.11342012
A3: -986 | B3: 0.0615 | E3: =(0.0905*EXP(0.0013*A3))/C$2 -> 0.10210213 | J3: 2014 | K3: 0.86446535 | L3: 1.2922 | M3: 1.1170621 | O3: 2015 | P3: 11 | Q3: 2015.8333 | R3: 1.1876149 | S3: 0.123 | T3: 0.14607664
A4: -973 | B4: 0.1231 | D4: y = 2E-07e2.0844x | E4: =(0.0905*EXP(0.0013*A4))/C$2 -> 0.10384232 | J4: 2013 | K4: 0.7433444 | L4: 0.4307 | M4: 0.32015843 | O4: 2015 | P4: 10 | Q4: 2015.75 | R4: 1.4376294 | S4: 0.0616 | T4: 0.088557972
A5: -959.778 | B5: 0.1846 | E5: =(0.0905*EXP(0.0013*A5))/C$2 -> 0.10564265 | J5: 2012 | K5: 0.93441808 | L5: 0.7999 | M5: 0.74744102 | O5: 2015 | P5: 9 | Q5: 2015.6667 | R5: 1.4135376 | S5: 0.03075 | T5: 0.043466282
A6: -946.667 | B6: 0.2461 | D6: y = 0.0705e0.0015x | E6: =(0.0905*EXP(0.0013*A6))/C$2 -> 0.10745869 | J6: 2011 | K6: 1.3073053 | L6: 0.9845 | M6: 1.287042 | O6: 2015 | P6: 8 | Q6: 2015.5833 | R6: 1.3849358 | S6: 0.03075
A7: -642.444 | B7: 0.3077 | E7: =(0.0905*EXP(0.0013*A7))/C$2 -> 0.15958814 | J7: 2010 | K7: 0.73758533 | L7: 0.7384 | M7: 0.54463301 | O7: 2015 | P7: 7 | Q7: 2015.5 | R7: 1.3563339 | S7: 0.0615 | T7: 0.083414536
A8: -308.333 | B8: 0.3692 | D8: y = 0.0905e0.0013x | E8: =(0.0905*EXP(0.0013*A8))/C$2 -> 0.24639617 | J8: 2009 | K8: 0.72177388 | L8: 0.8614 | M8: 0.62173602 | O8: 2015 | P8: 6 | Q8: 2015.4167 | R8: 1.3016313 | S8: 0.03075 | T8: 0.040025162
A9: 26.111 | B9: 0.4307 | E9: =(0.0905*EXP(0.0013*A9))/C$2 -> 0.38058818 | J9: 2008 | K9: 0.67579701 | L9: 0.4923 | M9: 0.33269487 | O9: 2015 | P9: 5 | Q9: 2015.3333 | R9: 1.2754732 | S9: 0.03075
A10: 360.667 | B10: 0.4922 | E10: =(0.0905*EXP(0.0013*A10))/C$2 -> 0.58794928 | J10: 2007 | K10: 0.69853794 | L10: 1.3537 | M10: 0.94561081 | O10: 2015 | P10: 4 | Q10: 2015.25 | R10: 1.2493151 | S10: 0.0308 | T10: 0.038478906
A11: 412.556 | B11: 0.5538 | E11: =(0.0905*EXP(0.0013*A11))/C$2 -> 0.62897807 | J11: 2006 | K11: 0.95251664 | L11: 0.7999 | M11: 0.76191806 | O11: 2015 | P11: 3 | Q11: 2015.1667 | R11: 1.242674 | S11: 0.0308
A12: 433.222 | B12: 0.6153 | E12: =(0.0905*EXP(0.0013*A12))/C$2 -> 0.64610511 | J12: 2005 | K12: 0.55090301 | L12: 1.4767 | M12: 0.81351847 | O12: 2015 | P12: 2 | Q12: 2015.0833 | R12: 1.2360328 | S12: 0.0615 | T12: 0.076016019
A13: 454.222 | B13: 0.6768 | E13: =(0.0905*EXP(0.0013*A13))/C$2 -> 0.66398675 | J13: 2004 | K13: 0.55635059 | L13: 0.7999 | M13: 0.44502484 | O13: 2015 | P13: 1 | Q13: 2015 | R13: 1.2292673 | S13: 0.0615 | T13: 0.07559994
A14: 474.778 | B14: 0.7384 | E14: =(0.0905*EXP(0.0013*A14))/C$2 -> 0.68196954 | J14: 2003 | K14: 0.62595563 | L14: 0.6769 | M14: 0.42370937 | O14: 2014 | P14: 12 | Q14: 2014.9167 | R14: 1.2220081 | S14: 0.0616 | T14: 0.075275701
A15: 473.222 | B15: 0.7999 | E15: =(0.0905*EXP(0.0013*A15))/C$2 -> 0.68059145 | J15: 2002 | K15: 0.78968726 | L15: 0.9229 | M15: 0.72880238 | O15: 2014 | P15: 11 | Q15: 2014.8333 | R15: 1.2158472 | S15: 0.0615 | T15: 0.074774603
A16: 469.222 | B16: 0.8614 | E16: =(0.0905*EXP(0.0013*A16))/C$2 -> 0.67706156 | J16: 2001 | K16: 0.57784011 | L16: 0.923 | M16: 0.53334642 | O16: 2014 | P16: 10 | Q16: 2014.75 | R16: 1.201454 | S16: 0.1231 | T16: 0.14789899
A17: 465 | B17: 0.923 | E17: =(0.0905*EXP(0.0013*A17))/C$2 -> 0.67335562 | J17: 2000 | K17: 0.66791998 | L17: 0.9845 | M17: 0.65756722 | O17: 2014 | P17: 9 | Q17: 2014.6667 | R17: 1.1821727 | S17: 0.123 | T17: 0.14540725
A18: 460.667 | B18: 0.9845 | E18: =(0.0905*EXP(0.0013*A18))/C$2 -> 0.66957333 | J18: 1999 | K18: 0.79194921 | L18: 0.8614 | M18: 0.68218505 | O18: 2014 | P18: 8 | Q18: 2014.5833 | R18: 1.1017886 | S18: 0.1231 | T18: 0.13563018
A19: 571.222 | B19: 1.046 | E19: =(0.0905*EXP(0.0013*A19))/C$2 -> 0.77306427 | J19: 1998 | K19: 1.1086827 | L19: 0.7384 | M19: 0.81865132 | O19: 2014 | P19: 7 | Q19: 2014.5 | R19: 1.000157 | S19: 0.1231 | T19: 0.12311933
A20: 695.889 | B20: 1.1076 | E20: =(0.0905*EXP(0.0013*A20))/C$2 -> 0.90907654 | J20: 1997 | K20: 1.1062872 | L20: 0.5538 | M20: 0.61266186 | O20: 2014 | P20: 6 | Q20: 2014.4167 | R20: 0.8258269 | S20: 0.123 | T20: 0.10157671
A21: 820.667 | B21: 1.1691 | E21: =(0.0905*EXP(0.0013*A21))/C$2 -> 1.069173 | J21: 1996 | K21: 0.98367171 | L21: 0.923 | M21: 0.90792899 | O21: 2014 | P21: 5 | Q21: 2014.3333 | R21: 0.64910072 | S21: 0.1231 | T21: 0.079904299
A22: 945.444 | B22: 1.2306 | E22: =(0.0905*EXP(0.0013*A22))/C$2 -> 1.2574621 | F22: Alta | G22: 1 | H22: 42674 | J22: 1995 | K22: 0.95665435 | L22: 1.1075 | M22: 1.0594947 | O22: 2014 | P22: 4 | Q22: 2014.25 | R22: 0.56720743 | S22: 0.123 | T22: 0.069766514
A23: 898.667 | B23: 1.2922 | E23: =(0.0905*EXP(0.0013*A23))/C$2 -> 1.1832743 | H23: 42643 | J23: 1994 | K23: 0.79267224 | L23: 0.8615 | M23: 0.68288714 | O23: 2014 | P23: 3 | Q23: 2014.1667 | R23: 0.53433228 | S23: 0.0616 | T23: 0.032914868
A24: 829.111 | B24: 1.3537 | E24: =(0.0905*EXP(0.0013*A24))/C$2 -> 1.0809741 | H24: 42612 | J24: 1993 | K24: 0.61590152 | L24: 0.9845 | M24: 0.60635505 | O24: 2014 | P24: 2 | Q24: 2014.0833 | R24: 0.51789899 | S24: 0.123 | T24: 0.063701576
A25: 759.444 | B25: 1.4152 | E25: =(0.0905*EXP(0.0013*A25))/C$2 -> 0.98737588 | H25: 42581 | J25: 1992 | K25: 0.66087751 | L25: 1.5998 | M25: 1.0572718 | O25: 2014 | P25: 1 | Q25: 2014 | R25: 0.54518592 | S25: 0.1231 | T25: 0.067112387
A26: 689.778 | B26: 1.4767 | E26: =(0.0905*EXP(0.0013*A26))/C$2 -> 0.90188317 | H26: 42551 | J26: 1991 | K26: 0.8167864 | L26: 0.4922 | M26: 0.40202227 | O26: 2013 | P26: 12 | Q26: 2013.9167 | R26: 0.59223685 | S26: 0.1231 | T26: 0.072904356
A27: 633.778 | B27: 1.5383 | E27: =(0.0905*EXP(0.0013*A27))/C$2 -> 0.83855904 | H27: 42520 | J27: 1990 | K27: 0.7792692 | L27: 0.6153 | M27: 0.47948434 | O27: 2013 | P27: 11 | Q27: 2013.8333 | R27: 0.67306418 | S27: 0.0615 | T27: 0.041393447
A28: 579.778 | B28: 1.5998 | E28: =(0.0905*EXP(0.0013*A28))/C$2 -> 0.78171091 | H28: 42489 | J28: 1989 | K28: 0.74153386 | L28: 1.1076 | M28: 0.8213229 | O28: 2013 | P28: 10 | Q28: 2013.75 | R28: 0.73622862 | S28: 0.0076875 | T28: 0.02263903
A29: 525.889 | B29: 1.6613 | E29: =(0.0905*EXP(0.0013*A29))/C$2 -> 0.72882183 | H29: 42458 | J29: 1988 | K29: 0.75387228 | L29: 0.9845 | M29: 0.74218726 | O29: 2013 | P29: 9 | Q29: 2013.6667 | R29: 0.75350166 | S29: 0.0076875
A30: 471.778 | B30: 1.7229 | E30: =(0.0905*EXP(0.0013*A30))/C$2 -> 0.67931504 | F30: Baja | G30: 1 | H30: 42428 | J30: 1987 | K30: 0.52984531 | L30: 1.1076 | M30: 0.58685667 | O30: 2013 | P30: 8 | Q30: 2013.5833 | R30: 0.7707747 | S30: 0.0076875
A31: 508.444 | B31: 1.7844 | E31: =(0.0905*EXP(0.0013*A31))/C$2 -> 0.71247925 | H31: 42413 | J31: 1986 | K31: 0.8235714 | L31: 1.4767 | M31: 1.2161679 | O31: 2013 | P31: 7 | Q31: 2013.5 | R31: 0.78804775 | S31: 0.0076875
A32: 558.556 | B32: 1.8459 | E32: =(0.0905*EXP(0.0013*A32))/C$2 -> 0.76043938 | H32: 42398 | J32: 1985 | K32: 0.87659393 | L32: 0.9845 | M32: 0.86300672 | O32: 2013 | P32: 6 | Q32: 2013.4167 | R32: 0.80532079 | S32: 0.0077 | T32: 0.02480388
A33: 608.556 | B33: 1.9075 | E33: =(0.0905*EXP(0.0013*A33))/C$2 -> 0.81150974 | H33: 42383 | J33: 1984 | K33: 0.73665796 | L33: 0.9845 | M33: 0.72523976 | O33: 2013 | P33: 5 | Q33: 2013.3333 | R33: 0.82127609 | S33: 0.0077
A34: 658.667 | B34: 1.969 | E34: =(0.0905*EXP(0.0013*A34))/C$2 -> 0.86613492 | H34: 42368 | J34: 1983 | K34: 0.63879412 | L34: 1.2306 | M34: 0.78610004 | O34: 2013 | P34: 4 | Q34: 2013.25 | R34: 0.83723138 | S34: 0.0077
A35: 751 | B35: 2.0305 | E35: =(0.0905*EXP(0.0013*A35))/C$2 -> 0.97659653 | H35: 42353 | J35: 1982 | K35: 0.66197748 | L35: 0.9845 | M35: 0.65171683 | O35: 2013 | P35: 3 | Q35: 2013.1667 | R35: 0.85318668 | S35: 0.0077
A36: 850.333 | B36: 2.0921 | E36: =(0.0905*EXP(0.0013*A36))/C$2 -> 1.1112119 | H36: 42338 | J36: 1981 | K36: 0.81809461 | L36: 0.9845 | M36: 0.80541414 | O36: 2013 | P36: 2 | Q36: 2013.0833 | R36: 0.86914198 | S36: 0.0615 | T36: 0.053452232
A37: 949.444 | B37: 2.1536 | E37: =(0.0905*EXP(0.0013*A37))/C$2 -> 1.264018 | H37: 42323 | J37: 1980 | K37: 0.60342128 | L37: 0.9845 | M37: 0.59406825 | O37: 2013 | P37: 1 | Q37: 2013 | R37: 0.93518156 | S37: 0.0615 | T37: 0.057513666
A38: 1048.444 | B38: 2.2151 | E38: =(0.0905*EXP(0.0013*A38))/C$2 -> 1.4376294 | F38: Alta | G38: 2 | H38: 42308 | J38: 1979 | K38: 0.82015152 | L38: 0.8615 | M38: 0.70656053 | O38: 2012 | P38: 12 | Q38: 2012.9167 | R38: 1.0060925 | S38: 0.03075 | T38: 0.030937344
A39: 1035.444 | B39: 2.2767 | E39: =(0.0905*EXP(0.0013*A39))/C$2 -> 1.4135376 | H39: 42259 | J39: 1978 | K39: 0.62185208 | L39: 0.7995 | M39: 0.49717074 | O39: 2012 | P39: 11 | Q39: 2012.8333 | R39: 1.0444707 | S39: 0.03075
A40: 1003.667 | B40: 2.3382 | E40: =(0.0905*EXP(0.0013*A40))/C$2 -> 1.3563339 | H40: 42210 | J40: 1977 | K40: 0.63915206 | L40: 0.984 | M40: 0.62892563 | O40: 2012 | P40: 10 | Q40: 2012.75 | R40: 1.082849 | S40: 0.0308 | T40: 0.033351749
...

Sheet VAR3-Sag
A1: HU | B1: Moving average | C1: Distancia (cm) | D1: Grosor corte (cm) | E1: Ecuación | F1: Densidad | G1: Banda | H1: Pair | I1: Fecha | K1: Year | L1: Density | M1: Extension | N1: Calcification | P1: Year | Q1: Month | R1: M.Y. | S1: Density | T1: Extension | U1: Calcification
A2: -992.889 | B2: =AVERAGE(A2:A3) -> -992.278 | C2: 0 | D2: 0.246 | F2: =(0.0905*EXP(0.0013*B2))/D$2 -> 0.10127223 | K2: 2015 | L2: 0.82357811 | M2: 0.73837 | N2: 0.60810537 | P2: 2015 | Q2: 12 | R2: 2015.9167 | S2: 0.89298771 | T2: 0.12307 | U2: 0.1099
A3: -991.667 | B3: =AVERAGE(A2:A4) -> -873.07433 | C3: 0.06153 | F3: =(0.0905*EXP(0.0013*B3))/D$2 -> 0.11824715 | K3: 2014 | L3: 0.58014103 | M3: 0.73836 | N3: 0.42835293 | P3: 2015 | Q3: 11 | R3: 2015.8333 | S3: 1.0770796 | T3: 0.12306 | U3: 0.13254541
A4: -634.667 | B4: =AVERAGE(A3:A5) -> -623.14833 | C4: 0.12306 | F4: =(0.0905*EXP(0.0013*B4))/D$2 -> 0.16364194 | K4: 2013 | L4: 0.77039062 | M4: 0.6153 | N4: 0.47402135 | P4: 2015 | Q4: 10 | R4: 2015.75 | S4: 1.18259 | T4: 0.06153 | U4: 0.07276476
A5: -243.111 | B5: =AVERAGE(A4:A6) -> -243.11133 | C5: 0.18459 | E5: y = 2E-07e2.0844x | F5: =(0.0905*EXP(0.0013*B5))/D$2 -> 0.2681989 | K5: 2012 | L5: 0.78599307 | M5: 0.6153 | N5: 0.48362153 | P5: 2015 | Q5: 9 | R5: 2015.6667 | S5: 1.0111914 | T5: 0.06153 | U5: 0.062218609
A6: 148.444 | B6: =AVERAGE(A5:A7) -> 148.40733 | C6: 0.24612 | E6: y = 0.0705e0.0015x | F6: =(0.0905*EXP(0.0013*B6))/D$2 -> 0.44617137 | K6: 2011 | L6: 0.99690064 | M6: 0.49224 | N6: 0.49071437 | P6: 2015 | Q6: 8 | R6: 2015.5833 | S6: 0.83276478 | T6: 0.030765 | U6: 0.025620009
A7: 539.889 | B7: =AVERAGE(A6:A8) -> 407.51833 | C7: 0.30766 | E7: y = 0.0905e0.0013x | F7: =(0.0905*EXP(0.0013*B7))/D$2 -> 0.62487237 | K7: 2010 | L7: 0.85682386 | M7: 0.73836 | N7: 0.63264447 | P7: 2015 | Q7: 7 | R7: 2015.5 | S7: 0.74218421 | T7: 0.030765
A8: 534.222 | B8: =AVERAGE(A7:A9) -> 520.44433 | C8: 0.36919 | F8: =(0.0905*EXP(0.0013*B8))/D$2 -> 0.72368139 | K8: 2009 | L8: 0.81481624 | M8: 0.67683 | N8: 0.55149208 | P8: 2015 | Q8: 6 | R8: 2015.4167 | S8: 0.65160364 | T8: 0.06153 | U8: 0.040093172
A9: 487.222 | B9: =AVERAGE(A8:A10) -> 487.296 | C9: 0.43072 | F9: =(0.0905*EXP(0.0013*B9))/D$2 -> 0.6931583 | K9: 2008 | L9: 0.71582633 | M9: 0.6153 | N9: 0.44044794 | P9: 2015 | Q9: 5 | R9: 2015.3333 | S9: 0.60740049 | T9: 0.06153 | U9: 0.037373352
A10: 440.444 | B10: =AVERAGE(A9:A11) -> 440.44433 | C10: 0.49225 | F10: =(0.0905*EXP(0.0013*B10))/D$2 -> 0.65219998 | K10: 2007 | L10: 0.68420154 | M10: 0.6153 | N10: 0.42098921 | P10: 2015 | Q10: 4 | R10: 2015.25 | S10: 0.56644138 | T10: 0.030765 | U10: 0.017426569
A11: 393.667 | B11: =AVERAGE(A10:A12) -> 395.963 | C11: 0.55378 | F11: =(0.0905*EXP(0.0013*B11))/D$2 -> 0.61555573 | K11: 2006 | L11: 0.67755301 | M11: 0.67683 | N11: 0.45858821 | P11: 2015 | Q11: 3 | R11: 2015.1667 | S11: 0.55568713 | T11: 0.030765
A12: 353.778 | B12: =AVERAGE(A11:A13) -> 354.18533 | C12: 0.61531 | F12: =(0.0905*EXP(0.0013*B12))/D$2 -> 0.58301594 | K12: 2005 | L12: 1.0003059 | M12: 0.98448 | N12: 0.98478117 | P12: 2015 | Q12: 2 | R12: 2015.0833 | S12: 0.54493288 | T12: 0.06153 | U12: 0.03352972
A13: 315.111 | B13: =AVERAGE(A12:A14) -> 315.037 | C13: 0.67684 | F13: =(0.0905*EXP(0.0013*B13))/D$2 -> 0.55408699 | K13: 2004 | L13: 0.80676533 | M13: 0.43071 | N13: 0.3474819 | P13: 2015 | Q13: 1 | R13: 2015 | S13: 0.54587825 | T13: 0.06153 | U13: 0.033587889
A14: 276.222 | B14: =AVERAGE(A13:A15) -> 276.259 | C14: 0.73837 | F14: =(0.0905*EXP(0.0013*B14))/D$2 -> 0.52684706 | K14: 2003 | L14: 0.52945631 | M14: 1.10754 | N14: 0.58639404 | P14: 2014 | Q14: 12 | R14: 2014.9167 | S14: 0.5650795 | T14: 0.06153 | U14: 0.034769342
A15: 237.444 | B15: =AVERAGE(A14:A16) -> 274.148 | C15: 0.79991 | F15: =(0.0905*EXP(0.0013*B15))/D$2 -> 0.52540321 | K15: 2002 | L15: 0.50029425 | M15: 1.2306 | N15: 0.6156621 | P15: 2014 | Q15: 11 | R15: 2014.8333 | S15: 0.59095747 | T15: 0.06153 | U15: 0.036361613
A16: 308.778 | B16: =AVERAGE(A15:A17) -> 313.185 | C16: 0.86144 | F16: =(0.0905*EXP(0.0013*B16))/D$2 -> 0.55275457 | K16: 2001 | L16: 0.53860149 | M16: 0.79989 | N16: 0.43082195 | P16: 2014 | Q16: 10 | R16: 2014.75 | S16: 0.60742971 | T16: 0.06153 | U16: 0.03737515
A17: 393.333 | B17: =AVERAGE(A16:A18) -> 393.22233 | C17: 0.92297 | F17: =(0.0905*EXP(0.0013*B17))/D$2 -> 0.61336649 | K17: 2000 | L17: 0.81153847 | M17: 0.67683 | N17: 0.54927358 | P17: 2014 | Q17: 9 | R17: 2014.6667 | S17: 0.60675729 | T17: 0.030765 | U17: 0.018666888
A18: 477.556 | B18: =AVERAGE(A17:A19) -> 477.66667 | C18: 0.9845 | F18: =(0.0905*EXP(0.0013*B18))/D$2 -> 0.68453533 | K18: 1999 | L18: 0.74117319 | M18: 1.2306 | N18: 0.91208772 | P18: 2014 | Q18: 8 | R18: 2014.5833 | S18: 0.59982632 | T18: 0.030765
A19: 562.111 | B19: =AVERAGE(A18:A20) -> 522.62967 | C19: 1.04603 | F19: =(0.0905*EXP(0.0013*B19))/D$2 -> 0.72574024 | K19: 1998 | L19: 0.6658435 | M19: 0.6153 | N19: 0.40969351 | P19: 2014 | Q19: 7 | R19: 2014.5 | S19: 0.59289534 | T19: 0.06153 | U19: 0.03648085
A20: 528.222 | B20: =AVERAGE(A19:A21) -> 523.259 | C20: 1.10756 | F20: =(0.0905*EXP(0.0013*B20))/D$2 -> 0.72633424 | G20: Alta | H20: 1 | I20: 42674 | K20: 1997 | L20: 0.73821278 | M20: 1.16907 | N20: 0.86302242 | P20: 2014 | Q20: 6 | R20: 2014.4167 | S20: 0.57520854 | T20: 0.030765 | U20: 0.017696291
A21: 479.444 | B21: =AVERAGE(A20:A22) -> 479.44433 | C21: 1.16909 | F21: =(0.0905*EXP(0.0013*B21))/D$2 -> 0.6861191 | I21: 42633 | K21: 1996 | L21: 0.88393918 | M21: 0.67683 | N21: 0.59827655 | P21: 2014 | Q21: 5 | R21: 2014.3333 | S21: 0.56920688 | T21: 0.030765
A22: 430.667 | B22: =AVERAGE(A21:A23) -> 430.74067 | C22: 1.23062 | F22: =(0.0905*EXP(0.0013*B22))/D$2 -> 0.6440243 | I22: 42592 | K22: 1995 | L22: 0.84581895 | M22: 0.73836 | N22: 0.62451888 | P22: 2014 | Q22: 4 | R22: 2014.25 | S22: 0.56320521 | T22: 0.030765 | U22: 0.017327008
A23: 382.111 | B23: =AVERAGE(A22:A24) -> 391 | C23: 1.29216 | F23: =(0.0905*EXP(0.0013*B23))/D$2 -> 0.61159702 | I23: 42551 | K23: 1994 | L23: 0.87654609 | M23: 0.67683 | N23: 0.59327269 | P23: 2014 | Q23: 3 | R23: 2014.1667 | S23: 0.5616267 | T23: 0.030765
A24: 360.222 | B24: =AVERAGE(A23:A25) -> 361.51833 | C24: 1.35369 | F24: =(0.0905*EXP(0.0013*B24))/D$2 -> 0.58860035 | I24: 42510 | K24: 1993 | L24: 0.97842141 | M24: 0.79989 | N24: 0.7826295 | P24: 2014 | Q24: 2 | R24: 2014.0833 | S24: 0.56004819 | T24: 0.18459 | U24: 0.1033793
A25: 342.222 | B25: =AVERAGE(A24:A26) -> 342.185 | C25: 1.41522 | F25: =(0.0905*EXP(0.0013*B25))/D$2 -> 0.57399122 | I25: 42469 | K25: 1992 | L25: 0.81360199 | M25: 1.04601 | N25: 0.85103582 | P25: 2014 | Q25: 1 | R25: 2014 | S25: 0.59000737 | T25: 0.12306 | U25: 0.072606307
A26: 324.111 | B26: =AVERAGE(A25:A27) -> 324.111 | C26: 1.47675 | F26: =(0.0905*EXP(0.0013*B26))/D$2 -> 0.56066181 | G26: Baja | H26: 1 | I26: 42428 | K26: 1991 | L26: 0.54568434 | M26: 0.79989 | N26: 0.43648745 | P26: 2013 | Q26: 12 | R26: 2013.9167 | S26: 0.69443161 | T26: 0.12306 | U26: 0.085456754
A27: 306 | B27: =AVERAGE(A26:A28) -> 344.77767 | C27: 1.53828 | F27: =(0.0905*EXP(0.0013*B27))/D$2 -> 0.5759291 | I27: 42413 | K27: 1990 | L27: 0.65199414 | M27: 0.92295 | N27: 0.60175799 | P27: 2013 | Q27: 11 | R27: 2013.8333 | S27: 0.84507455 | T27: 0.12306 | U27: 0.10399487
A28: 404.222 | B28: =AVERAGE(A27:A29) -> 409.59267 | C28: 1.59981 | F28: =(0.0905*EXP(0.0013*B28))/D$2 -> 0.6265597 | I28: 42398 | K28: 1989 | L28: 0.72755584 | M28: 1.04601 | N28: 0.76103069 | P28: 2013 | Q28: 10 | R28: 2013.75 | S28: 0.87683418 | T28: 0.030765 | U28: 0.026975803
A29: 518.556 | B29: =AVERAGE(A28:A30) -> 518.62967 | C29: 1.66134 | F29: =(0.0905*EXP(0.0013*B29))/D$2 -> 0.72197619 | I29: 42383 | K29: 1988 | L29: 0.77054005 | M29: 1.04601 | N29: 0.8059926 | P29: 2013 | Q29: 9 | R29: 2013.6667 | S29: 0.85234098 | T29: 0.030765
A30: 633.111 | B30: =AVERAGE(A29:A31) -> 633.14833 | C30: 1.72287 | F30: =(0.0905*EXP(0.0013*B30))/D$2 -> 0.83787291 | I30: 42368 | K30: 1987 | L30: 0.79070165 | M30: 0.86142 | N30: 0.68112622 | P30: 2013 | Q30: 8 | R30: 2013.5833 | S30: 0.82784778 | T30: 0.030765 | U30: 0.025468737
A31: 747.778 | B31: =AVERAGE(A30:A32) -> 728.22233 | C31: 1.7844 | F31: =(0.0905*EXP(0.0013*B31))/D$2 -> 0.94810251 | I31: 42353 | K31: 1986 | L31: 0.73789522 | M31: 1.16907 | N31: 0.86265116 | P31: 2013 | Q31: 7 | R31: 2013.5 | S31: 0.79480303 | T31: 0.030765
A32: 803.778 | B32: =AVERAGE(A31:A33) -> 800.852 | C32: 1.84594 | F32: =(0.0905*EXP(0.0013*B32))/D$2 -> 1.0419833 | I32: 42338 | K32: 1985 | L32: 0.73265961 | M32: 0.73836 | N32: 0.54096655 | P32: 2013 | Q32: 6 | R32: 2013.4167 | S32: 0.76175828 | T32: 0.030765 | U32: 0.023435494
A33: 851 | B33: =AVERAGE(A32:A34) -> 851 | C33: 1.90747 | F33: =(0.0905*EXP(0.0013*B33))/D$2 -> 1.1121758 | I33: 42323 | K33: 1984 | L33: 0.80611083 | M33: 1.16907 | N33: 0.94239999 | P33: 2013 | Q33: 5 | R33: 2013.3333 | S33: 0.73870055 | T33: 0.030765
A34: 898.222 | B34: =AVERAGE(A33:A35) -> 898.222 | C34: 1.969 | F34: =(0.0905*EXP(0.0013*B34))/D$2 -> 1.18259 | G34: Alta | H34: 2 | I34: 42308 | K34: 1983 | L34: 0.69569003 | M34: 1.41519 | N34: 0.98453357 | P34: 2013 | Q34: 4 | R34: 2013.25 | S34: 0.71564282 | T34: 0.030765 | U34: 0.022016751
A35: 945.444 | B35: =AVERAGE(A34:A36) -> 777.77767 | C35: 2.03053 | F35: =(0.0905*EXP(0.0013*B35))/D$2 -> 1.0111914 | I35: 42267 | K35: 1982 | L35: 0.6580415 | M35: 0.79989 | N35: 0.52636081 | P35: 2013 | Q35: 3 | R35: 2013.1667 | S35: 0.71137851 | T35: 0.030765
A36: 489.667 | B36: =AVERAGE(A35:A37) -> 628.44433 | C36: 2.09206 | F36: =(0.0905*EXP(0.0013*B36))/D$2 -> 0.83276478 | I36: 42226 | K36: 1981 | L36: 0.54744669 | M36: 1.41519 | N36: 0.77474107 | P36: 2013 | Q36: 2 | R36: 2013.0833 | S36: 0.70711419 | T36: 0.06153 | U36: 0.043508736
A37: 450.222 | B37: =AVERAGE(A36:A38) -> 439.74067 | C37: 2.15359 | F37: =(0.0905*EXP(0.0013*B37))/D$2 -> 0.65160364 | I37: 42185 | K37: 1980 | L37: 0.57956351 | M37: 0.92295 | N37: 0.53490814 | P37: 2013 | Q37: 1 | R37: 2013 | S37: 0.73569666 | T37: 0.06153 | U37: 0.045267416
A38: 379.333 | B38: =AVERAGE(A37:A39) -> 385.70367 | C38: 2.21512 | F38: =(0.0905*EXP(0.0013*B38))/D$2 -> 0.60740049 | I38: 42144 | K38: 1979 | L38: 1.117295 | M38: 0.73836 | N38: 0.82496595 | P38: 2012 | Q38: 12 | R38: 2012.9167 | S38: 0.78658086 | T38: 0.06153 | U38: 0.04839832
A39: 327.556 | B39: =AVERAGE(A38:A40) -> 332 | C39: 2.27665 | F39: =(0.0905*EXP(0.0013*B39))/D$2 -> 0.56644138 | I39: 42103 | K39: 1978 | L39: 0.55011982 | M39: 0.98448 | N39: 0.54158196 | P39: 2012 | Q39: 11 | R39: 2012.8333 | S39: 0.83124224 | T39: 0.06153 | U39: 0.051146335
A40: 289.111 | B40: =AVERAGE(A39:A41) -> 302.22233 | C40: 2.33818 | F40: =(0.0905*EXP(0.0013*B40))/D$2 -> 0.54493288 | G40: Baja | H40: 2 | I40: 42063 | K40: 1977 | L40: 0.76381988 | M40: 0.86142 | N40: 0.65796972 | P40: 2012 | Q40: 10 | R40: 2012.75 | S40: 0.84887683 | T40: 0.030765 | U40: 0.026115696
...

Sheet VAR4-Cor
A1: HU | B1: smooth | C1: Distancia (cm) | D1: Grosor corte (cm) | E1: Ecuación | F1: Densidad | G1: Banda | H1: Pair | I1: Fecha | K1: Year | L1: Density | M1: Extension | N1: Calcification | P1: Year | Q1: Month | R1: Y.M. | S1: Density | T1: Extension | U1: Calcification
A2: -973.417 | B2: =AVERAGE(A2:A3) -> -973.125 | C2: 0 | D2: 0.562 | F2: =(0.0975*EXP(0.0013*B2))/D$2 -> 0.048961942 | K2: 2015 | L2: 0.53342612 | M2: 0.9593 | N2: 0.51171568 | P2: 2015 | Q2: 12 | R2: 2015.9167 | S2: 0.60189898 | T2: 0.1439 | U2: 0.086613263
A3: -972.833 | B3: =AVERAGE(A2:A4) -> -973 | C3: 0.048 | F3: =(0.0975*EXP(0.0013*B3))/D$2 -> 0.048969899 | K3: 2014 | L3: 0.71713631 | M3: 1.0074 | N3: 0.72244312 | P3: 2015 | Q3: 11 | R3: 2015.8333 | S3: 0.63432872 | T3: 0.1439 | U3: 0.091279903
A4: -972.75 | B4: =AVERAGE(A3:A5) -> -972.58333 | C4: 0.0959 | F4: =(0.0975*EXP(0.0013*B4))/D$2 -> 0.048996432 | K4: 2013 | L4: 0.78032772 | M4: 1.1512 | N4: 0.89831327 | P4: 2015 | Q4: 10 | R4: 2015.75 | S4: 0.6735888 | T4: 0.0479 | U4: 0.032264904
A5: -972.167 | B5: =AVERAGE(A4:A6) -> -971.91667 | C5: 0.1439 | F5: =(0.0975*EXP(0.0013*B5))/D$2 -> 0.049038914 | K5: 2012 | L5: 0.79949474 | M5: 0.7675 | N5: 0.61361221 | P5: 2015 | Q5: 9 | R5: 2015.6667 | S5: 0.65244959 | T5: 0.048 | U5: 0.03131758
A6: -970.833 | B6: =AVERAGE(A5:A7) -> -970.75 | C6: 0.1919 | F6: =(0.0975*EXP(0.0013*B6))/D$2 -> 0.049113346 | K6: 2011 | L6: 0.80233777 | M6: 1.0074 | N6: 0.80827507 | P6: 2015 | Q6: 8 | R6: 2015.5833 | S6: 0.606223 | T6: 0.048 | U6: 0.029098704
A7: -969.25 | B7: =AVERAGE(A6:A8) -> -969.27767 | C7: 0.2398 | E7: y = 0.0975e0.0013x | F7: =(0.0975*EXP(0.0013*B7))/D$2 -> 0.04920744 | K7: 2010 | L7: 0.82624919 | M7: 0.8154 | N7: 0.67372359 | P7: 2015 | Q7: 7 | R7: 2015.5 | S7: 0.55477292 | T7: 0.048 | U7: 0.0266291
A8: -967.75 | B8: =AVERAGE(A7:A9) -> -961.08333 | C8: 0.2878 | F8: =(0.0975*EXP(0.0013*B8))/D$2 -> 0.049734431 | K8: 2009 | L8: 0.64821567 | M8: 1.1513 | N8: 0.7462907 | P8: 2015 | Q8: 6 | R8: 2015.4167 | S8: 0.51076037 | T8: 0.0479 | U8: 0.024465422
A9: -946.25 | B9: =AVERAGE(A8:A10) -> -917.94433 | C9: 0.3358 | F9: =(0.0975*EXP(0.0013*B9))/D$2 -> 0.052603264 | K9: 2008 | L9: 0.59820593 | M9: 1.2472 | N9: 0.74608243 | P9: 2015 | Q9: 5 | R9: 2015.3333 | S9: 0.47438404 | T9: 0.048 | U9: 0.022770434
A10: -839.833 | B10: =AVERAGE(A9:A11) -> -825.13867 | C10: 0.3837 | F10: =(0.0975*EXP(0.0013*B10))/D$2 -> 0.059348422 | K10: 2007 | L10: 0.59557636 | M10: 1.1998 | N10: 0.71457251 | P10: 2015 | Q10: 4 | R10: 2015.25 | S10: 0.44387212 | T10: 0.048 | U10: 0.021305862
A11: -689.333 | B11: =AVERAGE(A10:A12) -> -689.13867 | C11: 0.4317 | F11: =(0.0975*EXP(0.0013*B11))/D$2 -> 0.070825956 | K11: 2006 | L11: 0.45529615 | M11: 0.912 | N11: 0.41523009 | P11: 2015 | Q11: 3 | R11: 2015.1667 | S11: 0.41816697 | T11: 0.0479 | U11: 0.020030198
A12: -538.25 | B12: =AVERAGE(A11:A13) -> -525.361 | C12: 0.4797 | F12: =(0.0975*EXP(0.0013*B12))/D$2 -> 0.087631148 | K12: 2005 | L12: 0.75825379 | M12: 0.912 | N12: 0.69152746 | P12: 2015 | Q12: 2 | R12: 2015.0833 | S12: 0.40782305 | T12: 0.1439 | U12: 0.058685736
A13: -348.5 | B13: =AVERAGE(A12:A14) -> -301.861 | C13: 0.5277 | F13: =(0.0975*EXP(0.0013*B13))/D$2 -> 0.1171771 | K13: 2004 | L13: 0.62489811 | M13: 1.152 | N13: 0.71988262 | P13: 2015 | Q13: 1 | R13: 2015 | S13: 0.46738414 | T13: 0.1439 | U13: 0.067256578
A14: -18.833 | B14: =AVERAGE(A13:A15) -> 4.9446667 | C14: 0.5756 | F14: =(0.0975*EXP(0.0013*B14))/D$2 -> 0.17460633 | K14: 2003 | L14: 0.63355862 | M14: 1.152 | N14: 0.72985953 | P14: 2014 | Q14: 12 | R14: 2014.9167 | S14: 0.59932856 | T14: 0.1439 | U14: 0.08624338
A15: 382.167 | B15: =AVERAGE(A14:A16) -> 382.19467 | C15: 0.6236 | F15: =(0.0975*EXP(0.0013*B15))/D$2 -> 0.28513389 | K15: 2002 | L15: 0.65287464 | M15: 1.104 | N15: 0.72077361 | P15: 2014 | Q15: 11 | R15: 2014.8333 | S15: 0.75338472 | T15: 0.144 | U15: 0.1084874
A16: 783.25 | B16: =AVERAGE(A15:A17) -> 763.44467 | C16: 0.6716 | F16: =(0.0975*EXP(0.0013*B16))/D$2 -> 0.46805409 | K16: 2001 | L16: 0.74619887 | M16: 1.248 | N16: 0.93125619 | P16: 2014 | Q16: 10 | R16: 2014.75 | S16: 0.83218159 | T16: 0.0959 | U16: 0.079806214
A17: 1124.917 | B17: =AVERAGE(A16:A18) -> 1045.8057 | C17: 0.7195 | F17: =(0.0975*EXP(0.0013*B17))/D$2 -> 0.67563512 | K17: 2000 | L17: 0.63201592 | M17: 1.056 | N17: 0.66740881 | P17: 2014 | Q17: 9 | R17: 2014.6667 | S17: 0.8018553 | T17: 0.048 | U17: 0.038489055
A18: 1229.25 | B18: =AVERAGE(A17:A19) -> 1187.1947 | C18: 0.7675 | F18: =(0.0975*EXP(0.0013*B18))/D$2 -> 0.81196633 | K18: 1999 | L18: 0.70575035 | M18: 1.248 | N18: 0.88077644 | P18: 2014 | Q18: 8 | R18: 2014.5833 | S18: 0.76350915 | T18: 0.0479 | U18: 0.036572088
A19: 1207.417 | B19: =AVERAGE(A18:A20) -> 1207.3333 | C19: 0.8155 | F19: =(0.0975*EXP(0.0013*B19))/D$2 -> 0.83350453 | K19: 1998 | L19: 0.65486813 | M19: 1.296 | N19: 0.8487091 | P19: 2014 | Q19: 7 | R19: 2014.5 | S19: 0.73345732 | T19: 0.048 | U19: 0.035205951
... A24: 1319.167 | B24: =AVERAGE(A23:A25) -> 1314.139 | C24: 1.0553 | F24: =(0.0975*EXP(0.0013*B24))/D$2 -> 0.95765397 | K24: 1993 | L24: 0.77211095 | M24: 1.152 | N24: 0.88947182 | P24: 2014 | Q24: 2 | R24: 2014.0833 | S24: 0.69105166 | T24: 0.1439 | U24: 0.099442333
A25: 1360.417 | B25: =AVERAGE(A24:A26) -> 1342.4723 | C25: 1.1033 | F25: =(0.0975*EXP(0.0013*B25))/D$2 -> 0.99358522 | G25: Alta | H25: 1 | I25: 42674 | K25: 1992 | L25: 0.75803016 | M25: 0.912 | N25: 0.6913235 | P25: 2014 | Q25: 1 | R25: 2014 | S25: 0.7205018 | T25: 0.1439 | U25: 0.10368021
A26: 1347.833 | B26: =AVERAGE(A25:A27) -> 1338 | C26: 1.1512 | F26: =(0.0975*EXP(0.0013*B26))/D$2 -> 0.98782525 | I26: 42661 | K26: 1991 | L26: 0.85635514 | M26: 1.056 | N26: 0.90431102 | P26: 2013 | Q26: 12 | R26: 2013.9167 | S26: 0.80150222 | T26: 0.1439 | U26: 0.11533617
A27: 1305.75 | B27: =AVERAGE(A26:A28) -> 1305.861 | C27: 1.1992 | F27: =(0.0975*EXP(0.0013*B27))/D$2 -> 0.94740352 | I27: 42648 | K27: 1990 | L27: 0.84852412 | M27: 0.816 | N27: 0.69239569 | P27: 2013 | Q27: 11 | R27: 2013.8333 | S27: 0.91138071 | T27: 0.1439 | U27: 0.13114768
A28: 1264 | B28: =AVERAGE(A27:A29) -> 1265.8333 | C28: 1.2472 | F28: =(0.0975*EXP(0.0013*B28))/D$2 -> 0.89936516 | I28: 42635 | K28: 1989 | L28: 0.6770131 | M28: 0.624 | N28: 0.42245618 | P28: 2013 | Q28: 10 | R28: 2013.75 | S28: 0.96494414 | T28: 0.0959 | U28: 0.092538143
A29: 1227.75 | B29: =AVERAGE(A28:A30) -> 1233.8333 | C29: 1.2952 | F29: =(0.0975*EXP(0.0013*B29))/D$2 -> 0.8627191 | I29: 42622 | K29: 1988 | L29: 0.50758782 | M29: 0.72 | N29: 0.36546323 | P29: 2013 | Q29: 9 | R29: 2013.6667 | S29: 0.95782703 | T29: 0.048 | U29: 0.045975697
A30: 1209.75 | B30: =AVERAGE(A29:A31) -> 1213.2223 | C30: 1.3431 | F30: =(0.0975*EXP(0.0013*B30))/D$2 -> 0.83991008 | I30: 42609 | K30: 1987 | L30: 0.66110097 | M30: 1.104 | N30: 0.72985548 | P30: 2013 | Q30: 8 | R30: 2013.5833 | S30: 0.92345135 | T30: 0.0959 | U30: 0.088558984
A31: 1202.167 | B31: =AVERAGE(A30:A32) -> 1202.139 | C31: 1.3911 | F31: =(0.0975*EXP(0.0013*B31))/D$2 -> 0.82789514 | I31: 42596 | K31: 1986 | L31: 0.7235547 | M31: 0.816 | N31: 0.59042064 | P31: 2013 | Q31: 7 | R31: 2013.5 | S31: 0.86315511 | T31: 0.048 | U31: 0.041431445
A32: 1194.5 | B32: =AVERAGE(A31:A33) -> 1193.8613 | C32: 1.4391 | F32: =(0.0975*EXP(0.0013*B32))/D$2 -> 0.81903395 | I32: 42583 | K32: 1985 | L32: 0.69891515 | M32: 1.104 | N32: 0.77160233 | P32: 2013 | Q32: 6 | R32: 2013.4167 | S32: 0.7935263 | T32: 0.0959 | U32: 0.076099172
A33: 1184.917 | B33: =AVERAGE(A32:A34) -> 1180.9167 | C33: 1.487 | F33: =(0.0975*EXP(0.0013*B33))/D$2 -> 0.80536652 | I33: 42570 | K33: 1984 | L33: 0.61271935 | M33: 0.816 | N33: 0.49997899 | P33: 2013 | Q33: 5 | R33: 2013.3333 | S33: 0.72586889 | T33: 0.048 | U33: 0.034841707
A34: 1163.333 | B34: =AVERAGE(A33:A35) -> 1160.611 | C34: 1.535 | F34: =(0.0975*EXP(0.0013*B34))/D$2 -> 0.78438511 | I34: 42557 | K34: 1983 | L34: 0.60212712 | M34: 0.816 | N34: 0.49133573 | P34: 2013 | Q34: 4 | R34: 2013.25 | S34: 0.66216919 | T34: 0.096 | U34: 0.063568243
A35: 1133.583 | B35: =AVERAGE(A34:A36) -> 1133.583 | C35: 1.583 | F35: =(0.0975*EXP(0.0013*B35))/D$2 -> 0.7573032 | I35: 42544 | K35: 1982 | L35: 0.6882086 | M35: 0.912 | N35: 0.62764624 | P35: 2013 | Q35: 3 | R35: 2013.1667 | S35: 0.61431052 | T35: 0.0479 | U35: 0.029425474
A36: 1103.833 | B36: =AVERAGE(A35:A37) -> 1099.972 | C36: 1.6309 | F36: =(0.0975*EXP(0.0013*B36))/D$2 -> 0.72492587 | I36: 42531 | K36: 1981 | L36: 0.69447712 | M36: 0.768 | N36: 0.53335843 | P36: 2013 | Q36: 2 | R36: 2013.0833 | S36: 0.60622242 | T36: 0.1439 | U36: 0.087235406
A37: 1062.5 | B37: =AVERAGE(A36:A38) -> 1048.6667 | C37: 1.6789 | F37: =(0.0975*EXP(0.0013*B37))/D$2 -> 0.67815269 | I37: 42518 | K37: 1980 | L37: 0.94209354 | M37: 0.912 | N37: 0.85918931 | P37: 2013 | Q37: 1 | R37: 2013 | S37: 0.64040193 | T37: 0.1439 | U37: 0.092153838
... A43: 580.917 | B43: =AVERAGE(A42:A44) -> 581.05567 | C43: 1.9667 | F43: =(0.0975*EXP(0.0013*B43))/D$2 -> 0.36925157 | I43: 42440 | K43: 1974 | L43: 0.80802587 | M43: 0.72 | N43: 0.58177863 | P43: 2012 | Q43: 7 | R43: 2012.5 | S43: 0.83428723 | T43: 0.048 | U43: 0.040045787
A44: 549.333 | B44: =AVERAGE(A43:A45) -> 556.44433 | C44: 2.0147 | F44: =(0.0975*EXP(0.0013*B44))/D$2 -> 0.35762446 | G44: Baja | H44: 1 | I44: 42428 | K44: 1973 | L44: 0.74077926 | M44: 0.72 | N44: 0.53336107 | P44: 2012 | Q44: 6 | R44: 2012.4167 | S44: 0.80895164 | T44: 0.048 | U44: 0.038829679
A45: 539.083 | B45: =AVERAGE(A44:A46) -> 566.66633 | C45: 2.0627 | F45: =(0.0975*EXP(0.0013*B45))/D$2 -> 0.3624085 | I45: 42418 | K45: 1972 | L45: 0.47594254 | M45: 0.96 | N45: 0.45690484 | P45: 2012 | Q45: 5 | R45: 2012.3333 | S45: 0.78068352 | T45: 0.048 | U45: 0.037472809
