Workbook

Sheet DATA
A1: VAR-1 (X-RAY) | F1: VAR-2 (TOMO) | K1: VAR-3 (TOMO) | P1: VAR-4 (TOMO) | U1: PROMEDIO
A2: Año | B2: Densidad | C2: Extension | D2: Calcificacion | F2: Año | G2: Densidad | H2: Extension | I2: Calcificacion | K2: Año | L2: Densidad | M2: Extension | N2: Calcificacion | P2: Año | Q2: Densidad | R2: Extension | S2: Calcificacion | U2: Año | V2: Densidad | W2: Extension | X2: Calcificacion
A3: 2015 | B3: 0.64979045 | C3: 1.5996 | D3: 1.0394048 | F3: 2015 | G3: 0.60311461 | H3: 1.35375 | I3: 0.81009439 | K3: 2015 | L3: 0.77141124 | M3: 0.92297 | N3: 0.7183187 | P3: 2015 | Q3: 0.56139931 | R3: 0.9594 | S3: 0.5386065 | U3: 2015 | V3: =AVERAGE(Q3,L3,G3,B3) -> 0.6464289 | W3: =AVERAGE(R3,M3,H3,C3) -> 1.20893 | X3: =AVERAGE(S3,N3,I3,D3) -> 0.7766061
A4: 2014 | B4: 0.62513631 | C4: 1.5692 | D4: 0.98096389 | F4: 2014 | G4: 0.64102678 | H4: 0.86145 | I4: 0.56149233 | K4: 2014 | L4: 0.91130493 | M4: 0.58455 | N4: 0.5233397 | P4: 2014 | Q4: 0.62794163 | R4: 1.1513 | S4: 0.7229492 | U4: 2014 | V4: =AVERAGE(Q4,L4,G4,B4) -> 0.70135241 | W4: =AVERAGE(R4,M4,H4,C4) -> 1.041625 | X4: =AVERAGE(S4,N4,I4,D4) -> 0.69718628
A5: 2013 | B5: 0.61275542 | C5: 1.9347 | D5: 1.1854979 | F5: 2013 | G5: 0.63058724 | H5: 1.7228 | I5: 1.0863757 | K5: 2013 | L5: 0.62972335 | M5: 1.10756 | N5: 0.71588971 | P5: 2013 | Q5: 0.57166105 | R5: 1.1512 | S5: 0.6580962 | U5: 2013 | V5: =AVERAGE(Q5,L5,G5,B5) -> 0.61118177 | W5: =AVERAGE(R5,M5,H5,C5) -> 1.479065 | X5: =AVERAGE(S5,N5,I5,D5) -> 0.91146488
A6: 2012 | B6: 0.60951216 | C6: 1.2645 | D6: 0.77072813 | F6: 2012 | G6: 0.56774705 | H6: 1.1076 | I6: 0.62224998 | K6: 2012 | L6: 0.75110803 | M6: 0.39992 | N6: 0.29478449 | P6: 2012 | Q6: 0.8211381 | R6: 0.9594 | S6: 0.7877999 | U6: 2012 | V6: =AVERAGE(Q6,L6,G6,B6) -> 0.68737634 | W6: =AVERAGE(R6,M6,H6,C6) -> 0.932855 | X6: =AVERAGE(S6,N6,I6,D6) -> 0.61889063
A7: 2011 | B7: 0.56284024 | C7: 2.3308 | D7: 1.311868 | F7: 2011 | G7: 0.54462781 | H7: 1.19985 | I7: 0.67776872 | K7: 2011 | L7: 0.89300459 | M7: 0.953765 | N7: 0.89246024 | P7: 2011 | Q7: 0.9563076 | R7: 1.1513 | S7: 1.1009969 | U7: 2011 | V7: =AVERAGE(Q7,L7,G7,B7) -> 0.73919506 | W7: =AVERAGE(R7,M7,H7,C7) -> 1.4089287 | X7: =AVERAGE(S7,N7,I7,D7) -> 0.99577348
A8: 2010 | B8: 0.61516816 | C8: 0.7617 | D8: 0.46857359 | F8: 2010 | G8: 0.64980152 | H8: 0.89225 | I8: 0.54794208 | K8: 2010 | L8: 1.005208 | M8: 0.49224 | N8: 0.50069913 | P8: 2010 | Q8: 0.98264907 | R8: 1.0553 | S8: 1.0369896 | U8: 2010 | V8: =AVERAGE(Q8,L8,G8,B8) -> 0.81320669 | W8: =AVERAGE(R8,M8,H8,C8) -> 0.8003725 | X8: =AVERAGE(S8,N8,I8,D8) -> 0.63855109
A9: 2009 | B9: 0.60836364 | C9: 1.4778 | D9: 0.89903979 | F9: 2009 | G9: 0.7525208 | H9: 0.92295 | I9: 0.6945407 | K9: 2009 | L9: 0.70576041 | M9: 0.86141 | N9: 0.60794954 | P9: 2009 | Q9: 0.9083832 | R9: 0.9594 | S9: 0.87150284 | U9: 2009 | V9: =AVERAGE(Q9,L9,G9,B9) -> 0.74375701 | W9: =AVERAGE(R9,M9,H9,C9) -> 1.05539 | X9: =AVERAGE(S9,N9,I9,D9) -> 0.76825822
A10: 2008 | B10: 0.66298357 | C10: 0.9902 | D10: 0.65648633 | F10: 2008 | G10: 0.67717084 | H10: 1.13835 | I10: 0.76597106 | K10: 2008 | L10: 0.64737146 | M10: 0.67685 | N10: 0.43490667 | P10: 2008 | Q10: 0.73604812 | R10: 1.2471 | S10: 0.9179256 | U10: 2008 | V10: =AVERAGE(Q10,L10,G10,B10) -> 0.6808935 | W10: =AVERAGE(R10,M10,H10,C10) -> 1.013125 | X10: =AVERAGE(S10,N10,I10,D10) -> 0.69382242
A11: 2007 | B11: 0.68530775 | C11: 2.2242 | D11: 1.5242615 | F11: 2007 | G11: 0.6450884 | H11: 1.19985 | I11: 0.79190421 | K11: 2007 | L11: 0.59712321 | M11: 0.55375 | N11: 0.33185108 | P11: 2007 | Q11: 0.60853333 | R11: 1.2472 | S11: 0.75896277 | U11: 2007 | V11: =AVERAGE(Q11,L11,G11,B11) -> 0.63401317 | W11: =AVERAGE(R11,M11,H11,C11) -> 1.30625 | X11: =AVERAGE(S11,N11,I11,D11) -> 0.85174489
A12: 2006 | B12: 0.61661593 | C12: 2.1176 | D12: 1.3057459 | F12: 2006 | G12: 0.69052092 | H12: 1.1383 | I12: 0.77858604 | K12: 2006 | L12: 0.64632324 | M12: 1.076815 | N12: 0.7110792 | P12: 2006 | Q12: 0.53088713 | R12: 1.0553 | S12: 0.56024519 | U12: 2006 | V12: =AVERAGE(Q12,L12,G12,B12) -> 0.6210868 | W12: =AVERAGE(R12,M12,H12,C12) -> 1.3470038 | X12: =AVERAGE(S12,N12,I12,D12) -> 0.83891408
A13: 2005 | B13: 0.61940247 | C13: 0.975 | D13: 0.6039174 | F13: 2005 | G13: 0.70315603 | H13: 1.1999 | I13: 0.84297111 | K13: 2005 | L13: 0.68197759 | M13: 0.64605 | N13: 0.44359111 | P13: 2005 | Q13: 0.79875069 | R13: 1.1513 | S13: 0.91960167 | U13: 2005 | V13: =AVERAGE(Q13,L13,G13,B13) -> 0.7008217 | W13: =AVERAGE(R13,M13,H13,C13) -> 0.9930625 | X13: =AVERAGE(S13,N13,I13,D13) -> 0.70252033
A14: 2004 | B14: 0.65005351 | C14: 1.5234 | D14: 0.99029152 | F14: 2004 | G14: 0.70080849 | H14: 1.046 | I14: 0.72659752 | K14: 2004 | L14: 0.68882015 | M14: 1.261375 | N14: 0.7879505 | P14: 2004 | Q14: 0.71376098 | R14: 1.2472 | S14: 0.89020269 | U14: 2004 | V14: =AVERAGE(Q14,L14,G14,B14) -> 0.68836078 | W14: =AVERAGE(R14,M14,H14,C14) -> 1.2694938 | X14: =AVERAGE(S14,N14,I14,D14) -> 0.84876056
... A34: 1984 | B34: 0.85550138 | C34: 0.77673 | D34: 0.66449359 | F34: 1984 | G34: 0.77308151 | H34: 0.9536 | I34: 0.8207218 | K34: 1984 | L34: 0.73257958 | M34: 0.86143 | N34: 0.63332075 | P34: 1984 | Q34: 0.55710808 | R34: 0.9 | S34: 0.50139727 | U34: 1984 | V34: =AVERAGE(Q34,L34,G34,B34) -> 0.72956764 | W34: =AVERAGE(R34,M34,H34,C34) -> 0.87294 | X34: =AVERAGE(S34,N34,I34,D34) -> 0.65498335
F35: 1983 | G35: 0.6841536 | H35: 0.892 | I35: 0.62844633 | K35: 1983 | L35: 0.6386834 | M35: 1.230615 | N35: 0.78843226 | P35: 1983 | Q35: 0.4713034 | R35: 0.99 | S35: 0.46659037 | U35: 1983 | V35: =AVERAGE(Q35,L35,G35,B35) -> 0.5980468 | W35: =AVERAGE(R35,M35,H35,C35) -> 1.0375383 | X35: =AVERAGE(S35,N35,I35,D35) -> 0.62782299
F36: 1982 | G36: 0.80671152 | H36: 1.0151 | I36: 0.92498358 | K36: 1982 | L36: 0.5508457 | M36: 1.13835 | N36: 0.62982882 | P36: 1982 | Q36: 0.53071147 | R36: 0.81 | S36: 0.42987629 | U36: 1982 | V36: =AVERAGE(Q36,L36,G36,B36) -> 0.6294229 | W36: =AVERAGE(R36,M36,H36,C36) -> 0.98781667 | X36: =AVERAGE(S36,N36,I36,D36) -> 0.6615629
F37: 1981 | G37: 0.75366653 | H37: 0.98425 | I37: 0.74184981 | K37: 1981 | L37: 0.60134255 | M37: 0.86143 | N37: 0.52287402 | P37: 1981 | Q37: 0.69212054 | R37: 1.08 | S37: 0.74749019 | U37: 1981 | V37: =AVERAGE(Q37,L37,G37,B37) -> 0.68237654 | W37: =AVERAGE(R37,M37,H37,C37) -> 0.97522667 | X37: =AVERAGE(S37,N37,I37,D37) -> 0.670738
F38: 1980 | G38: 0.94822181 | H38: 1.3534 | I38: 1.327987 | K38: 1980 | L38: 0.56583396 | M38: 1.23061 | N38: 0.66457058 | P38: 1980 | Q38: 0.83645864 | R38: 0.72 | S38: 0.60225022 | U38: 1980 | V38: =AVERAGE(Q38,L38,G38,B38) -> 0.7835048 | W38: =AVERAGE(R38,M38,H38,C38) -> 1.1013367 | X38: =AVERAGE(S38,N38,I38,D38) -> 0.86493593
F39: 1979 | G39: 0.85356215 | H39: 1.10725 | I39: 0.91672792 | K39: 1979 | L39: 0.60077673 | M39: 0.953725 | N39: 0.57070539 | P39: 1979 | Q39: 0.87285758 | R39: 0.81 | S39: 0.70701464 | U39: 1979 | V39: =AVERAGE(Q39,L39,G39,B39) -> 0.77573215 | W39: =AVERAGE(R39,M39,H39,C39) -> 0.95699167 | X39: =AVERAGE(S39,N39,I39,D39) -> 0.73148265
F40: 1978 | G40: 0.87640622 | H40: 1.4763 | I40: 1.2794971 | K40: 1978 | L40: 0.84251149 | M40: 0.73833 | N40: 0.62205236 | P40: 1978 | Q40: 0.82326037 | R40: 0.9 | S40: 0.74093433 | U40: 1978 | V40: =AVERAGE(Q40,L40,G40,B40) -> 0.8473927 | W40: =AVERAGE(R40,M40,H40,C40) -> 1.03821 | X40: =AVERAGE(S40,N40,I40,D40) -> 0.88082792
F41: 1977 | G41: 0.98869927 | H41: 0.98425 | I41: 0.97314973 | K41: 1977 | L41: 0.53492841 | M41: 1.07652 | N41: 0.57548639 | P41: 1977 | Q41: 0.88438982 | R41: 0.99 | S41: 0.87554592 | U41: 1977 | V41: =AVERAGE(Q41,L41,G41,B41) -> 0.8026725 | W41: =AVERAGE(R41,M41,H41,C41) -> 1.0169233 | X41: =AVERAGE(S41,N41,I41,D41) -> 0.80806068
F42: 1976 | G42: 0.9361184 | H42: 0.984 | I42: 0.92114051 | K42: 1976 | L42: 0.55824825 | M42: 0.707415 | N42: 0.39259118 | P42: 1976 | Q42: 0.83214665 | R42: 0.72 | S42: 0.59914559 | U42: 1976 | V42: =AVERAGE(Q42,L42,G42,B42) -> 0.77550443 | W42: =AVERAGE(R42,M42,H42,C42) -> 0.803805 | X42: =AVERAGE(S42,N42,I42,D42) -> 0.63762576
F43: 1975 | G43: 0.82021215 | H43: 1.13775 | I43: 0.92820878 | K43: 1975 | L43: 0.54176412 | M43: 0.86124 | N43: 0.46065451 | P43: 1975 | Q43: 0.79203321 | R43: 0.9 | S43: 0.71282989 | U43: 1975 | V43: =AVERAGE(Q43,L43,G43,B43) -> 0.71800316 | W43: =AVERAGE(R43,M43,H43,C43) -> 0.96633 | X43: =AVERAGE(S43,N43,I43,D43) -> 0.70056439
F44: 1974 | G44: 0.97093271 | H44: 1.01475 | I44: 1.0406172 | K44: 1974 | L44: 0.57183168 | M44: 0.953475 | N44: 0.54648791 | P44: 1974 | Q44: 0.80581397 | R44: 0.72 | S44: 0.58018606 | U44: 1974 | V44: =AVERAGE(Q44,L44,G44,B44) -> 0.78285946 | W44: =AVERAGE(R44,M44,H44,C44) -> 0.896075 | X44: =AVERAGE(S44,N44,I44,D44) -> 0.7224304
F45: 1973 | G45: 1.1005528 | H45: 1.01475 | I45: 1.1751815 | K45: 1973 | L45: 0.59634736 | M45: 0.891945 | N45: 0.528368 | P45: 1973 | Q45: 0.92072509 | R45: 0.9 | S45: 0.82865258 | U45: 1973 | V45: =AVERAGE(Q45,L45,G45,B45) -> 0.87254175 | W45: =AVERAGE(R45,M45,H45,C45) -> 0.935565 | X45: =AVERAGE(S45,N45,I45,D45) -> 0.84406737
F46: 1972 | G46: 1.126627 | H46: 1.01475 | I46: 1.1492558 | K46: 1972 | L46: 0.61544761 | M46: 0.953475 | N46: 0.58492321 | P46: 1972 | Q46: 0.61519312 | R46: 0.99 | S46: 0.60904119 | U46: 1972 | V46: =AVERAGE(Q46,L46,G46,B46) -> 0.78575591 | W46: =AVERAGE(R46,M46,H46,C46) -> 0.986075 | X46: =AVERAGE(S46,N46,I46,D46) -> 0.78107341
... F68: 1950 | G68: 0.89334446 | H68: 0.9225 | I68: 0.82411027 | K68: 1950 | L68: 0.72304786 | M68: 1.38411 | N68: 1.0028598 | P68: 1950 | Q68: 0.59477434 | R68: 1.53 | S68: 0.91000474 | U68: 1950 | V68: =AVERAGE(Q68,L68,G68,B68) -> 0.73705555 | W68: =AVERAGE(R68,M68,H68,C68) -> 1.27887 | X68: =AVERAGE(S68,N68,I68,D68) -> 0.91232492
K69: 1949 | L69: 0.91030963 | M69: 0.953415 | N69: 0.85294783 | U69: 1949 | V69: =AVERAGE(Q69,L69,G69,B69) -> 0.91030963 | W69: =AVERAGE(R69,M69,H69,C69) -> 0.953415 | X69: =AVERAGE(S69,N69,I69,D69) -> 0.85294783
K70: 1948 | L70: 0.92724857 | M70: 1.015065 | N70: 0.87652276 | U70: 1948 | V70: =AVERAGE(Q70,L70,G70,B70) -> 0.92724857 | W70: =AVERAGE(R70,M70,H70,C70) -> 1.015065 | X70: =AVERAGE(S70,N70,I70,D70) -> 0.87652276
K71: 1947 | L71: 0.82134299 | M71: 1.38414 | N71: 1.0702707 | U71: 1947 | V71: =AVERAGE(Q71,L71,G71,B71) -> 0.82134299 | W71: =AVERAGE(R71,M71,H71,C71) -> 1.38414 | X71: =AVERAGE(S71,N71,I71,D71) -> 1.0702707
K72: 1946 | L72: 0.81977996 | M72: 1.44558 | N72: 1.1953527 | U72: 1946 | V72: =AVERAGE(Q72,L72,G72,B72) -> 0.81977996 | W72: =AVERAGE(R72,M72,H72,C72) -> 1.44558 | X72: =AVERAGE(S72,N72,I72,D72) -> 1.1953527
K73: 1945 | L73: 0.90412281 | M73: 1.1073 | N73: 0.96586807 | U73: 1945 | V73: =AVERAGE(Q73,L73,G73,B73) -> 0.90412281 | W73: =AVERAGE(R73,M73,H73,C73) -> 1.1073 | X73: =AVERAGE(S73,N73,I73,D73) -> 0.96586807
K74: 1944 | L74: 1.0842757 | M74: 1.10724 | N74: 1.234284 | U74: 1944 | V74: =AVERAGE(Q74,L74,G74,B74) -> 1.0842757 | W74: =AVERAGE(R74,M74,H74,C74) -> 1.10724 | X74: =AVERAGE(S74,N74,I74,D74) -> 1.234284
K75: 1943 | L75: 0.73367003 | M75: 1.35366 | N75: 0.99313978 | U75: 1943 | V75: =AVERAGE(Q75,L75,G75,B75) -> 0.73367003 | W75: =AVERAGE(R75,M75,H75,C75) -> 1.35366 | X75: =AVERAGE(S75,N75,I75,D75) -> 0.99313978
K76: 1942 | L76: 0.74214927 | M76: 1.2306 | N76: 0.91328889 | U76: 1942 | V76: =AVERAGE(Q76,L76,G76,B76) -> 0.74214927 | W76: =AVERAGE(R76,M76,H76,C76) -> 1.2306 | X76: =AVERAGE(S76,N76,I76,D76) -> 0.91328889
K77: 1941 | L77: 0.85518658 | M77: 0.86142 | N77: 0.73667482 | U77: 1941 | V77: =AVERAGE(Q77,L77,G77,B77) -> 0.85518658 | W77: =AVERAGE(R77,M77,H77,C77) -> 0.86142 | X77: =AVERAGE(S77,N77,I77,D77) -> 0.73667482
A79: PROMEDIO | B79: =AVERAGE(B3:B34) -> 0.69663086 | C79: =AVERAGE(C3:C34) -> 1.4242272 | D79: =AVERAGE(D3:D34) -> 0.97926436 | F79: PROMEDIO | G79: =AVERAGE(G3:G68) -> 0.74844432 | H79: =AVERAGE(H3:H68) -> 1.0984333 | I79: =AVERAGE(I3:I68) -> 0.81922323 | K79: PROMEDIO | L79: =AVERAGE(L3:L77) -> 0.73030227 | M79: =AVERAGE(M3:M77) -> 0.97410293 | N79: =AVERAGE(N3:N77) -> 0.70269041 | P79: PROMEDIO | Q79: =AVERAGE(Q3:Q68) -> 0.65494536 | R79: =AVERAGE(R3:R68) -> 1.0619 | S79: =AVERAGE(S3:S68) -> 0.68813421 | U79: PROMEDIO | V79: =AVERAGE(V3:V77) -> 0.72752676 | W79: =AVERAGE(W3:W77) -> 1.093315 | X79: =AVERAGE(X3:X77) -> 0.7874455
A80: DE | B80: =_xlfn.STDEV.S(B3:B34) -> 0.082517873 | C80: =_xlfn.STDEV.S(C3:C34) -> 0.42445836 | D80: =_xlfn.STDEV.S(D3:D34) -> 0.26697919 | F80: DE | G80: =_xlfn.STDEV.S(G3:G68) -> 0.14046394 | H80: =_xlfn.STDEV.S(H3:H68) -> 0.19975553 | I80: =_xlfn.STDEV.S(I3:I68) -> 0.20390248 | K80: DE | L80: =_xlfn.STDEV.S(L3:L77) -> 0.12509256 | M80: =_xlfn.STDEV.S(M3:M77) -> 0.22727821 | N80: =_xlfn.STDEV.S(N3:N77) -> 0.20139799 | P80: DE | Q80: =_xlfn.STDEV.S(Q3:Q68) -> 0.15689888 | R80: =_xlfn.STDEV.S(R3:R68) -> 0.22648809 | S80: =_xlfn.STDEV.S(S3:S68) -> 0.18948473 | U80: DE | V80: =_xlfn.STDEV.S(V3:V77) -> 0.093725982 | W80: =_xlfn.STDEV.S(W3:W77) -> 0.15824407 | X80: =_xlfn.STDEV.S(X3:X77) -> 0.13006071

Sheet DATA-Match
A1: VAR-1 (X-RAY) | B1: IMBANACO-ENERO 2017 | F1: VAR-1 (X-RAY) | G1: VETERINARIA-JULIO 2016 | K1: VAR-2 (TOMO) | P1: VAR-3 (TOMO) | U1: VAR-4 (TOMO) | Z1: PROMEDIO
A2: Año | B2: Densidad | C2: Extensión | D2: Calcificación | F2: Año | G2: Densidad | H2: Extension | I2: Calcificacion | K2: Año | L2: Densidad | M2: Extension | N2: Calcificacion | P2: Año | Q2: Densidad | R2: Extension | S2: Calcificacion | U2: Año | V2: Densidad | W2: Extension | X2: Calcificacion | Z2: Año | AA2: Densidad | AB2: Extension | AC2: Calcificacion
A3: 2015 | B3: 0.41375667 | C3: 1.8519 | D3: 0.76623599 | F3: 2015 | G3: 0.68516075 | H3: 1.4472 | I3: 0.99156464 | K3: 2015 | L3: 0.62119327 | M3: 0.8614 | N3: 0.53509589 | P3: 2015 | Q3: 1.0125993 | R3: 0.738385 | S3: 0.74769125 | U3: 2015 | V3: 0.55244606 | W3: 1.0073 | X3: 0.55736198 | Z3: 2015 | AA3: =AVERAGE(V3,Q3,L3,G3) -> 0.71784984 | AB3: =AVERAGE(W3,R3,M3,H3) -> 1.0135713 | AC3: =AVERAGE(X3,S3,N3,I3) -> 0.70792844 | AD3: =(AA3-AA$79)/AA$80 -> -0.19584292 | AF3: Density | AI3: Extension | AL3: Calcification
A4: 2014 | B4: 0.4197296 | C4: 1.5741 | D4: 0.66069637 | F4: 2014 | G4: 0.64420237 | H4: 1.63 | I4: 1.0500499 | K4: 2014 | L4: 0.64016045 | M4: 1.66135 | N4: 1.0734865 | P4: 2014 | Q4: 0.70969204 | R4: 0.98448 | S4: 0.72911794 | U4: 2014 | V4: 0.6737332 | W4: 1.07935 | X4: 0.72389923 | Z4: 2014 | AA4: =AVERAGE(V4,Q4,L4,G4) -> 0.66694701 | AB4: =AVERAGE(W4,R4,M4,H4) -> 1.338795 | AC4: =AVERAGE(X4,S4,N4,I4) -> 0.89413838 | AD4: =(AA4-AA$79)/AA$80 -> -0.91060097 | AF4: Mean | AG4: SD | AH4: SE | AI4: Mean | AJ4: SD | AK4: SE | AL4: Mean | AM4: SD | AN4: SE
A5: 2013 | B5: 0.37647563 | C5: 1.9629 | D5: 0.73898401 | F5: 2013 | G5: 0.61752516 | H5: 1.63 | I5: 1.006566 | K5: 2013 | L5: 0.57414766 | M5: 1.2922 | N5: 0.73143771 | P5: 2013 | Q5: 0.79106192 | R5: 0.55375 | S5: 0.43686881 | U5: 2013 | V5: 0.67404673 | W5: 1.1512 | X5: 0.7759626 | Z5: 2013 | AA5: =AVERAGE(V5,Q5,L5,G5) -> 0.66419537 | AB5: =AVERAGE(W5,R5,M5,H5) -> 1.1567875 | AC5: =AVERAGE(X5,S5,N5,I5) -> 0.73770878 | AD5: =(AA5-AA$79)/AA$80 -> -0.94923858 | AE5: 1951-1984 | AF5: =AVERAGE(AA34:AA67) -> 0.76748869 | AG5: =_xlfn.STDEV.S(AA34:AA67) -> 0.067647261 | AH5: =AG5/SQRT(34) -> 0.01160141 | AI5: =AVERAGE(AB34:AB67) -> 1.0338344 | AJ5: =_xlfn.STDEV.S(AB34:AB67) -> 0.10918556 | AK5: =AJ5/SQRT(34) -> 0.018725169 | AL5: =AVERAGE(AC34:AC67) -> 0.79363797 | AM5: =_xlfn.STDEV.S(AC34:AC67) -> 0.093866653 | AN5: =AM5/SQRT(34) -> 0.016097998
A6: 2012 | B6: 0.31552184 | C6: 1.4445 | D6: 0.45577129 | F6: 2012 | G6: 0.61419012 | H6: 1.95 | I6: 1.1976707 | K6: 2012 | L6: 0.52600276 | M6: 1.0768 | N6: 0.59076555 | P6: 2012 | Q6: 0.87570355 | R6: 0.67685 | S6: 0.59760797 | U6: 2012 | V6: 0.81399765 | W6: 0.86345 | X6: 0.7035314 | Z6: 2012 | AA6: =AVERAGE(V6,Q6,L6,G6) -> 0.70747352 | AB6: =AVERAGE(W6,R6,M6,H6) -> 1.141775 | AC6: =AVERAGE(X6,S6,N6,I6) -> 0.77239391 | AD6: =(AA6-AA$79)/AA$80 -> -0.34154322 | AE6: 1984-2015 | AF6: =AVERAGE(AA3:AA34) -> 0.69311611 | AG6: =_xlfn.STDEV.S(AA3:AA34) -> 0.051738532 | AH6: =AG6/SQRT(32) -> 0.0091461668 | AI6: =AVERAGE(AB3:AB34) -> 1.0990803 | AJ6: =_xlfn.STDEV.S(AB3:AB34) -> 0.12806916 | AK6: =AJ6/SQRT(32) -> 0.022639643 | AL6: =AVERAGE(AC3:AC34) -> 0.75190137 | AM6: =_xlfn.STDEV.S(AC3:AC34) -> 0.094707643 | AN6: =AM6/SQRT(32) -> 0.016742104
A7: 2011 | B7: 0.2976837 | C7: 1.2407 | D7: 0.36933616 | F7: 2011 | G7: 0.49883694 | H7: 1.3711 | I7: 0.68395533 | K7: 2011 | L7: 0.62489177 | M7: 0.9537 | N7: 0.57115761 | P7: 2011 | Q7: 1.1571421 | R7: 0.70762 | S7: 0.85115902 | U7: 2011 | V7: 0.87813465 | W7: 1.07935 | X7: 0.95343918 | Z7: 2011 | AA7: =AVERAGE(V7,Q7,L7,G7) -> 0.78975136 | AB7: =AVERAGE(W7,R7,M7,H7) -> 1.0279425 | AC7: =AVERAGE(X7,S7,N7,I7) -> 0.76492778 | AD7: =(AA7-AA$79)/AA$80 -> 0.81377077
A8: 2010 | B8: 0.3238978 | C8: 1.5741 | D8: 0.50984753 | F8: 2010 | G8: 0.63175884 | H8: 1.493 | I8: 0.94321595 | K8: 2010 | L8: 0.74676149 | M8: 0.8922 | N8: 0.66344322 | P8: 2010 | Q8: 0.80087882 | R8: 0.76913 | S8: 0.61447359 | U8: 2010 | V8: 0.90217623 | W8: 0.93535 | X8: 0.85350325 | Z8: 2010 | AA8: =AVERAGE(V8,Q8,L8,G8) -> 0.77039384 | AB8: =AVERAGE(W8,R8,M8,H8) -> 1.02242 | AC8: =AVERAGE(X8,S8,N8,I8) -> 0.768659 | AD8: =(AA8-AA$79)/AA$80 -> 0.54195994
A9: 2009 | B9: 0.31922052 | C9: 1.4259 | D9: 0.45517654 | F9: 2009 | G9: 0.56872467 | H9: 1.0969 | I9: 0.6238341 | K9: 2009 | L9: 0.64925693 | M9: 0.923 | N9: 0.59926414 | P9: 2009 | Q9: 0.76428239 | R9: 0.769115 | S9: 0.58352027 | U9: 2009 | V9: 0.7777758 | W9: 1.05535 | X9: 0.80829391 | Z9: 2009 | AA9: =AVERAGE(V9,Q9,L9,G9) -> 0.69000995 | AB9: =AVERAGE(W9,R9,M9,H9) -> 0.96109125 | AC9: =AVERAGE(X9,S9,N9,I9) -> 0.6537281 | AD9: =(AA9-AA$79)/AA$80 -> -0.58676005
A10: 2008 | B10: 0.3347041 | C10: 1.4259 | D10: 0.47725457 | F10: 2008 | G10: 0.66884489 | H10: 1.234 | I10: 0.82535459 | K10: 2008 | L10: 0.66878829 | M10: 1.29215 | N10: 0.87830756 | P10: 2008 | Q10: 0.69483669 | R10: 0.5538 | S10: 0.38613982 | U10: 2008 | V10: 0.66820374 | W10: 1.24715 | X10: 0.8333469 | Z10: 2008 | AA10: =AVERAGE(V10,Q10,L10,G10) -> 0.6751684 | AB10: =AVERAGE(W10,R10,M10,H10) -> 1.081775 | AC10: =AVERAGE(X10,S10,N10,I10) -> 0.73078722 | AD10: =(AA10-AA$79)/AA$80 -> -0.79515938
A11: 2007 | B11: 0.31712281 | C11: 1.2408 | D11: 0.39348598 | F11: 2007 | G11: 0.64346527 | H11: 1.4473 | I11: 0.93128729 | K11: 2007 | L11: 0.66820878 | M11: 1.10755 | N11: 0.73435477 | P11: 2007 | Q11: 0.69761665 | R11: 0.9845 | S11: 0.68999358 | U11: 2007 | V11: 0.59938447 | W11: 1.2235 | X11: 0.73356373 | Z11: 2007 | AA11: =AVERAGE(V11,Q11,L11,G11) -> 0.6521688 | AB11: =AVERAGE(W11,R11,M11,H11) -> 1.1907125 | AC11: =AVERAGE(X11,S11,N11,I11) -> 0.77229984 | AD11: =(AA11-AA$79)/AA$80 -> -1.1181111
A12: 2006 | B12: 0.47727574 | C12: 1.1296 | D12: 0.53913068 | F12: 2006 | G12: 0.70462819 | H12: 0.7922 | I12: 0.55820645 | K12: 2006 | L12: 0.68828896 | M12: 1.2306 | N12: 0.84950836 | P12: 2006 | Q12: 0.80800203 | R12: 0.738365 | S12: 0.60450575 | U12: 2006 | V12: 0.49762252 | W12: 0.98365 | X12: 0.49186981 | Z12: 2006 | AA12: =AVERAGE(V12,Q12,L12,G12) -> 0.67463543 | AB12: =AVERAGE(W12,R12,M12,H12) -> 0.93620375 | AC12: =AVERAGE(X12,S12,N12,I12) -> 0.62602259 | AD12: =(AA12-AA$79)/AA$80 -> -0.80264322
A13: 2005 | B13: 0.34423837 | C13: 1.463 | D13: 0.50362073 | F13: 2005 | G13: 0.64314227 | H13: 2.011 | I13: 1.2933591 | K13: 2005 | L13: 0.71016199 | M13: 1.19985 | N13: 0.84455713 | P13: 2005 | Q13: 0.77179205 | R13: 1.23059 | S13: 0.89528307 | U13: 2005 | V13: 0.77793406 | W13: 1.03165 | X13: 0.80504638 | Z13: 2005 | AA13: =AVERAGE(V13,Q13,L13,G13) -> 0.72575759 | AB13: =AVERAGE(W13,R13,M13,H13) -> 1.3682725 | AC13: =AVERAGE(X13,S13,N13,I13) -> 0.95956142 | AD13: =(AA13-AA$79)/AA$80 -> -0.084805255
A14: 2004 | B14: 0.42125237 | C14: 1.4259 | D14: 0.60066375 | F14: 2004 | G14: 0.61592095 | H14: 1.2492 | I14: 0.76940846 | K14: 2004 | L14: 0.61407763 | M14: 0.9538 | N14: 0.56230553 | P14: 2004 | Q14: 0.66640379 | R14: 0.64607 | S14: 0.41388146 | U14: 2004 | V14: 0.66970273 | W14: 1.1996 | X14: 0.80547257 | Z14: 2004 | AA14: =AVERAGE(V14,Q14,L14,G14) -> 0.64152628 | AB14: =AVERAGE(W14,R14,M14,H14) -> 1.0121675 | AC14: =AVERAGE(X14,S14,N14,I14) -> 0.637767 | AD14: =(AA14-AA$79)/AA$80 -> -1.2675493
A15: 2003 | B15: 0.40402219 | C15: 1.0741 | D15: 0.43396023 | F15: 2003 | G15: 0.63199034 | H15: 1.173 | I15: 0.74132467 | K15: 2003 | L15: 0.53957047 | M15: 1.26135 | N15: 0.68729686 | P15: 2003 | Q15: 0.57355839 | R15: 0.861455 | S15: 0.48394386 | U15: 2003 | V15: 0.62307428 | W15: 1.10365 | X15: 0.68809238 | Z15: 2003 | AA15: =AVERAGE(V15,Q15,L15,G15) -> 0.59204837 | AB15: =AVERAGE(W15,R15,M15,H15) -> 1.0998637 | AC15: =AVERAGE(X15,S15,N15,I15) -> 0.65016444 | AD15: =(AA15-AA$79)/AA$80 -> -1.9622991
A16: 2002 | B16: 0.47814479 | C16: 1.1111 | D16: 0.53126668 | F16: 2002 | G16: 0.67841986 | H16: 1.3102 | I16: 0.8888657 | K16: 2002 | L16: 0.48742452 | M16: 1.41525 | N16: 0.68549348 | P16: 2002 | Q16: 0.63824347 | R16: 1.10755 | S16: 0.68993728 | U16: 2002 | V16: 0.63376867 | W16: 1.22355 | X16: 0.77256183 | Z16: 2002 | AA16: =AVERAGE(V16,Q16,L16,G16) -> 0.60946413 | AB16: =AVERAGE(W16,R16,M16,H16) -> 1.2641375 | AC16: =AVERAGE(X16,S16,N16,I16) -> 0.75921458 | AD16: =(AA16-AA$79)/AA$80 -> -1.7177537
A17: 2001 | B17: 0.51216369 | C17: 1.3889 | D17: 0.71134415 | F17: 2001 | G17: 0.68850186 | H17: 1.9195 | I17: 1.3215793 | K17: 2001 | L17: 0.62380954 | M17: 0.92295 | N17: 0.57250079 | P17: 2001 | Q17: 0.55921951 | R17: 0.830645 | S17: 0.46487506 | U17: 2001 | V17: 0.65815547 | W17: 1.2476 | X17: 0.82114887 | Z17: 2001 | AA17: =AVERAGE(V17,Q17,L17,G17) -> 0.63242159 | AB17: =AVERAGE(W17,R17,M17,H17) -> 1.2301737 | AC17: =AVERAGE(X17,S17,N17,I17) -> 0.79502601 | AD17: =(AA17-AA$79)/AA$80 -> -1.3953938
A18: 2000 | B18: 0.50600678 | C18: 1.7963 | D18: 0.90893997 | F18: 2000 | G18: 0.62470719 | H18: 1.5234 | I18: 0.95167894 | K18: 2000 | L18: 0.70088068 | M18: 1.29215 | N18: 0.95516297 | P18: 2000 | Q18: 0.74589764 | R18: 0.830665 | S18: 0.6086918 | U18: 2000 | V18: 0.58441029 | W18: 1.05565 | X18: 0.61695034 | Z18: 2000 | AA18: =AVERAGE(V18,Q18,L18,G18) -> 0.66397395 | AB18: =AVERAGE(W18,R18,M18,H18) -> 1.1754662 | AC18: =AVERAGE(X18,S18,N18,I18) -> 0.78312101
A19: 1999 | B19: 0.57639854 | C19: 1.2407 | D19: 0.71513766 | F19: 1999 | G19: 0.70055476 | H19: 1.7062 | I19: 1.1952865 | K19: 1999 | L19: 0.59948203 | M19: 0.9845 | N19: 0.59906671 | P19: 1999 | Q19: 0.76988592 | R19: 1.046 | S19: 0.79896581 | U19: 1999 | V19: 0.59344571 | W19: 1.2476 | X19: 0.74042745 | Z19: 1999 | AA19: =AVERAGE(V19,Q19,L19,G19) -> 0.66584211 | AB19: =AVERAGE(W19,R19,M19,H19) -> 1.246075 | AC19: =AVERAGE(X19,S19,N19,I19) -> 0.83343663
A20: 1998 | B20: 0.69909853 | C20: 0.5365 | D20: 0.37506636 | F20: 1998 | G20: 0.66004582 | H20: 1.43163 | I20: 0.9449414 | K20: 1998 | L20: 0.52908185 | M20: 1.4152 | N20: 0.74921562 | P20: 1998 | Q20: 0.88970844 | R20: 0.67685 | S20: 0.61555175 | U20: 1998 | V20: 0.62401771 | W20: 1.51145 | X20: 0.93585019 | Z20: 1998 | AA20: =AVERAGE(V20,Q20,L20,G20) -> 0.67571345 | AB20: =AVERAGE(W20,R20,M20,H20) -> 1.2587825 | AC20: =AVERAGE(X20,S20,N20,I20) -> 0.81138974
A21: 1997 | B21: 0.58289746 | C21: 0.7955 | D21: 0.46369493 | F21: 1997 | G21: 0.65863837 | H21: 0.92903 | I21: 0.61189481 | K21: 1997 | L21: 0.57386193 | M21: 1.046 | N21: 0.6028964 | P21: 1997 | Q21: 0.92425464 | R21: 0.861435 | S21: 0.74016235 | U21: 1997 | V21: 0.63222932 | W21: 1.15165 | X21: 0.73271709 | Z21: 1997 | AA21: =AVERAGE(V21,Q21,L21,G21) -> 0.69724606 | AB21: =AVERAGE(W21,R21,M21,H21) -> 0.99702875 | AC21: =AVERAGE(X21,S21,N21,I21) -> 0.67191766
A22: 1996 | B22: 0.48903561 | C22: 1.147 | D22: 0.56092384 | F22: 1996 | G22: 0.62495722 | H22: 1.46208 | I22: 0.91373745 | K22: 1996 | L22: 0.60864243 | M22: 1.2922 | N22: 0.7912034 | P22: 1996 | Q22: 0.93248217 | R22: 0.799915 | S22: 0.75158397 | U22: 1996 | V22: 0.67847663 | W22: 1.27155 | X22: 0.86267398 | Z22: 1996 | AA22: =AVERAGE(V22,Q22,L22,G22) -> 0.71113961 | AB22: =AVERAGE(W22,R22,M22,H22) -> 1.2064362 | AC22: =AVERAGE(X22,S22,N22,I22) -> 0.8297997
A23: 1995 | B23: 0.44657551 | C23: 1.2395 | D23: 0.55353035 | F23: 1995 | G23: 0.76493761 | H23: 1.08133 | I23: 0.82714998 | K23: 1995 | L23: 0.77288175 | M23: 1.04605 | N23: 0.78622844 | P23: 1995 | Q23: 0.89821093 | R23: 0.92293 | S23: 0.83918389 | U23: 1995 | V23: 0.61099529 | W23: 1.1516 | X23: 0.70253588 | Z23: 1995 | AA23: =AVERAGE(V23,Q23,L23,G23) -> 0.76175639 | AB23: =AVERAGE(W23,R23,M23,H23) -> 1.0504775 | AC23: =AVERAGE(X23,S23,N23,I23) -> 0.78877455
A24: 1994 | B24: 0.53508168 | C24: 1.1285 | D24: 0.60383968 | F24: 1994 | G24: 0.76138876 | H24: 1.27932 | I24: 0.97405987 | K24: 1994 | L24: 0.89485913 | M24: 1.13835 | N24: 1.0130281 | P24: 1994 | Q24: 0.83442383 | R24: 0.769165 | S24: 0.63748879 | U24: 1994 | V24: 0.58168747 | W24: 1.3675 | X24: 0.79347078 | Z24: 1994 | AA24: =AVERAGE(V24,Q24,L24,G24) -> 0.7680898 | AB24: =AVERAGE(W24,R24,M24,H24) -> 1.1385838 | AC24: =AVERAGE(X24,S24,N24,I24) -> 0.85451188
A25: 1993 | B25: 0.5050894 | C25: 1.073 | D25: 0.54196092 | F25: 1993 | G25: 0.7006854 | H25: 1.35547 | I25: 0.94975804 | K25: 1993 | L25: 0.73340452 | M25: 0.7691 | N25: 0.57455077 | P25: 1993 | Q25: 0.79519943 | R25: 0.892195 | S25: 0.69254223 | U25: 1993 | V25: 0.71008642 | W25: 1.1516 | X25: 0.81775951 | Z25: 1993 | AA25: =AVERAGE(V25,Q25,L25,G25) -> 0.73484394 | AB25: =AVERAGE(W25,R25,M25,H25) -> 1.0420913 | AC25: =AVERAGE(X25,S25,N25,I25) -> 0.75865264
A26: 1992 | B26: 0.53480401 | C26: 1.443 | D26: 0.77172219 | F26: 1992 | G26: 0.728454 | H26: 1.3707 | I26: 0.9984919 | K26: 1992 | L26: 0.63733925 | M26: 0.73835 | N26: 0.47057668 | P26: 1992 | Q26: 0.73397241 | R26: 1.322905 | S26: 0.95252982 | U26: 1992 | V26: 0.69611401 | W26: 0.9357 | X26: 0.64987664 | Z26: 1992 | AA26: =AVERAGE(V26,Q26,L26,G26) -> 0.69896992 | AB26: =AVERAGE(W26,R26,M26,H26) -> 1.0919138 | AC26: =AVERAGE(X26,S26,N26,I26) -> 0.76786876
A27: 1991 | B27: 0.52895345 | C27: 1.147 | D27: 0.60670961 | F27: 1991 | G27: 0.781272 | H27: 1.15748 | I27: 0.90430672 | K27: 1991 | L27: 0.60051194 | M27: 0.7384 | N27: 0.45723834 | P27: 1991 | Q27: 0.67807067 | R27: 0.646045 | S27: 0.41796708 | U27: 1991 | V27: 0.69062459 | W27: 1.1249 | X27: 0.76539271 | Z27: 1991 | AA27: =AVERAGE(V27,Q27,L27,G27) -> 0.6876198 | AB27: =AVERAGE(W27,R27,M27,H27) -> 0.91670625 | AC27: =AVERAGE(X27,S27,N27,I27) -> 0.63622621
A28: 1990 | B28: 0.50252146 | C28: 1.184 | D28: 0.59498541 | F28: 1990 | G28: 0.75557288 | H28: 1.14225 | I28: 0.86305312 | K28: 1990 | L28: 0.60682863 | M28: 1.23065 | N28: 0.74679819 | P28: 1990 | Q28: 0.71726364 | R28: 0.769125 | S28: 0.54206163 | U28: 1990 | V28: 0.65612063 | W28: 1.083 | X28: 0.66071672 | Z28: 1990 | AA28: =AVERAGE(V28,Q28,L28,G28) -> 0.68394645 | AB28: =AVERAGE(W28,R28,M28,H28) -> 1.0562563 | AC28: =AVERAGE(X28,S28,N28,I28) -> 0.70315742
A29: 1989 | B29: 0.60903768 | C29: 1.11 | D29: 0.67603183 | F29: 1989 | G29: 0.60147414 | H29: 0.80719 | I29: 0.48550391 | K29: 1989 | L29: 0.57305043 | M29: 0.79985 | N29: 0.42651679 | P29: 1989 | Q29: 0.73716266 | R29: 1.076805 | S29: 0.79402771 | U29: 1989 | V29: 0.61801031 | W29: 0.717 | X29: 0.43838211 | Z29: 1989 | AA29: =AVERAGE(V29,Q29,L29,G29) -> 0.63242438 | AB29: =AVERAGE(W29,R29,M29,H29) -> 0.85021125 | AC29: =AVERAGE(X29,S29,N29,I29) -> 0.53610763
... A36: 1982 | B36: 0.84868268 | C36: 0.999 | D36: 0.847834 | F36: 1982 | G36: 0.80287254 | H36: 0.83765 | I36: 0.67252619 | K36: 1982 | L36: 0.74777003 | M36: 1.04585 | N36: 0.81981086 | P36: 1982 | Q36: 0.66076016 | R36: 0.892195 | S36: 0.58965696 | U36: 1982 | V36: 0.61020537 | W36: 0.861 | X36: 0.52944102 | Z36: 1982 | AA36: =AVERAGE(V36,Q36,L36,G36) -> 0.70540203 | AB36: =AVERAGE(W36,R36,M36,H36) -> 0.90917375 | AC36: =AVERAGE(X36,S36,N36,I36) -> 0.65285876
K37: 1981 | L37: 0.93029319 | M37: 1.35335 | N37: 1.3046116 | P37: 1981 | Q37: 0.67817969 | R37: 1.199845 | S37: 0.78488314 | U37: 1981 | V37: 0.694496 | W37: 0.924 | X37: 0.64134374 | Z37: 1981 | AA37: =AVERAGE(V37,Q37,L37,G37) -> 0.76765629 | AB37: =AVERAGE(W37,R37,M37,H37) -> 1.159065 | AC37: =AVERAGE(X37,S37,N37,I37) -> 0.91027949
K38: 1980 | L38: 0.85337161 | M38: 1.10725 | N38: 0.91452633 | P38: 1980 | Q38: 0.62270223 | R38: 0.98449 | S38: 0.61304393 | U38: 1980 | V38: 0.89039353 | W38: 0.816 | X38: 0.73173887 | Z38: 1980 | AA38: =AVERAGE(V38,Q38,L38,G38) -> 0.78882246 | AB38: =AVERAGE(W38,R38,M38,H38) -> 0.96924667 | AC38: =AVERAGE(X38,S38,N38,I38) -> 0.75310304
K39: 1979 | L39: 0.82012319 | M39: 1.23025 | N39: 0.98323202 | P39: 1979 | Q39: 0.94102333 | R39: 0.79993 | S39: 0.74575635 | U39: 1979 | V39: 0.90963101 | W39: 0.813 | X39: 0.73964033 | Z39: 1979 | AA39: =AVERAGE(V39,Q39,L39,G39) -> 0.89025918 | AB39: =AVERAGE(W39,R39,M39,H39) -> 0.94772667 | AC39: =AVERAGE(X39,S39,N39,I39) -> 0.82287624
K40: 1978 | L40: 0.98956895 | M40: 1.1688 | N40: 1.1586645 | P40: 1978 | Q40: 0.58396359 | R40: 0.861225 | S40: 0.500613 | U40: 1978 | V40: 0.80159334 | W40: 0.834 | X40: 0.66995887 | Z40: 1978 | AA40: =AVERAGE(V40,Q40,L40,G40) -> 0.79170862 | AB40: =AVERAGE(W40,R40,M40,H40) -> 0.954675 | AC40: =AVERAGE(X40,S40,N40,I40) -> 0.77641212
K41: 1977 | L41: 0.91516845 | M41: 0.92255 | N41: 0.84070676 | P41: 1977 | Q41: 0.6949072 | R41: 0.92271 | S41: 0.63740937 | U41: 1977 | V41: 0.89431009 | W41: 0.927 | X41: 0.82840048 | Z41: 1977 | AA41: =AVERAGE(V41,Q41,L41,G41) -> 0.83479525 | AB41: =AVERAGE(W41,R41,M41,H41) -> 0.92408667 | AC41: =AVERAGE(X41,S41,N41,I41) -> 0.76883887
K42: 1976 | L42: 0.85404013 | M42: 1.13775 | N42: 0.96829987 | P42: 1976 | Q42: 0.58990273 | R42: 0.768975 | S42: 0.45169534 | U42: 1976 | V42: 0.85699679 | W42: 0.744 | X42: 0.63820201 | Z42: 1976 | AA42: =AVERAGE(V42,Q42,L42,G42) -> 0.76697988 | AB42: =AVERAGE(W42,R42,M42,H42) -> 0.883575 | AC42: =AVERAGE(X42,S42,N42,I42) -> 0.68606574
K43: 1975 | L43: 0.89822413 | M43: 1.07625 | N43: 0.97974579 | P43: 1975 | Q43: 0.66688545 | R43: 1.014975 | S43: 0.68178404 | U43: 1975 | V43: 0.7792961 | W43: 0.906 | X43: 0.70596584 | Z43: 1975 | AA43: =AVERAGE(V43,Q43,L43,G43) -> 0.78146856 | AB43: =AVERAGE(W43,R43,M43,H43) -> 0.999075 | AC43: =AVERAGE(X43,S43,N43,I43) -> 0.78916522
K44: 1974 | L44: 1.0672407 | M44: 1.07625 | N44: 1.2456629 | P44: 1974 | Q44: 0.63046332 | R44: 0.79968 | S44: 0.50356562 | U44: 1974 | V44: 0.80884511 | W44: 0.72 | X44: 0.58236848 | Z44: 1974 | AA44: =AVERAGE(V44,Q44,L44,G44) -> 0.83551639 | AB44: =AVERAGE(W44,R44,M44,H44) -> 0.86531 | AC44: =AVERAGE(X44,S44,N44,I44) -> 0.77719899
K45: 1973 | L45: 1.1485226 | M45: 1.0455 | N45: 1.2007804 | P45: 1973 | Q45: 0.71200348 | R45: 0.984225 | S45: 0.69673135 | U45: 1973 | V45: 0.82623385 | W45: 0.81 | X45: 0.67775363 | Z45: 1973 | AA45: =AVERAGE(V45,Q45,L45,G45) -> 0.89558665 | AB45: =AVERAGE(W45,R45,M45,H45) -> 0.946575 | AC45: =AVERAGE(X45,S45,N45,I45) -> 0.8584218
K46: 1972 | L46: 0.85798614 | M46: 0.95325 | N46: 0.81968864 | P46: 1972 | Q46: 0.75856742 | R46: 0.861195 | S46: 0.65343002 | U46: 1972 | V46: 0.54778338 | W46: 0.975 | X46: 0.53509994 | Z46: 1972 | AA46: =AVERAGE(V46,Q46,L46,G46) -> 0.72144564 | AB46: =AVERAGE(W46,R46,M46,H46) -> 0.929815 | AC46: =AVERAGE(X46,S46,N46,I46) -> 0.6694062
...

Sheet STDA-Match
A1: VAR-1 (X-RAY) | C1: IMBANACO-ENERO 2017 | F1: VAR-1 (X-RAY) | H1: VETERINARIA-JULIO 2016 | K1: VAR-2 (TOMO) | P1: VAR-3 (TOMO) | U1: VAR-4 (TOMO) | Z1: PROMEDIO | AB1: (VAR1-Vet)
A2: Año | B2: Densidad | C2: Extensión | D2: Calcificación | F2: Año | G2: Densidad | H2: Extension | I2: Calcificacion | K2: Año | L2: Densidad | M2: Extension | N2: Calcificacion | P2: Año | Q2: Densidad | R2: Extension | S2: Calcificacion | U2: Año | V2: Densidad | W2: Extension | X2: Calcificacion | Z2: Año | AA2: Densidad | AB2: Extension | AC2: Calcificacion
A3: 2015 | B3: =STANDARDIZE('DATA-Match'!B3,'DATA-Match'!B$79,'DATA-Match'!B$80) -> -0.59651067 | C3: =STANDARDIZE('DATA-Match'!C3,'DATA-Match'!C$79,'DATA-Match'!C$80) -> 1.8997938 | D3: =STANDARDIZE('DATA-Match'!D3,'DATA-Match'!D$79,'DATA-Match'!D$80) -> 0.52877935 | F3: 2015 | G3: =STANDARDIZE('DATA-Match'!G3,'DATA-Match'!G$79,'DATA-Match'!G$80) -> -0.080737371 | H3: =STANDARDIZE('DATA-Match'!H3,'DATA-Match'!H$79,'DATA-Match'!H$80) -> 0.32874163 | I3: =STANDARDIZE('DATA-Match'!I3,'DATA-Match'!I$79,'DATA-Match'!I$80) -> 0.32769502 | K3: 2015 | L3: =STANDARDIZE('DATA-Match'!L3,'DATA-Match'!L$79,'DATA-Match'!L$80) -> -0.84239006 | M3: =STANDARDIZE('DATA-Match'!M3,'DATA-Match'!M$79,'DATA-Match'!M$80) -> -1.2260092 | N3: =STANDARDIZE('DATA-Match'!N3,'DATA-Match'!N$79,'DATA-Match'!N$80) -> -1.3114467 | P3: 2015 | Q3: =STANDARDIZE('DATA-Match'!Q3,'DATA-Match'!Q$79,'DATA-Match'!Q$80) -> 1.8544048 | R3: =STANDARDIZE('DATA-Match'!R3,'DATA-Match'!R$79,'DATA-Match'!R$80) -> -1.0630589 | S3: =STANDARDIZE('DATA-Match'!S3,'DATA-Match'!S$79,'DATA-Match'!S$80) -> 0.017456133 | U3: 2015 | V3: =STANDARDIZE('DATA-Match'!V3,'DATA-Match'!V$79,'DATA-Match'!V$80) -> -0.91310895 | W3: =STANDARDIZE('DATA-Match'!W3,'DATA-Match'!W$79,'DATA-Match'!W$80) -> -0.13194753 | X3: =STANDARDIZE('DATA-Match'!X3,'DATA-Match'!X$79,'DATA-Match'!X$80) -> -0.85554961 | Z3: 2015 | AA3: =STANDARDIZE('DATA-Match'!AA3,'DATA-Match'!AA$79,'DATA-Match'!AA$80) -> -0.19584292 | AB3: =STANDARDIZE('DATA-Match'!AB3,'DATA-Match'!AB$79,'DATA-Match'!AB$80) -> -0.43457308 | AC3: =STANDARDIZE('DATA-Match'!AC3,'DATA-Match'!AC$79,'DATA-Match'!AC$80) -> -0.69155774 | AF3: Density | AI3: Extension | AL3: Calcification
A4: 2014 | B4: =STANDARDIZE('DATA-Match'!B4,'DATA-Match'!B$79,'DATA-Match'!B$80) -> -0.56412751 | C4: =STANDARDIZE('DATA-Match'!C4,'DATA-Match'!C$79,'DATA-Match'!C$80) -> 1.0157561 | D4: =STANDARDIZE('DATA-Match'!D4,'DATA-Match'!D$79,'DATA-Match'!D$80) -> 0.10326435 | F4: 2014 | G4: =STANDARDIZE('DATA-Match'!G4,'DATA-Match'!G$79,'DATA-Match'!G$80) -> -0.5664299 | H4: =STANDARDIZE('DATA-Match'!H4,'DATA-Match'!H$79,'DATA-Match'!H$80) -> 0.85213185 | I4: =STANDARDIZE('DATA-Match'!I4,'DATA-Match'!I$79,'DATA-Match'!I$80) -> 0.57457107 | K4: 2014 | L4: =STANDARDIZE('DATA-Match'!L4,'DATA-Match'!L$79,'DATA-Match'!L$80) -> -0.70579194 | M4: =STANDARDIZE('DATA-Match'!M4,'DATA-Match'!M$79,'DATA-Match'!M$80) -> 2.9727358 | N4: =STANDARDIZE('DATA-Match'!N4,'DATA-Match'!N$79,'DATA-Match'!N$80) -> 1.243643 | P4: 2014 | Q4: =STANDARDIZE('DATA-Match'!Q4,'DATA-Match'!Q$79,'DATA-Match'!Q$80) -> -0.66970191 | R4: =STANDARDIZE('DATA-Match'!R4,'DATA-Match'!R$79,'DATA-Match'!R$80) -> 0.19114525 | S4: =STANDARDIZE('DATA-Match'!S4,'DATA-Match'!S$79,'DATA-Match'!S$80) -> -0.081333464 | U4: 2014 | V4: =STANDARDIZE('DATA-Match'!V4,'DATA-Match'!V$79,'DATA-Match'!V$80) -> 0.04504757 | W4: =STANDARDIZE('DATA-Match'!W4,'DATA-Match'!W$79,'DATA-Match'!W$80) -> 0.24660139 | X4: =STANDARDIZE('DATA-Match'!X4,'DATA-Match'!X$79,'DATA-Match'!X$80) -> 0.29869142 | Z4: 2014 | AA4: =STANDARDIZE('DATA-Match'!AA4,'DATA-Match'!AA$79,'DATA-Match'!AA$80) -> -0.91060097 | AB4: =STANDARDIZE('DATA-Match'!AB4,'DATA-Match'!AB$79,'DATA-Match'!AB$80) -> 2.2161995 | AC4: =STANDARDIZE('DATA-Match'!AC4,'DATA-Match'!AC$79,'DATA-Match'!AC$80) -> 1.2435776 | AF4: Mean | AG4: SD | AH4: SE | AI4: Mean | AJ4: SD | AK4: SE | AL4: Mean | AM4: SD | AN4: SE
A5: 2013 | B5: =STANDARDIZE('DATA-Match'!B5,'DATA-Match'!B$79,'DATA-Match'!B$80) -> -0.79863564 | C5: =STANDARDIZE('DATA-Match'!C5,'DATA-Match'!C$79,'DATA-Match'!C$80) -> 2.253027 | D5: =STANDARDIZE('DATA-Match'!D5,'DATA-Match'!D$79,'DATA-Match'!D$80) -> 0.41890473 | F5: 2013 | G5: =STANDARDIZE('DATA-Match'!G5,'DATA-Match'!G$79,'DATA-Match'!G$80) -> -0.88277348 | H5: =STANDARDIZE('DATA-Match'!H5,'DATA-Match'!H$79,'DATA-Match'!H$80) -> 0.85213185 | I5: =STANDARDIZE('DATA-Match'!I5,'DATA-Match'!I$79,'DATA-Match'!I$80) -> 0.39101834 | K5: 2013 | L5: =STANDARDIZE('DATA-Match'!L5,'DATA-Match'!L$79,'DATA-Match'!L$80) -> -1.1812041 | M5: =STANDARDIZE('DATA-Match'!M5,'DATA-Match'!M$79,'DATA-Match'!M$80) -> 1.0351563 | N5: =STANDARDIZE('DATA-Match'!N5,'DATA-Match'!N$79,'DATA-Match'!N$80) -> -0.37964922 | P5: 2013 | Q5: =STANDARDIZE('DATA-Match'!Q5,'DATA-Match'!Q$79,'DATA-Match'!Q$80) -> 0.0083480841 | R5: =STANDARDIZE('DATA-Match'!R5,'DATA-Match'!R$79,'DATA-Match'!R$80) -> -2.0040368 | S5: =STANDARDIZE('DATA-Match'!S5,'DATA-Match'!S$79,'DATA-Match'!S$80) -> -1.6357783 | U5: 2013 | V5: =STANDARDIZE('DATA-Match'!V5,'DATA-Match'!V$79,'DATA-Match'!V$80) -> 0.047524402 | W5: =STANDARDIZE('DATA-Match'!W5,'DATA-Match'!W$79,'DATA-Match'!W$80) -> 0.62409952 | X5: =STANDARDIZE('DATA-Match'!X5,'DATA-Match'!X$79,'DATA-Match'!X$80) -> 0.65953367 | Z5: 2013 | AA5: =STANDARDIZE('DATA-Match'!AA5,'DATA-Match'!AA$79,'DATA-Match'!AA$80) -> -0.94923858 | AB5: =STANDARDIZE('DATA-Match'!AB5,'DATA-Match'!AB$79,'DATA-Match'!AB$80) -> 0.73272701 | AC5: =STANDARDIZE('DATA-Match'!AC5,'DATA-Match'!AC$79,'DATA-Match'!AC$80) -> -0.38207377 | AE5: 1951-1984 | AF5: =AVERAGE(AA34:AA67) -> 0.50116692 | AG5: =_xlfn.STDEV.S(AA34:AA67) -> 0.94987704 | AH5: =AG5/SQRT(34) -> 0.16290257 | AI5: =AVERAGE(AB34:AB67) -> -0.26941561 | AJ5: =_xlfn.STDEV.S(AB34:AB67) -> 0.88992912 | AK5: =AJ5/SQRT(34) -> 0.15262158 | AL5: =AVERAGE(AC34:AC67) -> 0.19915492 | AM5: =_xlfn.STDEV.S(AC34:AC67) -> 0.97548325 | AN5: =AM5/SQRT(34) -> 0.167294
A6: 2012 | B6: =STANDARDIZE('DATA-Match'!B6,'DATA-Match'!B$79,'DATA-Match'!B$80) -> -1.129106 | C6: =STANDARDIZE('DATA-Match'!C6,'DATA-Match'!C$79,'DATA-Match'!C$80) -> 0.60333243 | D6: =STANDARDIZE('DATA-Match'!D6,'DATA-Match'!D$79,'DATA-Match'!D$80) -> -0.72295331 | F6: 2012 | G6: =STANDARDIZE('DATA-Match'!G6,'DATA-Match'!G$79,'DATA-Match'!G$80) -> -0.92232103 | H6: =STANDARDIZE('DATA-Match'!H6,'DATA-Match'!H$79,'DATA-Match'!H$80) -> 1.768351 | I6: =STANDARDIZE('DATA-Match'!I6,'DATA-Match'!I$79,'DATA-Match'!I$80) -> 1.1977039 | K6: 2012 | L6: =STANDARDIZE('DATA-Match'!L6,'DATA-Match'!L$79,'DATA-Match'!L$80) -> -1.5279349 | M6: =STANDARDIZE('DATA-Match'!M6,'DATA-Match'!M$79,'DATA-Match'!M$80) -> -0.095426482 | N6: =STANDARDIZE('DATA-Match'!N6,'DATA-Match'!N$79,'DATA-Match'!N$80) -> -1.04725 | P6: 2012 | Q6: =STANDARDIZE('DATA-Match'!Q6,'DATA-Match'!Q$79,'DATA-Match'!Q$80) -> 0.71366145 | R6: =STANDARDIZE('DATA-Match'!R6,'DATA-Match'!R$79,'DATA-Match'!R$80) -> -1.3766672 | S6: =STANDARDIZE('DATA-Match'!S6,'DATA-Match'!S$79,'DATA-Match'!S$80) -> -0.78082228 | U6: 2012 | V6: =STANDARDIZE('DATA-Match'!V6,'DATA-Match'!V$79,'DATA-Match'!V$80) -> 1.1531229 | W6: =STANDARDIZE('DATA-Match'!W6,'DATA-Match'!W$79,'DATA-Match'!W$80) -> -0.88773187 | X6: =STANDARDIZE('DATA-Match'!X6,'DATA-Match'!X$79,'DATA-Match'!X$80) -> 0.1575255 | Z6: 2012 | AA6: =STANDARDIZE('DATA-Match'!AA6,'DATA-Match'!AA$79,'DATA-Match'!AA$80) -> -0.34154322 | AB6: =STANDARDIZE('DATA-Match'!AB6,'DATA-Match'!AB$79,'DATA-Match'!AB$80) -> 0.61036595 | AC6: =STANDARDIZE('DATA-Match'!AC6,'DATA-Match'!AC$79,'DATA-Match'!AC$80) -> -0.021618115 | AE6: 1984-2015 | AF6: =AVERAGE(AA3:AA34) -> -0.54314453 | AG6: =_xlfn.STDEV.S(AA3:AA34) -> 0.72649274 | AH6: =AG6/SQRT(32) -> 0.12842699 | AI6: =AVERAGE(AB3:AB34) -> 0.2623778 | AJ6: =_xlfn.STDEV.S(AB3:AB34) -> 1.043842 | AK6: =AJ6/SQRT(32) -> 0.18452695 | AL6: =AVERAGE(AC3:AC34) -> -0.23458117 | AM6: =_xlfn.STDEV.S(AC3:AC34) -> 0.98422301 | AN6: =AM6/SQRT(32) -> 0.17398769
A7: 2011 | B7: =STANDARDIZE('DATA-Match'!B7,'DATA-Match'!B$79,'DATA-Match'!B$80) -> -1.2258183 | C7: =STANDARDIZE('DATA-Match'!C7,'DATA-Match'!C$79,'DATA-Match'!C$80) -> -0.045216471 | D7: =STANDARDIZE('DATA-Match'!D7,'DATA-Match'!D$79,'DATA-Match'!D$80) -> -1.0714428 | F7: 2011 | G7: =STANDARDIZE('DATA-Match'!G7,'DATA-Match'!G$79,'DATA-Match'!G$80) -> -2.2902016 | H7: =STANDARDIZE('DATA-Match'!H7,'DATA-Match'!H$79,'DATA-Match'!H$80) -> 0.11085326 | I7: =STANDARDIZE('DATA-Match'!I7,'DATA-Match'!I$79,'DATA-Match'!I$80) -> -0.97077617 | K7: 2011 | L7: =STANDARDIZE('DATA-Match'!L7,'DATA-Match'!L$79,'DATA-Match'!L$80) -> -0.81575419 | M7: =STANDARDIZE('DATA-Match'!M7,'DATA-Match'!M$79,'DATA-Match'!M$80) -> -0.74154875 | N7: =STANDARDIZE('DATA-Match'!N7,'DATA-Match'!N$79,'DATA-Match'!N$80) -> -1.1403052 | P7: 2011 | Q7: =STANDARDIZE('DATA-Match'!Q7,'DATA-Match'!Q$79,'DATA-Match'!Q$80) -> 3.0588707 | R7: =STANDARDIZE('DATA-Match'!R7,'DATA-Match'!R$79,'DATA-Match'!R$80) -> -1.2198503 | S7: =STANDARDIZE('DATA-Match'!S7,'DATA-Match'!S$79,'DATA-Match'!S$80) -> 0.5677912 | U7: 2011 | V7: =STANDARDIZE('DATA-Match'!V7,'DATA-Match'!V$79,'DATA-Match'!V$80) -> 1.6597989 | W7: =STANDARDIZE('DATA-Match'!W7,'DATA-Match'!W$79,'DATA-Match'!W$80) -> 0.24660139 | X7: =STANDARDIZE('DATA-Match'!X7,'DATA-Match'!X$79,'DATA-Match'!X$80) -> 1.8895934 | Z7: 2011 | AA7: =STANDARDIZE('DATA-Match'!AA7,'DATA-Match'!AA$79,'DATA-Match'!AA$80) -> 0.81377077 | AB7: =STANDARDIZE('DATA-Match'!AB7,'DATA-Match'!AB$79,'DATA-Match'!AB$80) -> -0.31743859 | AC7: =STANDARDIZE('DATA-Match'!AC7,'DATA-Match'!AC$79,'DATA-Match'!AC$80) -> -0.099207802
A8: 2010 | B8: =STANDARDIZE('DATA-Match'!B8,'DATA-Match'!B$79,'DATA-Match'!B$80) -> -1.0836945 | C8: =STANDARDIZE('DATA-Match'!C8,'DATA-Match'!C$79,'DATA-Match'!C$80) -> 1.0157561 | D8: =STANDARDIZE('DATA-Match'!D8,'DATA-Match'!D$79,'DATA-Match'!D$80) -> -0.50492854 | F8: 2010 | G8: =STANDARDIZE('DATA-Match'!G8,'DATA-Match'!G$79,'DATA-Match'!G$80) -> -0.71398773 | H8: =STANDARDIZE('DATA-Match'!H8,'DATA-Match'!H$79,'DATA-Match'!H$80) -> 0.45987551 | I8: =STANDARDIZE('DATA-Match'!I8,'DATA-Match'!I$79,'DATA-Match'!I$80) -> 0.12360696 | K8: 2010 | L8: =STANDARDIZE('DATA-Match'!L8,'DATA-Match'!L$79,'DATA-Match'!L$80) -> 0.061929391 | M8: =STANDARDIZE('DATA-Match'!M8,'DATA-Match'!M$79,'DATA-Match'!M$80) -> -1.0643475 | N8: =STANDARDIZE('DATA-Match'!N8,'DATA-Match'!N$79,'DATA-Match'!N$80) -> -0.7023369 | P8: 2010 | Q8: =STANDARDIZE('DATA-Match'!Q8,'DATA-Match'!Q$79,'DATA-Match'!Q$80) -> 0.090151727 | R8: =STANDARDIZE('DATA-Match'!R8,'DATA-Match'!R$79,'DATA-Match'!R$80) -> -0.90636935 | S8: =STANDARDIZE('DATA-Match'!S8,'DATA-Match'!S$79,'DATA-Match'!S$80) -> -0.6911157 | U8: 2010 | V8: =STANDARDIZE('DATA-Match'!V8,'DATA-Match'!V$79,'DATA-Match'!V$80) -> 1.849725 | W8: =STANDARDIZE('DATA-Match'!W8,'DATA-Match'!W$79,'DATA-Match'!W$80) -> -0.50997105 | X8: =STANDARDIZE('DATA-Match'!X8,'DATA-Match'!X$79,'DATA-Match'!X$80) -> 1.1969546 | Z8: 2010 | AA8: =STANDARDIZE('DATA-Match'!AA8,'DATA-Match'!AA$79,'DATA-Match'!AA$80) -> 0.54195994 | AB8: =STANDARDIZE('DATA-Match'!AB8,'DATA-Match'!AB$79,'DATA-Match'!AB$80) -> -0.36245035 | AC8: =STANDARDIZE('DATA-Match'!AC8,'DATA-Match'!AC$79,'DATA-Match'!AC$80) -> -0.060432149
A9: 2009 | B9: =STANDARDIZE('DATA-Match'!B9,'DATA-Match'!B$79,'DATA-Match'!B$80) -> -1.1090531 | C9: =STANDARDIZE('DATA-Match'!C9,'DATA-Match'!C$79,'DATA-Match'!C$80) -> 0.544142 | D9: =STANDARDIZE('DATA-Match'!D9,'DATA-Match'!D$79,'DATA-Match'!D$80) -> -0.72535125 | F9: 2009 | G9: =STANDARDIZE('DATA-Match'!G9,'DATA-Match'!G$79,'DATA-Match'!G$80) -> -1.4614592 | H9: =STANDARDIZE('DATA-Match'!H9,'DATA-Match'!H$79,'DATA-Match'!H$80) -> -0.67423206 | I9: =STANDARDIZE('DATA-Match'!I9,'DATA-Match'!I$79,'DATA-Match'!I$80) -> -1.2245581 | K9: 2009 | L9: =STANDARDIZE('DATA-Match'!L9,'DATA-Match'!L$79,'DATA-Match'!L$80) -> -0.64028074 | M9: =STANDARDIZE('DATA-Match'!M9,'DATA-Match'!M$79,'DATA-Match'!M$80) -> -0.90268566 | N9: =STANDARDIZE('DATA-Match'!N9,'DATA-Match'!N$79,'DATA-Match'!N$80) -> -1.0069175 | P9: 2009 | Q9: =STANDARDIZE('DATA-Match'!Q9,'DATA-Match'!Q$79,'DATA-Match'!Q$80) -> -0.21480397 | R9: =STANDARDIZE('DATA-Match'!R9,'DATA-Match'!R$79,'DATA-Match'!R$80) -> -0.9064458 | S9: =STANDARDIZE('DATA-Match'!S9,'DATA-Match'!S$79,'DATA-Match'!S$80) -> -0.8557534 | U9: 2009 | V9: =STANDARDIZE('DATA-Match'!V9,'DATA-Match'!V$79,'DATA-Match'!V$80) -> 0.86697385 | W9: =STANDARDIZE('DATA-Match'!W9,'DATA-Match'!W$79,'DATA-Match'!W$80) -> 0.12050599 | X9: =STANDARDIZE('DATA-Match'!X9,'DATA-Match'!X$79,'DATA-Match'!X$80) -> 0.88361647 | Z9: 2009 | AA9: =STANDARDIZE('DATA-Match'!AA9,'DATA-Match'!AA$79,'DATA-Match'!AA$80) -> -0.58676005 | AB9: =STANDARDIZE('DATA-Match'!AB9,'DATA-Match'!AB$79,'DATA-Match'!AB$80) -> -0.86231719 | AC9: =STANDARDIZE('DATA-Match'!AC9,'DATA-Match'!AC$79,'DATA-Match'!AC$80) -> -1.2548197
A10: 2008 | B10: =STANDARDIZE('DATA-Match'!B10,'DATA-Match'!B$79,'DATA-Match'!B$80) -> -1.0251064 | C10: =STANDARDIZE('DATA-Match'!C10,'DATA-Match'!C$79,'DATA-Match'!C$80) -> 0.544142 | D10: =STANDARDIZE('DATA-Match'!D10,'DATA-Match'!D$79,'DATA-Match'!D$80) -> -0.63633693 | F10: 2008 | G10: =STANDARDIZE('DATA-Match'!G10,'DATA-Match'!G$79,'DATA-Match'!G$80) -> -0.2742141 | H10: =STANDARDIZE('DATA-Match'!H10,'DATA-Match'!H$79,'DATA-Match'!H$80) -> -0.2816894 | I10: =STANDARDIZE('DATA-Match'!I10,'DATA-Match'!I$79,'DATA-Match'!I$80) -> -0.37390586 | K10: 2008 | L10: =STANDARDIZE('DATA-Match'!L10,'DATA-Match'!L$79,'DATA-Match'!L$80) -> -0.49961943 | M10: =STANDARDIZE('DATA-Match'!M10,'DATA-Match'!M$79,'DATA-Match'!M$80) -> 1.0348938 | N10: =STANDARDIZE('DATA-Match'!N10,'DATA-Match'!N$79,'DATA-Match'!N$80) -> 0.31736452 | P10: 2008 | Q10: =STANDARDIZE('DATA-Match'!Q10,'DATA-Match'!Q$79,'DATA-Match'!Q$80) -> -0.79349055 | R10: =STANDARDIZE('DATA-Match'!R10,'DATA-Match'!R$79,'DATA-Match'!R$80) -> -2.003782 | S10: =STANDARDIZE('DATA-Match'!S10,'DATA-Match'!S$79,'DATA-Match'!S$80) -> -1.9056009 | U10: 2008 | V10: =STANDARDIZE('DATA-Match'!V10,'DATA-Match'!V$79,'DATA-Match'!V$80) -> 0.0013653419 | W10: =STANDARDIZE('DATA-Match'!W10,'DATA-Match'!W$79,'DATA-Match'!W$80) -> 1.1282184 | X10: =STANDARDIZE('DATA-Match'!X10,'DATA-Match'!X$79,'DATA-Match'!X$80) -> 1.0572544 | Z10: 2008 | AA10: =STANDARDIZE('DATA-Match'!AA10,'DATA-Match'!AA$79,'DATA-Match'!AA$80) -> -0.79515938 | AB10: =STANDARDIZE('DATA-Match'!AB10,'DATA-Match'!AB$79,'DATA-Match'!AB$80) -> 0.12132923 | AC10: =STANDARDIZE('DATA-Match'!AC10,'DATA-Match'!AC$79,'DATA-Match'!AC$80) -> -0.45400419
A11: 2007 | B11: =STANDARDIZE('DATA-Match'!B11,'DATA-Match'!B$79,'DATA-Match'!B$80) -> -1.1204261 | C11: =STANDARDIZE('DATA-Match'!C11,'DATA-Match'!C$79,'DATA-Match'!C$80) -> -0.044898243 | D11: =STANDARDIZE('DATA-Match'!D11,'DATA-Match'!D$79,'DATA-Match'!D$80) -> -0.97407544 | F11: 2007 | G11: =STANDARDIZE('DATA-Match'!G11,'DATA-Match'!G$79,'DATA-Match'!G$80) -> -0.57517054 | H11: =STANDARDIZE('DATA-Match'!H11,'DATA-Match'!H$79,'DATA-Match'!H$80) -> 0.32902795 | I11: =STANDARDIZE('DATA-Match'!I11,'DATA-Match'!I$79,'DATA-Match'!I$80) -> 0.073254068 | K11: 2007 | L11: =STANDARDIZE('DATA-Match'!L11,'DATA-Match'!L$79,'DATA-Match'!L$80) -> -0.50379291 | M11: =STANDARDIZE('DATA-Match'!M11,'DATA-Match'!M$79,'DATA-Match'!M$80) -> 0.065972867 | N11: =STANDARDIZE('DATA-Match'!N11,'DATA-Match'!N$79,'DATA-Match'!N$80) -> -0.36580544 | P11: 2007 | Q11: =STANDARDIZE('DATA-Match'!Q11,'DATA-Match'!Q$79,'DATA-Match'!Q$80) -> -0.77032536 | R11: =STANDARDIZE('DATA-Match'!R11,'DATA-Match'!R$79,'DATA-Match'!R$80) -> 0.19124718 | S11: =STANDARDIZE('DATA-Match'!S11,'DATA-Match'!S$79,'DATA-Match'!S$80) -> -0.28943219 | U11: 2007 | V11: =STANDARDIZE('DATA-Match'!V11,'DATA-Match'!V$79,'DATA-Match'!V$80) -> -0.54230008 | W11: =STANDARDIZE('DATA-Match'!W11,'DATA-Match'!W$79,'DATA-Match'!W$80) -> 1.0039619 | X11: =STANDARDIZE('DATA-Match'!X11,'DATA-Match'!X$79,'DATA-Match'!X$80) -> 0.36567442 | Z11: 2007 | AA11: =STANDARDIZE('DATA-Match'!AA11,'DATA-Match'!AA$79,'DATA-Match'!AA$80) -> -1.1181111 | AB11: =STANDARDIZE('DATA-Match'!AB11,'DATA-Match'!AB$79,'DATA-Match'!AB$80) -> 1.0092365 | AC11: =STANDARDIZE('DATA-Match'!AC11,'DATA-Match'!AC$79,'DATA-Match'!AC$80) -> -0.02259572
A12: 2006 | B12: =STANDARDIZE('DATA-Match'!B12,'DATA-Match'!B$79,'DATA-Match'!B$80) -> -0.25213222 | C12: =STANDARDIZE('DATA-Match'!C12,'DATA-Match'!C$79,'DATA-Match'!C$80) -> -0.39876791 | D12: =STANDARDIZE('DATA-Match'!D12,'DATA-Match'!D$79,'DATA-Match'!D$80) -> -0.38686464 | F12: 2006 | G12: =STANDARDIZE('DATA-Match'!G12,'DATA-Match'!G$79,'DATA-Match'!G$80) -> 0.15011127 | H12: =STANDARDIZE('DATA-Match'!H12,'DATA-Match'!H$79,'DATA-Match'!H$80) -> -1.5466445 | I12: =STANDARDIZE('DATA-Match'!I12,'DATA-Match'!I$79,'DATA-Match'!I$80) -> -1.5015836 | K12: 2006 | L12: =STANDARDIZE('DATA-Match'!L12,'DATA-Match'!L$79,'DATA-Match'!L$80) -> -0.35917909 | M12: =STANDARDIZE('DATA-Match'!M12,'DATA-Match'!M$79,'DATA-Match'!M$80) -> 0.7118327 | N12: =STANDARDIZE('DATA-Match'!N12,'DATA-Match'!N$79,'DATA-Match'!N$80) -> 0.18068952 | P12: 2006 | Q12: =STANDARDIZE('DATA-Match'!Q12,'DATA-Match'!Q$79,'DATA-Match'!Q$80) -> 0.14950898 | R12: =STANDARDIZE('DATA-Match'!R12,'DATA-Match'!R$79,'DATA-Match'!R$80) -> -1.0631608 | S12: =STANDARDIZE('DATA-Match'!S12,'DATA-Match'!S$79,'DATA-Match'!S$80) -> -0.74413369 | U12: 2006 | V12: =STANDARDIZE('DATA-Match'!V12,'DATA-Match'!V$79,'DATA-Match'!V$80) -> -1.3462095 | W12: =STANDARDIZE('DATA-Match'!W12,'DATA-Match'!W$79,'DATA-Match'!W$80) -> -0.25620404 | X12: =STANDARDIZE('DATA-Match'!X12,'DATA-Match'!X$79,'DATA-Match'!X$80) -> -1.3094646 | Z12: 2006 | AA12: =STANDARDIZE('DATA-Match'!AA12,'DATA-Match'!AA$79,'DATA-Match'!AA$80) -> -0.80264322 | AB12: =STANDARDIZE('DATA-Match'!AB12,'DATA-Match'!AB$79,'DATA-Match'!AB$80) -> -1.0651655 | AC12: =STANDARDIZE('DATA-Match'!AC12,'DATA-Match'!AC$79,'DATA-Match'!AC$80) -> -1.5427416
A13: 2005 | B13: =STANDARDIZE('DATA-Match'!B13,'DATA-Match'!B$79,'DATA-Match'!B$80) -> -0.97341492 | C13: =STANDARDIZE('DATA-Match'!C13,'DATA-Match'!C$79,'DATA-Match'!C$80) -> 0.66220463 | D13: =STANDARDIZE('DATA-Match'!D13,'DATA-Match'!D$79,'DATA-Match'!D$80) -> -0.53003376 | F13: 2005 | G13: =STANDARDIZE('DATA-Match'!G13,'DATA-Match'!G$79,'DATA-Match'!G$80) -> -0.57900078 | H13: =STANDARDIZE('DATA-Match'!H13,'DATA-Match'!H$79,'DATA-Match'!H$80) -> 1.9430053 | I13: =STANDARDIZE('DATA-Match'!I13,'DATA-Match'!I$79,'DATA-Match'!I$80) -> 1.6016207 | K13: 2005 | L13: =STANDARDIZE('DATA-Match'!L13,'DATA-Match'!L$79,'DATA-Match'!L$80) -> -0.20165354 | M13: =STANDARDIZE('DATA-Match'!M13,'DATA-Match'!M$79,'DATA-Match'!M$80) -> 0.55043335 | N13: =STANDARDIZE('DATA-Match'!N13,'DATA-Match'!N$79,'DATA-Match'!N$80) -> 0.15719199 | P13: 2005 | Q13: =STANDARDIZE('DATA-Match'!Q13,'DATA-Match'!Q$79,'DATA-Match'!Q$80) -> -0.15222645 | R13: =STANDARDIZE('DATA-Match'!R13,'DATA-Match'!R$79,'DATA-Match'!R$80) -> 1.4454258 | S13: =STANDARDIZE('DATA-Match'!S13,'DATA-Match'!S$79,'DATA-Match'!S$80) -> 0.80248276 | U13: 2005 | V13: =STANDARDIZE('DATA-Match'!V13,'DATA-Match'!V$79,'DATA-Match'!V$80) -> 0.86822408 | W13: =STANDARDIZE('DATA-Match'!W13,'DATA-Match'!W$79,'DATA-Match'!W$80) -> -0.0040132288 | X13: =STANDARDIZE('DATA-Match'!X13,'DATA-Match'!X$79,'DATA-Match'!X$80) -> 0.86110841 | Z13: 2005 | AA13: =STANDARDIZE('DATA-Match'!AA13,'DATA-Match'!AA$79,'DATA-Match'!AA$80) -> -0.084805255 | AB13: =STANDARDIZE('DATA-Match'!AB13,'DATA-Match'!AB$79,'DATA-Match'!AB$80) -> 2.4564592 | AC13: =STANDARDIZE('DATA-Match'!AC13,'DATA-Match'!AC$79,'DATA-Match'!AC$80) -> 1.9234685
A14: 2004 | B14: =STANDARDIZE('DATA-Match'!B14,'DATA-Match'!B$79,'DATA-Match'!B$80) -> -0.5558716 | C14: =STANDARDIZE('DATA-Match'!C14,'DATA-Match'!C$79,'DATA-Match'!C$80) -> 0.544142 | D14: =STANDARDIZE('DATA-Match'!D14,'DATA-Match'!D$79,'DATA-Match'!D$80) -> -0.13877537 | F14: 2004 | G14: =STANDARDIZE('DATA-Match'!G14,'DATA-Match'!G$79,'DATA-Match'!G$80) -> -0.90179648 | H14: =STANDARDIZE('DATA-Match'!H14,'DATA-Match'!H$79,'DATA-Match'!H$80) -> -0.23816899 | I14: =STANDARDIZE('DATA-Match'!I14,'DATA-Match'!I$79,'DATA-Match'!I$80) -> -0.61006401 | K14: 2004 | L14: =STANDARDIZE('DATA-Match'!L14,'DATA-Match'!L$79,'DATA-Match'!L$80) -> -0.89363561 | M14: =STANDARDIZE('DATA-Match'!M14,'DATA-Match'!M$79,'DATA-Match'!M$80) -> -0.74102388 | N14: =STANDARDIZE('DATA-Match'!N14,'DATA-Match'!N$79,'DATA-Match'!N$80) -> -1.1823153 | P14: 2004 | Q14: =STANDARDIZE('DATA-Match'!Q14,'DATA-Match'!Q$79,'DATA-Match'!Q$80) -> -1.0304201 | R14: =STANDARDIZE('DATA-Match'!R14,'DATA-Match'!R$79,'DATA-Match'!R$80) -> -1.5335351 | S14: =STANDARDIZE('DATA-Match'!S14,'DATA-Match'!S$79,'DATA-Match'!S$80) -> -1.7580458 | U14: 2004 | V14: =STANDARDIZE('DATA-Match'!V14,'DATA-Match'!V$79,'DATA-Match'!V$80) -> 0.013207243 | W14: =STANDARDIZE('DATA-Match'!W14,'DATA-Match'!W$79,'DATA-Match'!W$80) -> 0.87839192 | X14: =STANDARDIZE('DATA-Match'!X14,'DATA-Match'!X$79,'DATA-Match'!X$80) -> 0.86406223 | Z14: 2004 | AA14: =STANDARDIZE('DATA-Match'!AA14,'DATA-Match'!AA$79,'DATA-Match'!AA$80) -> -1.2675493 | AB14: =STANDARDIZE('DATA-Match'!AB14,'DATA-Match'!AB$79,'DATA-Match'!AB$80) -> -0.4460145 | AC14: =STANDARDIZE('DATA-Match'!AC14,'DATA-Match'!AC$79,'DATA-Match'!AC$80) -> -1.4206911
A15: 2003 | B15: =STANDARDIZE('DATA-Match'!B15,'DATA-Match'!B$79,'DATA-Match'!B$80) -> -0.64928769 | C15: =STANDARDIZE('DATA-Match'!C15,'DATA-Match'!C$79,'DATA-Match'!C$80) -> -0.57538451 | D15: =STANDARDIZE('DATA-Match'!D15,'DATA-Match'!D$79,'DATA-Match'!D$80) -> -0.81089121 | F15: 2003 | G15: =STANDARDIZE('DATA-Match'!G15,'DATA-Match'!G$79,'DATA-Match'!G$80) -> -0.71124256 | H15: =STANDARDIZE('DATA-Match'!H15,'DATA-Match'!H$79,'DATA-Match'!H$80) -> -0.45634368 | I15: =STANDARDIZE('DATA-Match'!I15,'DATA-Match'!I$79,'DATA-Match'!I$80) -> -0.72861045 | K15: 2003 | L15: =STANDARDIZE('DATA-Match'!L15,'DATA-Match'!L$79,'DATA-Match'!L$80) -> -1.4302226 | M15: =STANDARDIZE('DATA-Match'!M15,'DATA-Match'!M$79,'DATA-Match'!M$80) -> 0.87323205 | N15: =STANDARDIZE('DATA-Match'!N15,'DATA-Match'!N$79,'DATA-Match'!N$80) -> -0.58913249 | P15: 2003 | Q15: =STANDARDIZE('DATA-Match'!Q15,'DATA-Match'!Q$79,'DATA-Match'!Q$80) -> -1.8040949 | R15: =STANDARDIZE('DATA-Match'!R15,'DATA-Match'!R$79,'DATA-Match'!R$80) -> -0.43584214 | S15: =STANDARDIZE('DATA-Match'!S15,'DATA-Match'!S$79,'DATA-Match'!S$80) -> -1.3853907 | U15: 2003 | V15: =STANDARDIZE('DATA-Match'!V15,'DATA-Match'!V$79,'DATA-Match'!V$80) -> -0.35515292 | W15: =STANDARDIZE('DATA-Match'!W15,'DATA-Match'!W$79,'DATA-Match'!W$80) -> 0.37427299 | X15: =STANDARDIZE('DATA-Match'!X15,'DATA-Match'!X$79,'DATA-Match'!X$80) -> 0.050520279 | Z15: 2003 | AA15: =STANDARDIZE('DATA-Match'!AA15,'DATA-Match'!AA$79,'DATA-Match'!AA$80) -> -1.9622991 | AB15: =STANDARDIZE('DATA-Match'!AB15,'DATA-Match'!AB$79,'DATA-Match'!AB$80) -> 0.26876361 | AC15: =STANDARDIZE('DATA-Match'!AC15,'DATA-Match'!AC$79,'DATA-Match'!AC$80) -> -1.2918541
A16: 2002 | B16: =STANDARDIZE('DATA-Match'!B16,'DATA-Match'!B$79,'DATA-Match'!B$80) -> -0.24742052 | C16: =STANDARDIZE('DATA-Match'!C16,'DATA-Match'!C$79,'DATA-Match'!C$80) -> -0.45764011 | D16: =STANDARDIZE('DATA-Match'!D16,'DATA-Match'!D$79,'DATA-Match'!D$80) -> -0.41857073 | F16: 2002 | G16: =STANDARDIZE('DATA-Match'!G16,'DATA-Match'!G$79,'DATA-Match'!G$80) -> -0.16067219 | H16: =STANDARDIZE('DATA-Match'!H16,'DATA-Match'!H$79,'DATA-Match'!H$80) -> -0.063514706 | I16: =STANDARDIZE('DATA-Match'!I16,'DATA-Match'!I$79,'DATA-Match'!I$80) -> -0.10581467 | K16: 2002 | L16: =STANDARDIZE('DATA-Match'!L16,'DATA-Match'!L$79,'DATA-Match'!L$80) -> -1.8057683 | M16: =STANDARDIZE('DATA-Match'!M16,'DATA-Match'!M$79,'DATA-Match'!M$80) -> 1.6810161 | N16: =STANDARDIZE('DATA-Match'!N16,'DATA-Match'!N$79,'DATA-Match'!N$80) -> -0.59769097 | P16: 2002 | Q16: =STANDARDIZE('DATA-Match'!Q16,'DATA-Match'!Q$79,'DATA-Match'!Q$80) -> -1.2650783 | R16: =STANDARDIZE('DATA-Match'!R16,'DATA-Match'!R$79,'DATA-Match'!R$80) -> 0.81836197 | S16: =STANDARDIZE('DATA-Match'!S16,'DATA-Match'!S$79,'DATA-Match'!S$80) -> -0.2897316 | U16: 2002 | V16: =STANDARDIZE('DATA-Match'!V16,'DATA-Match'!V$79,'DATA-Match'!V$80) -> -0.27066834 | W16: =STANDARDIZE('DATA-Match'!W16,'DATA-Match'!W$79,'DATA-Match'!W$80) -> 1.0042246 | X16: =STANDARDIZE('DATA-Match'!X16,'DATA-Match'!X$79,'DATA-Match'!X$80) -> 0.63596358 | Z16: 2002 | AA16: =STANDARDIZE('DATA-Match'!AA16,'DATA-Match'!AA$79,'DATA-Match'!AA$80) -> -1.7177537 | AB16: =STANDARDIZE('DATA-Match'!AB16,'DATA-Match'!AB$79,'DATA-Match'!AB$80) -> 1.6076952 | AC16: =STANDARDIZE('DATA-Match'!AC16,'DATA-Match'!AC$79,'DATA-Match'!AC$80) -> -0.15858075
A17: 2001 | B17: =STANDARDIZE('DATA-Match'!B17,'DATA-Match'!B$79,'DATA-Match'!B$80) -> -0.062981786 | C17: =STANDARDIZE('DATA-Match'!C17,'DATA-Match'!C$79,'DATA-Match'!C$80) -> 0.42639759 | D17: =STANDARDIZE('DATA-Match'!D17,'DATA-Match'!D$79,'DATA-Match'!D$80) -> 0.30746627 | F17: 2001 | G17: =STANDARDIZE('DATA-Match'!G17,'DATA-Match'!G$79,'DATA-Match'!G$80) -> -0.041117948 | H17: =STANDARDIZE('DATA-Match'!H17,'DATA-Match'!H$79,'DATA-Match'!H$80) -> 1.6810239 | I17: =STANDARDIZE('DATA-Match'!I17,'DATA-Match'!I$79,'DATA-Match'!I$80) -> 1.720743 | K17: 2001 | L17: =STANDARDIZE('DATA-Match'!L17,'DATA-Match'!L$79,'DATA-Match'!L$80) -> -0.82354822 | M17: =STANDARDIZE('DATA-Match'!M17,'DATA-Match'!M$79,'DATA-Match'!M$80) -> -0.9029481 | N17: =STANDARDIZE('DATA-Match'!N17,'DATA-Match'!N$79,'DATA-Match'!N$80) -> -1.1339308 | P17: 2001 | Q17: =STANDARDIZE('DATA-Match'!Q17,'DATA-Match'!Q$79,'DATA-Match'!Q$80) -> -1.9235799 | R17: =STANDARDIZE('DATA-Match'!R17,'DATA-Match'!R$79,'DATA-Match'!R$80) -> -0.59286292 | S17: =STANDARDIZE('DATA-Match'!S17,'DATA-Match'!S$79,'DATA-Match'!S$80) -> -1.4868158 | U17: 2001 | V17: =STANDARDIZE('DATA-Match'!V17,'DATA-Match'!V$79,'DATA-Match'!V$80) -> -0.078014998 | W17: =STANDARDIZE('DATA-Match'!W17,'DATA-Match'!W$79,'DATA-Match'!W$80) -> 1.1305827 | X17: =STANDARDIZE('DATA-Match'!X17,'DATA-Match'!X$79,'DATA-Match'!X$80) -> 0.97271196 | Z17: 2001 | AA17: =STANDARDIZE('DATA-Match'!AA17,'DATA-Match'!AA$79,'DATA-Match'!AA$80) -> -1.3953938 | AB17: =STANDARDIZE('DATA-Match'!AB17,'DATA-Match'!AB$79,'DATA-Match'!AB$80) -> 1.3308699 | AC17: =STANDARDIZE('DATA-Match'!AC17,'DATA-Match'!AC$79,'DATA-Match'!AC$80) -> 0.21357966
A18: 2000 | B18: =STANDARDIZE('DATA-Match'!B18,'DATA-Match'!B$79,'DATA-Match'!B$80) -> -0.096362475 | C18: =STANDARDIZE('DATA-Match'!C18,'DATA-Match'!C$79,'DATA-Match'!C$80) -> 1.7228589 | D18: =STANDARDIZE('DATA-Match'!D18,'DATA-Match'!D$79,'DATA-Match'!D$80) -> 1.1041338 | F18: 2000 | G18: =STANDARDIZE('DATA-Match'!G18,'DATA-Match'!G$79,'DATA-Match'!G$80) -> -0.79760754 | H18: =STANDARDIZE('DATA-Match'!H18,'DATA-Match'!H$79,'DATA-Match'!H$80) -> 0.54691633 | I18: =STANDARDIZE('DATA-Match'!I18,'DATA-Match'!I$79,'DATA-Match'!I$80) -> 0.15933067 | K18: 2000 | L18: =STANDARDIZE('DATA-Match'!L18,'DATA-Match'!L$79,'DATA-Match'!L$80) -> -0.26849583 | M18: =STANDARDIZE('DATA-Match'!M18,'DATA-Match'!M$79,'DATA-Match'!M$80) -> 1.0348938 | N18: =STANDARDIZE('DATA-Match'!N18,'DATA-Match'!N$79,'DATA-Match'!N$80) -> 0.6821043 | P18: 2000 | Q18: =STANDARDIZE('DATA-Match'!Q18,'DATA-Match'!Q$79,'DATA-Match'!Q$80) -> -0.36800296 | R18: =STANDARDIZE('DATA-Match'!R18,'DATA-Match'!R$79,'DATA-Match'!R$80) -> -0.59276099 | S18: =STANDARDIZE('DATA-Match'!S18,'DATA-Match'!S$79,'DATA-Match'!S$80) -> -0.72186846 | U18: 2000 | V18: =STANDARDIZE('DATA-Match'!V18,'DATA-Match'!V$79,'DATA-Match'!V$80) -> -0.66059463 | W18: =STANDARDIZE('DATA-Match'!W18,'DATA-Match'!W$79,'DATA-Match'!W$80) -> 0.12208218 | X18: =STANDARDIZE('DATA-Match'!X18,'DATA-Match'!X$79,'DATA-Match'!X$80) -> -0.44255296 | Z18: 2000 | AA18: =STANDARDIZE('DATA-Match'!AA18,'DATA-Match'!AA$79,'DATA-Match'!AA$80) -> -0.95234759 | AB18: =STANDARDIZE('DATA-Match'!AB18,'DATA-Match'!AB$79,'DATA-Match'!AB$80) -> 0.88497025 | AC18: =STANDARDIZE('DATA-Match'!AC18,'DATA-Match'!AC$79,'DATA-Match'!AC$80) -> 0.089860284
